Workbook

Sheet RESUMEN
A1: RESUMEN POR PREDIO – VALOR DE CONSTRUCCIONES (calculado desde las hojas LIQ)
A3: Predio | B3: Hoja LIQ | C3: Nº construcciones | D3: Clasificadas | E3: Sin clasificar | F3: Sin área | G3: Valor construcciones (principal + anexas)
A4: LÍBANO | B4: LIQ LÍBANO | C4: 6 | D4: 6 | E4: 0 | F4: 0 | G4: ='LIQ LÍBANO'!F9+'LIQ LÍBANO'!F21
A5: PORCIÓN 1-2-3 | B5: LIQ PORCIÓN 1-2-3 | C5: 9 | D5: 4 | E5: 5 | F5: 0 | G5: ='LIQ PORCIÓN 1-2-3'!F9+'LIQ PORCIÓN 1-2-3'!F21
A6: SANTA ISABEL | B6: LIQ SANTA ISABEL | C6: 2 | D6: 2 | E6: 0 | F6: 0 | G6: ='LIQ SANTA ISABEL'!F9+'LIQ SANTA ISABEL'!F21
A7: CANCÚN (parte 1/2) | B7: LIQ CANCÚN (1) | C7: 10 | D7: 7 | E7: 3 | F7: 2 | G7: ='LIQ CANCÚN (1)'!F9+'LIQ CANCÚN (1)'!F21
A8: CANCÚN (parte 2/2) | B8: LIQ CANCÚN (2) | C8: 1 | D8: 1 | E8: 0 | F8: 1 | G8: ='LIQ CANCÚN (2)'!F9+'LIQ CANCÚN (2)'!F21
A9: CIMARRONA | B9: LIQ CIMARRONA | C9: 10 | D9: 10 | E9: 0 | F9: 5 | G9: ='LIQ CIMARRONA'!F9+'LIQ CIMARRONA'!F21
A10: CARI CARI | B10: LIQ CARI CARI | C10: 4 | D10: 3 | E10: 1 | F10: 0 | G10: ='LIQ CARI CARI'!F9+'LIQ CARI CARI'!F21
A11: EL CORUAL (parte 1/2) | B11: LIQ EL CORUAL (1) | C11: 10 | D11: 7 | E11: 3 | F11: 7 | G11: ='LIQ EL CORUAL (1)'!F9+'LIQ EL CORUAL (1)'!F21
A12: EL CORUAL (parte 2/2) | B12: LIQ EL CORUAL (2) | C12: 9 | D12: 8 | E12: 1 | F12: 2 | G12: ='LIQ EL CORUAL (2)'!F9+'LIQ EL CORUAL (2)'!F21
A13: LAS MERCEDES (parte 1/2) | B13: LIQ LAS MERCEDES (1) | C13: 10 | D13: 9 | E13: 1 | F13: 5 | G13: ='LIQ LAS MERCEDES (1)'!F9+'LIQ LAS MERCEDES (1)'!F21
A14: LAS MERCEDES (parte 2/2) | B14: LIQ LAS MERCEDES (2) | C14: 5 | D14: 4 | E14: 1 | F14: 5 | G14: ='LIQ LAS MERCEDES (2)'!F9+'LIQ LAS MERCEDES (2)'!F21
A15: VERSALLES 1 | B15: LIQ VERSALLES 1 | C15: 2 | D15: 2 | E15: 0 | F15: 0 | G15: ='LIQ VERSALLES 1'!F9+'LIQ VERSALLES 1'!F21
A16: TOTAL | C16: =SUM(C4:C15) | D16: =SUM(D4:D15) | E16: =SUM(E4:E15) | F16: =SUM(F4:F15) | G16: =SUM(G4:G15)
A18: Los valores de predios con más de 10 construcciones se reparten en dos hojas (el formato admite 10 por hoja); sume ambas partes. Las construcciones sin clasificar y las de área vacía aportan $0 hasta que digite el presupuesto propio / el área.

Sheet CLASIFICACIÓN
A1: CLASIFICACIÓN DE CONSTRUCCIONES POR TIPOLOGÍA – Catálogo IGAC de Valores de Reposición (oct-2025 a oct-2026) · Región Norte
A3: Predio | B3: Nº | C3: Ítem | D3: Área (m²) | E3: Edad | F3: Vida útil aplicada | G3: Estado (archivo) | H3: Calif. aplicada | I3: Tipología asignada (catálogo) | J3: Vida útil catálogo | K3: Valor reposición $/m² (Región Norte) | L3: Confianza | M3: Estado de la clasificación | N3: Criterio | O3: Alertas | P3: Hoja DEP | Q3: Fila
A4: LÍBANO | B4: 1 | C4: Casa Principal | D4: 96.88 | E4: 30 | F4: 70 | G4: Bueno | H4: 2 | I4: 1014113_Residencial.Tipo_3 | J4: 100 | K4: 1131400 | L4: Alta | M4: CLASIFICADA | N4: Mampostería de bloque, revoque y pintura, pisos concreto/cerámica. | O4: Vida útil del archivo (70) distinta a la del catálogo (100); se respetó el archivo. | P4: DEP LÍBANO | Q4: 5
A5: LÍBANO | B5: 2 | C5: Casa Mayordomo | D5: 59.29 | E5: 30 | F5: 70 | G5: Regular | H5: 3 | I5: 1004113_Residencial.Tipo_3_Menos | J5: 100 | K5: 1014000 | L5: Media | M5: CLASIFICADA | N5: Acabados austeros, pañete a la vista/pintura, cubierta metálica. | O5: Vida útil del archivo (70) distinta a la del catálogo (100); se respetó el archivo. | P5: DEP LÍBANO | Q5: 6
A6: LÍBANO | B6: 3 | C6: Casa pequeña | D6: 69.97 | E6: 25 | F6: 70 | G6: Regular | H6: 3 | I6: 1004113_Residencial.Tipo_3_Menos | J6: 100 | K6: 1014000 | L6: Media | M6: CLASIFICADA | N6: Vivienda auxiliar sencilla, pisos en concreto afinado. | O6: Vida útil del archivo (70) distinta a la del catálogo (100); se respetó el archivo. | P6: DEP LÍBANO | Q6: 7
A7: LÍBANO | B7: 4 | C7: Bodega principal | D7: 72 | E7: 30 | F7: 70 | G7: Deficiente | H7: 3.5 | I7: 3001121_Industrial.Liviana_2 | J7: 100 | K7: 1226000 | L7: Media | M7: CLASIFICADA | N7: Bodega de una nave en mampostería con cercha metálica. | O7: Vida útil del archivo (70) distinta a la del catálogo (100); se respetó el archivo. | P7: DEP LÍBANO | Q7: 8
A8: LÍBANO | B8: 5 | C8: Cuarto útil | D8: 9 | E8: 30 | F8: 70 | G8: Deficiente | H8: 3.5 | I8: Anexos.Depósitos_1 | J8: 70 | K8: 767900 | L8: Media | M8: CLASIFICADA | N8: Cuarto de almacenamiento en mampostería. | P8: DEP LÍBANO | Q8: 9
A9: LÍBANO | B9: 6 | C9: Bodega auxiliar | D9: 8.32 | E9: 30 | F9: 50 | G9: Deficiente | H9: 3.5 | I9: Anexos.Depósitos_1 | J9: 70 | K9: 767900 | L9: Media | M9: CLASIFICADA | N9: Cuarto de almacenamiento en mampostería. | O9: Vida útil del archivo (50) distinta a la del catálogo (70); se respetó el archivo. | P9: DEP LÍBANO | Q9: 10
A10: PORCIÓN 1-2-3 | B10: 1 | C10: Casa Principal | D10: =12*21 | E10: 45 | F10: 70 | G10: Regular | H10: 3.5 | I10: 1004113_Residencial.Tipo_3_Menos | J10: 100 | K10: 1014000 | L10: Media | M10: CLASIFICADA | N10: Mampostería revocada, piso concreto liso, cubierta zinc sobre madera. | O10: Vida útil del archivo (70) distinta a la del catálogo (100); se respetó el archivo. | Estado: el texto dice 'Regular' (3) pero la calificación numérica es 3.5; se usó la numérica del archivo. | P10: DEP PORCIÓN 1-2-3 | Q10: 5
A11: PORCIÓN 1-2-3 | B11: 2 | C11: Caseta de Porteria | D11: =2.6*2.7 | E11: 40 | F11: 70 | G11: Regular | H11: 3.5 | I11: 1004113_Residencial.Tipo_3_Menos | J11: 100 | K11: 1014000 | L11: Media | M11: CLASIFICADA | N11: Caseta pequeña en mampostería con placa; sin tipología específica de portería. | O11: Vida útil del archivo (70) distinta a la del catálogo (100); se respetó el archivo. | Estado: el texto dice 'Regular' (3) pero la calificación numérica es 3.5; se usó la numérica del archivo. | P11: DEP PORCIÓN 1-2-3 | Q11: 6
A12: PORCIÓN 1-2-3 | B12: 3 | C12: Caseta de Fertilizantes | D12: =4*4 | E12: 40 | F12: 70 | G12: Regular | H12: 3 | I12: SIN CLASIFICAR | J12: — | L12: — | M12: SIN CLASIFICAR | N12: Instalación/equipo o caseta en malla: sin tipología directa en el catálogo (requiere presupuesto propio). Murete + malla eslabonada + cubierta zinc. | O12: Vida útil vacía y sin tipología: se usó 70 provisional. | Valor de reposición pendiente: digitar presupuesto propio. | P12: DEP PORCIÓN 1-2-3 | Q12: 7
A13: PORCIÓN 1-2-3 | B13: 4 | C13: Comedor | D13: 367 | E13: 30 | F13: 70 | G13: Bueno | H13: 2 | I13: Anexos.Ramadas_Cobertizos_Caneyes_Plus_Tipo_80 | J13: 70 | K13: 912600 | L13: Media | M13: CLASIFICADA | N13: Cubierta metálica sobre marcos metálicos, piso en baldosa. | O13: Vida útil vacía en el archivo: se usó la del catálogo (70). | P13: DEP PORCIÓN 1-2-3 | Q13: 8
A14: PORCIÓN 1-2-3 | B14: 5 | C14: Empacadora | D14: 297 | E14: 45 | F14: 70 | G14: Bueno | H14: 2 | I14: Anexos.Beneficiaderos_Medio_Tipo_60 | J14: 100 | K14: 680600 | L14: Media | M14: CLASIFICADA | N14: Tinas de lavado en concreto bajo cubierta metálica (empacadora). | O14: Vida útil del archivo (70) distinta a la del catálogo (100); se respetó el archivo. | P14: DEP PORCIÓN 1-2-3 | Q14: 9
A15: PORCIÓN 1-2-3 | B15: 6 | C15: Planta agua potable | D15: =2.2*3 | E15: 45 | F15: 70 | G15: Regular | H15: 3 | I15: SIN CLASIFICAR | J15: — | L15: — | M15: SIN CLASIFICAR | N15: Instalación/equipo o caseta en malla: sin tipología directa en el catálogo (requiere presupuesto propio). Planta de agua potable. | O15: Vida útil vacía y sin tipología: se usó 70 provisional. | Valor de reposición pendiente: digitar presupuesto propio. | P15: DEP PORCIÓN 1-2-3 | Q15: 10
A16: PORCIÓN 1-2-3 | B16: 7 | C16: Caseta Planta electrica | D16: =2.5*2.75 | E16: 40 | F16: 70 | G16: Regular | H16: 3 | I16: SIN CLASIFICAR | J16: — | L16: — | M16: SIN CLASIFICAR | N16: Instalación/equipo o caseta en malla: sin tipología directa en el catálogo (requiere presupuesto propio). Caseta de planta eléctrica. | O16: Vida útil vacía y sin tipología: se usó 70 provisional. | Valor de reposición pendiente: digitar presupuesto propio. | P16: DEP PORCIÓN 1-2-3 | Q16: 11
A17: PORCIÓN 1-2-3 | B17: 8 | C17: Ramada Aceite | D17: 28.88 | E17: 40 | F17: 70 | G17: Regular | H17: 3 | I17: SIN CLASIFICAR | J17: — | L17: — | M17: SIN CLASIFICAR | N17: Instalación/equipo o caseta en malla: sin tipología directa en el catálogo (requiere presupuesto propio). Ramada de aceite con cerramiento en malla. | O17: Vida útil vacía y sin tipología: se usó 70 provisional. | Valor de reposición pendiente: digitar presupuesto propio. | P17: DEP PORCIÓN 1-2-3 | Q17: 12
A18: PORCIÓN 1-2-3 | B18: 9 | C18: Caseta de desinfección | D18: =8.1*2.5 | E18: 40 | F18: 70 | G18: Regular | H18: 3 | I18: SIN CLASIFICAR | J18: — | L18: — | M18: SIN CLASIFICAR | N18: Pozetas de desinfección bajo cubierta: sin tipología directa (requiere presupuesto propio). | O18: Vida útil vacía y sin tipología: se usó 70 provisional. | Valor de reposición pendiente: digitar presupuesto propio. | P18: DEP PORCIÓN 1-2-3 | Q18: 13
A19: SANTA ISABEL | B19: 1 | C19: Casa 1 | D19: 100 | E19: 30 | F19: 70 | G19: Regular | H19: 3 | I19: 1004113_Residencial.Tipo_3_Menos | J19: 100 | K19: 1014000 | L19: Media | M19: CLASIFICADA | N19: Mampostería de bloque, revoque y pintura, piso concreto afinado. | O19: Vida útil del archivo (70) distinta a la del catálogo (100); se respetó el archivo. | P19: DEP SANTA ISABEL | Q19: 5
A20: SANTA ISABEL | B20: 2 | C20: Casa 2 | D20: 80 | E20: 30 | F20: 70 | G20: Regular | H20: 3 | I20: 1004113_Residencial.Tipo_3_Menos | J20: 100 | K20: 1014000 | L20: Media | M20: CLASIFICADA | N20: Mampostería sencilla, abandonada (el deterioro se refleja en el estado). | O20: Vida útil del archivo (70) distinta a la del catálogo (100); se respetó el archivo. | P20: DEP SANTA ISABEL | Q20: 6
A21: CANCÚN | B21: 1 | C21: Almacen | D21: 148.4 | E21: 15 | F21: 70 | G21: Regular | H21: 3 | I21: 2014111_Comercial.Basico_2 | J21: 70 | K21: 1038900 | L21: Media | M21: CLASIFICADA | N21: Almacén/depósito de insumos, un nivel, cubierta metálica. | P21: DEP CANCÚN (1) | Q21: 5
A22: CANCÚN | B22: 2 | C22: Bodega Cartonera | D22: 253 | E22: 20 | F22: 70 | G22: Regular | H22: 3 | I22: 3002311_Industrial.Liviana_1 | J22: 70 | K22: 476900 | L22: Media | M22: CLASIFICADA | N22: Galpón de acopio con cerramiento a la vista (malla/lámina) y cubierta metálica. | P22: DEP CANCÚN (1) | Q22: 6
A23: CANCÚN | B23: 3 | C23: Portería | D23: 12.05 | E23: 18 | F23: 100 | G23: Regular | H23: 3 | I23: 1004113_Residencial.Tipo_3_Menos | J23: 100 | K23: 1014000 | L23: Media | M23: CLASIFICADA | N23: Caseta pequeña en mampostería. | O23: Vida útil vacía en el archivo: se usó la del catálogo (100). | P23: DEP CANCÚN (1) | Q23: 7
A24: CANCÚN | B24: 4 | C24: Comedor | D24: 202.4 | E24: 20 | F24: 70 | G24: Bueno | H24: 2 | I24: Anexos.Ramadas_Cobertizos_Caneyes_Plus_Tipo_80 | J24: 70 | K24: 912600 | L24: Media | M24: CLASIFICADA | N24: Estructura abierta con cerchas metálicas; criterio por foto. | O24: Vida útil vacía en el archivo: se usó la del catálogo (70). | P24: DEP CANCÚN (1) | Q24: 8
A25: CANCÚN | B25: 5 | C25: Empacadora | D25: 350 | E25: 15 | F25: 70 | G25: Bueno | H25: 2 | I25: Anexos.Beneficiaderos_Medio_Tipo_60 | J25: 100 | K25: 680600 | L25: Media | M25: CLASIFICADA | N25: Tinas de lavado en concreto bajo cubierta metálica (empacadora). | O25: Vida útil del archivo (70) distinta a la del catálogo (100); se respetó el archivo. | P25: DEP CANCÚN (1) | Q25: 9
A26: CANCÚN | B26: 6 | C26: Planta agua potable | D26: 21 | E26: 15 | F26: 70 | G26: Bueno | H26: 4 | I26: SIN CLASIFICAR | J26: — | L26: — | M26: SIN CLASIFICAR | N26: Instalación/equipo o caseta en malla: sin tipología directa en el catálogo (requiere presupuesto propio). Planta de agua potable. | O26: Vida útil vacía y sin tipología: se usó 70 provisional. | Estado: el texto dice 'Bueno' (2) pero la calificación numérica es 4; se usó la numérica del archivo. | Valor de reposición pendiente: digitar presupuesto propio. | P26: DEP CANCÚN (1) | Q26: 10
A27: CANCÚN | B27: 7 | C27: Zona de carga | E27: 12 | F27: 70 | G27: Bueno | H27: 2 | I27: Anexos.Ramadas_Cobertizos_Caneyes_Plus_Tipo_80 | J27: 70 | K27: 912600 | L27: Media | M27: CLASIFICADA | N27: Plataforma en concreto con cubierta metálica en voladizo. ÁREA PENDIENTE. | O27: Vida útil vacía en el archivo: se usó la del catálogo (70). | Área vacía en el archivo (ver croquis en "levantamiento en campo"). | P27: DEP CANCÚN (1) | Q27: 11
A28: CANCÚN | B28: 8 | C28: Enramada | D28: 25 | E28: 10 | F28: 30 | G28: Regular | H28: 3 | I28: Anexos.Ramadas_Cobertizos_Caneyes_Media_Tipo_60 | J28: 30 | K28: 363000 | L28: Media | M28: CLASIFICADA | N28: Estructura metálica con cubierta de zinc, sin muros. | O28: Vida útil vacía en el archivo: se usó la del catálogo (30). | P28: DEP CANCÚN (1) | Q28: 12
A29: CANCÚN | B29: 9 | C29: Caseta de desinfección | E29: 10 | F29: 70 | G29: Regular | H29: 3 | I29: SIN CLASIFICAR | J29: — | L29: — | M29: SIN CLASIFICAR | N29: Pozetas de desinfección bajo cubierta: sin tipología directa (requiere presupuesto propio). | O29: Vida útil vacía y sin tipología: se usó 70 provisional. | Área vacía en el archivo (ver croquis en "levantamiento en campo"). | Valor de reposición pendiente: digitar presupuesto propio. | P29: DEP CANCÚN (1) | Q29: 13
A30: CANCÚN | B30: 10 | C30: Enramada Combustible | D30: 51 | E30: 13 | F30: 70 | G30: Regular | H30: 3 | I30: SIN CLASIFICAR | J30: — | L30: — | M30: SIN CLASIFICAR | N30: Instalación/equipo o caseta en malla: sin tipología directa en el catálogo (requiere presupuesto propio). Enramada de combustible (contención/malla). | O30: Vida útil vacía y sin tipología: se usó 70 provisional. | Valor de reposición pendiente: digitar presupuesto propio. | P30: DEP CANCÚN (1) | Q30: 14
A31: CANCÚN | B31: 11 | C31: Baños | E31: 13 | F31: 70 | G31: Bueno | H31: 2 | I31: Anexos.Baños_2 | J31: 100 | K31: 1241200 | L31: Media | M31: CLASIFICADA | N31: Baño con acabados (piso en cerámica, muro pintado/enchapado). | O31: Vida útil del archivo (70) distinta a la del catálogo (100); se respetó el archivo. | Área vacía en el archivo (ver croquis en "levantamiento en campo"). | P31: DEP CANCÚN (2) | Q31: 5
A32: CIMARRONA | B32: 1 | C32: Casa 1 | D32: 442 | E32: 47 | F32: 70 | G32: Deficiente | H32: 3.5 | I32: 1014113_Residencial.Tipo_3 | J32: 100 | K32: 1131400 | L32: Media | M32: CLASIFICADA | N32: Bloque, pañete con pintura, teja de barro, piso cerámica. | O32: Vida útil del archivo (70) distinta a la del catálogo (100); se respetó el archivo. | P32: DEP CIMARRONA | Q32: 5
A33: CIMARRONA | B33: 2 | C33: Comedor | D33: 93.5 | E33: 45 | F33: 70 | G33: Malo | H33: 4 | I33: 1004113_Residencial.Tipo_3_Menos | J33: 100 | K33: 1014000 | L33: Media | M33: CLASIFICADA | N33: Edificación en bloque/ladrillo sin acabados, cubierta metálica. | O33: Vida útil del archivo (70) distinta a la del catálogo (100); se respetó el archivo. | P33: DEP CIMARRONA | Q33: 6
A34: CIMARRONA | B34: 3 | C34: Comedor 2 | D34: 160 | E34: 35 | F34: 70 | G34: Regular | H34: 3 | I34: Anexos.Ramadas_Cobertizos_Caneyes_Plus_Tipo_80 | J34: 70 | K34: 912600 | L34: Media | M34: CLASIFICADA | N34: Estructura abierta con cerchas metálicas y pilares en concreto. | P34: DEP CIMARRONA | Q34: 7
A35: CIMARRONA | B35: 4 | C35: Comedor casa principal | E35: 43 | F35: 70 | G35: Regular | H35: 3 | I35: 1004113_Residencial.Tipo_3_Menos | J35: 100 | K35: 1014000 | L35: Baja | M35: CLASIFICADA | N35: Edificación de 2 niveles con balcón en madera; revisar tipología. | O35: Vida útil del archivo (70) distinta a la del catálogo (100); se respetó el archivo. | Área vacía en el archivo (ver croquis en "levantamiento en campo"). | P35: DEP CIMARRONA | Q35: 8
A36: CIMARRONA | B36: 5 | C36: Empacadora | E36: 45 | F36: 70 | G36: Malo | H36: 4 | I36: 3002311_Industrial.Liviana_1 | J36: 70 | K36: 476900 | L36: Media | M36: CLASIFICADA | N36: Galpón cerrado con lámina metálica y cubierta metálica. ÁREA PENDIENTE. | O36: Área vacía en el archivo (ver croquis en "levantamiento en campo"). | P36: DEP CIMARRONA | Q36: 9
A37: CIMARRONA | B37: 6 | C37: Bodega | D37: 20 | E37: 39 | F37: 70 | G37: Malo | H37: 4 | I37: Anexos.Depósitos_1 | J37: 70 | K37: 767900 | L37: Media | M37: CLASIFICADA | N37: Cuarto/bodega pequeña en mampostería. | P37: DEP CIMARRONA | Q37: 10
A38: CIMARRONA | B38: 7 | C38: Bodega cartonera | E38: 40 | F38: 50 | G38: Deficiente | H38: 3.5 | I38: 3002311_Industrial.Liviana_1 | J38: 70 | K38: 476900 | L38: Media | M38: CLASIFICADA | N38: Galpón con cerramiento en malla/lámina y cubierta metálica. ÁREA PENDIENTE. | O38: Vida útil del archivo (50) distinta a la del catálogo (70); se respetó el archivo. | Área vacía en el archivo (ver croquis en "levantamiento en campo"). | P38: DEP CIMARRONA | Q38: 11
A39: CIMARRONA | B39: 8 | C39: Caseta del gas | D39: 9 | E39: 40 | F39: 70 | G39: Regular | H39: 3 | I39: Anexos.Depósitos_1 | J39: 70 | K39: 767900 | L39: Media | M39: CLASIFICADA | N39: Caseta pequeña en mampostería. | O39: Vida útil vacía en el archivo: se usó la del catálogo (70). | P39: DEP CIMARRONA | Q39: 12
A40: CIMARRONA | B40: 9 | C40: Comedor empacadora | E40: 40 | F40: 70 | G40: Regular | H40: 3 | I40: Anexos.Ramadas_Cobertizos_Caneyes_Media_Tipo_60 | J40: 30 | K40: 363000 | L40: Media | M40: CLASIFICADA | N40: Estructura con columnas metálicas, muro bajo y cubierta de lámina. | O40: Vida útil vacía y sin referencia válida (catálogo ≤ edad o sin tipología): se usó 70 provisional. | Área vacía en el archivo (ver croquis en "levantamiento en campo"). | P40: DEP CIMARRONA | Q40: 13
A41: CIMARRONA | B41: 10 | C41: Baños | E41: 41 | F41: 70 | G41: Regular | H41: 3 | I41: Anexos.Baños_1 | J41: 70 | K41: 930700 | L41: Baja | M41: CLASIFICADA | N41: Baños pequeños en mampostería sencilla. | O41: Área vacía en el archivo (ver croquis en "levantamiento en campo"). | P41: DEP CIMARRONA | Q41: 14
...

Sheet SIN CLASIFICAR
A1: CONSTRUCCIONES SIN TIPOLOGÍA EN EL CATÁLOGO – PENDIENTES DE PRESUPUESTO PROPIO
A3: Predio | B3: Nº | C3: Ítem | D3: Área (m²) | E3: Edad | F3: Vida útil provisional | G3: Calif. | H3: Motivo | I3: Dónde digitar el valor de reposición ($/m²) | J3: Presupuesto propio $/m² (referencia)
A4: PORCIÓN 1-2-3 | B4: 3 | C4: Caseta de Fertilizantes | D4: =4*4 | E4: 40 | F4: 70 | G4: 3 | H4: Instalación/equipo o caseta en malla: sin tipología directa en el catálogo (requiere presupuesto propio). Murete + malla eslabonada + cubierta zinc. | I4: 'DEP PORCIÓN 1-2-3'!F7
A5: PORCIÓN 1-2-3 | B5: 6 | C5: Planta agua potable | D5: =2.2*3 | E5: 45 | F5: 70 | G5: 3 | H5: Instalación/equipo o caseta en malla: sin tipología directa en el catálogo (requiere presupuesto propio). Planta de agua potable. | I5: 'DEP PORCIÓN 1-2-3'!F10
A6: PORCIÓN 1-2-3 | B6: 7 | C6: Caseta Planta electrica | D6: =2.5*2.75 | E6: 40 | F6: 70 | G6: 3 | H6: Instalación/equipo o caseta en malla: sin tipología directa en el catálogo (requiere presupuesto propio). Caseta de planta eléctrica. | I6: 'DEP PORCIÓN 1-2-3'!F11
A7: PORCIÓN 1-2-3 | B7: 8 | C7: Ramada Aceite | D7: 28.88 | E7: 40 | F7: 70 | G7: 3 | H7: Instalación/equipo o caseta en malla: sin tipología directa en el catálogo (requiere presupuesto propio). Ramada de aceite con cerramiento en malla. | I7: 'DEP PORCIÓN 1-2-3'!F12
A8: PORCIÓN 1-2-3 | B8: 9 | C8: Caseta de desinfección | D8: =8.1*2.5 | E8: 40 | F8: 70 | G8: 3 | H8: Pozetas de desinfección bajo cubierta: sin tipología directa (requiere presupuesto propio). | I8: 'DEP PORCIÓN 1-2-3'!F13
A9: CANCÚN | B9: 6 | C9: Planta agua potable | D9: 21 | E9: 15 | F9: 70 | G9: 4 | H9: Instalación/equipo o caseta en malla: sin tipología directa en el catálogo (requiere presupuesto propio). Planta de agua potable. | I9: 'DEP CANCÚN (1)'!F10
A10: CANCÚN | B10: 9 | C10: Caseta de desinfección | E10: 10 | F10: 70 | G10: 3 | H10: Pozetas de desinfección bajo cubierta: sin tipología directa (requiere presupuesto propio). | I10: 'DEP CANCÚN (1)'!F13
A11: CANCÚN | B11: 10 | C11: Enramada Combustible | D11: 51 | E11: 13 | F11: 70 | G11: 3 | H11: Instalación/equipo o caseta en malla: sin tipología directa en el catálogo (requiere presupuesto propio). Enramada de combustible (contención/malla). | I11: 'DEP CANCÚN (1)'!F14
A12: CARI CARI | B12: 4 | C12: Baño - Tanque | D12: 21.6 | E12: 30 | F12: 70 | G12: 4 | H12: Baño combinado con tanque elevado: sin tipología directa (requiere presupuesto propio). | I12: 'DEP CARI CARI'!F8
A13: EL CORUAL | B13: 3 | C13: Bomba ACPM | E13: 35 | F13: 70 | G13: 3.5 | H13: Tanque de ACPM sobre base en concreto: instalación sin tipología directa. | I13: 'DEP EL CORUAL (1)'!F8
A14: EL CORUAL | B14: 4 | C14: Bomba Aceite | E14: 25 | F14: 70 | G14: 4 | H14: Tanques de aceite sobre plataforma: instalación sin tipología directa. | I14: 'DEP EL CORUAL (1)'!F9
A15: EL CORUAL | B15: 5 | C15: Cable vía | E15: 35 | F15: 70 | G15: 3.5 | H15: Cable vía (sistema de transporte de racimos): sin tipología directa. | I15: 'DEP EL CORUAL (1)'!F10
A16: EL CORUAL | B16: 11 | C16: Máquina de bombeo | E16: 28 | F16: 70 | G16: 3 | H16: Casa de bombeo con equipos: instalación sin tipología directa. | I16: 'DEP EL CORUAL (2)'!F5
A17: LAS MERCEDES | B17: 4 | C17: Zona de lavado | E17: 19 | F17: 50 | G17: 3 | H17: Zona de lavado/agroquímicos con cerramiento en malla y ducha de emergencia: sin tipología directa. | I17: 'DEP LAS MERCEDES (1)'!F8
A18: LAS MERCEDES | B18: 15 | C18: Tanque combustible | E18: 21 | F18: 70 | G18: 4 | H18: Tanques de combustible elevados con contención: instalación sin tipología directa. | I18: 'DEP LAS MERCEDES (2)'!F9

Sheet NOTAS
A1: CRITERIOS APLICADOS
A2: 1. Valores de reposición: Catálogo IGAC de Tipologías Constructivas (vigencia oct-2025 a oct-2026), columna REGIÓN NORTE (incluye Magdalena y Atlántico). Unidad: $/m².
A3: 2. Depreciación: método Ross-Heidecke del formato rural (hojas DEP = copia de DEPRECIACIÓN; hojas LIQ = copia de LIQUIDACIÓN). No se modificó ninguna fórmula; solo se cargaron los datos azules (edad, vida útil, calificación, valor de reposición y área).
A4: 3. Edad, vida útil, estado y área provienen del Excel de construcciones. Si la vida útil estaba vacía se tomó la del catálogo; si esa resultaba ≤ edad se usó 70 (criterio del archivo) y se marcó en amarillo.
A5: 4. Estado: el archivo trae texto (Bueno, Regular…) y número. Donde no coinciden se usó el NÚMERO del archivo y se marcó en naranja (ver hoja CLASIFICACIÓN, columna Alertas). Conviene revisarlos: un "Bueno" con 4 deprecia ~50 %.
A6: 5. Áreas vacías: en el archivo de construcciones varias áreas no están digitadas (probablemente solo en los croquis de "levantamiento en campo"). Quedaron en blanco (naranja) y aportan $0.
A7: 6. Construcciones sin clasificar (rosado): valor de reposición vacío para que digite su presupuesto propio (columna F de la hoja DEP; ver hoja SIN CLASIFICAR). Mientras estén vacías aportan $0.
A8: 7. Construcción principal = primera fila de cada hoja. En EL CORUAL se puso "La casona" y en LAS MERCEDES "Oficinas" en primer lugar; en los demás predios se respetó el orden del archivo.
A9: 8. El formato admite 10 construcciones por hoja: CANCÚN, EL CORUAL y LAS MERCEDES se dividen en dos hojas (1) y (2). En la hoja (2) la superficie de terreno queda en 0.
A10: 9. TERRENO: no hay datos de terreno en el archivo de construcciones; la superficie (Ha) quedó en 0 y el valor por Ha lo toma de la hoja MERCADO RURAL (celda H24, hoja de apoyo) o se digita en E5 de cada LIQ.
A11: 10. Hoja AUX_COMBINACIONES (oculta) y MERCADO RURAL son hojas de apoyo mínimas para que las fórmulas de vínculo del formato no den error.
A12: 11. Columnas V:W de cada hoja DEP (tipología y confianza) son informativas y están fuera del rango de las fórmulas.

Sheet DEP LÍBANO
A1: DEPRECIACIÓN DE CONSTRUCCIONES MÉTODO ROSS – HEIDECKE
A2: PREDIO LÍBANO · Valores de reposición: Catálogo IGAC de Tipologías Constructivas (vigencia oct-2025 a oct-2026), Región Norte
A3: CÁLCULO DEL VALOR POR ESTADO DE CONSERVACIÓN SEGÚN ROSS - HEIDECKE
A4: OFERTA No. | B4: ÍTEM | C4: EDAD (años) | D4: VIDA ÚTIL (años) | E4: CALIFICACIÓN ESTADO | F4: VALOR REPOSICIÓN | G4: % (DE VIDA) | H4: FACTOR DEPRECIACIÓN POR EDAD ROSS | I4: E = FACTOR DEPRECIACIÓN POR ESTADO HEIDECKE | J4: K = DEPRECIACIÓN (tabla Ross-Heidecke) | K4: VALOR DEPRECIADO | L4: FD = FACTOR DEPRECIACIÓN | M4: VALOR ACTUAL (VALOR DEPRECIADO) | N4: VALOR ADOPTADO | O4: ÁREA CONSTRUIDA (m²) | P4: VALOR TOTAL CONSTRUCCIÓN (N × O) | Q4: ORDEN EN LIQUIDACIÓN (A vacío = predio objeto) | S4: TABLA HEIDECKE | V4: TIPOLOGÍA CATÁLOGO IGAC (Región Norte) | W4: CONFIANZA
B5: Casa Principal | C5: 30 | D5: 70 | E5: 2 | F5: 1131400 | G5: =IF($B5="","",C5/D5) | H5: =IF($B5="","",1-0.5*(G5+G5^2)) | I5: =IF($B5="","",1-INDEX($T$6:$T$14,MATCH(E5,$S$6:$S$14,0))) | J5: =IF($B5="","",1-H5*I5) | K5: =IF($B5="","",F5*J5) | L5: =IF($B5="","",I5*H5) | M5: =IF($B5="","",F5*L5) | N5: =IF($B5="","",MROUND(M5,1000)) | O5: 96.88 | P5: =IF($B5="","",MROUND(N5*O5,100)) | Q5: =IF(AND($B5<>"",$A5=""),COUNTIFS($A$5:$A5,"",$B$5:$B5,"<>"),"") | S5: CALIFICACIÓN | T5: % DEPRECIACIÓN | V5: 1014113_Residencial.Tipo_3 | W5: Alta
B6: Casa Mayordomo | C6: 30 | D6: 70 | E6: 3 | F6: 1014000 | G6: =IF($B6="","",C6/D6) | H6: =IF($B6="","",1-0.5*(G6+G6^2)) | I6: =IF($B6="","",1-INDEX($T$6:$T$14,MATCH(E6,$S$6:$S$14,0))) | J6: =IF($B6="","",1-H6*I6) | K6: =IF($B6="","",F6*J6) | L6: =IF($B6="","",I6*H6) | M6: =IF($B6="","",F6*L6) | N6: =IF($B6="","",MROUND(M6,1000)) | O6: 59.29 | P6: =IF($B6="","",MROUND(N6*O6,100)) | Q6: =IF(AND($B6<>"",$A6=""),COUNTIFS($A$5:$A6,"",$B$5:$B6,"<>"),"") | S6: 1 | T6: 0 | V6: 1004113_Residencial.Tipo_3_Menos | W6: Media
B7: Casa pequeña | C7: 25 | D7: 70 | E7: 3 | F7: 1014000 | G7: =IF($B7="","",C7/D7) | H7: =IF($B7="","",1-0.5*(G7+G7^2)) | I7: =IF($B7="","",1-INDEX($T$6:$T$14,MATCH(E7,$S$6:$S$14,0))) | J7: =IF($B7="","",1-H7*I7) | K7: =IF($B7="","",F7*J7) | L7: =IF($B7="","",I7*H7) | M7: =IF($B7="","",F7*L7) | N7: =IF($B7="","",MROUND(M7,1000)) | O7: 69.97 | P7: =IF($B7="","",MROUND(N7*O7,100)) | Q7: =IF(AND($B7<>"",$A7=""),COUNTIFS($A$5:$A7,"",$B$5:$B7,"<>"),"") | S7: 1.5 | T7: 0.00032 | V7: 1004113_Residencial.Tipo_3_Menos | W7: Media
B8: Bodega principal | C8: 30 | D8: 70 | E8: 3.5 | F8: 1226000 | G8: =IF($B8="","",C8/D8) | H8: =IF($B8="","",1-0.5*(G8+G8^2)) | I8: =IF($B8="","",1-INDEX($T$6:$T$14,MATCH(E8,$S$6:$S$14,0))) | J8: =IF($B8="","",1-H8*I8) | K8: =IF($B8="","",F8*J8) | L8: =IF($B8="","",I8*H8) | M8: =IF($B8="","",F8*L8) | N8: =IF($B8="","",MROUND(M8,1000)) | O8: 72 | P8: =IF($B8="","",MROUND(N8*O8,100)) | Q8: =IF(AND($B8<>"",$A8=""),COUNTIFS($A$5:$A8,"",$B$5:$B8,"<>"),"") | S8: 2 | T8: 0.0252 | V8: 3001121_Industrial.Liviana_2 | W8: Media
B9: Cuarto útil | C9: 30 | D9: 70 | E9: 3.5 | F9: 767900 | G9: =IF($B9="","",C9/D9) | H9: =IF($B9="","",1-0.5*(G9+G9^2)) | I9: =IF($B9="","",1-INDEX($T$6:$T$14,MATCH(E9,$S$6:$S$14,0))) | J9: =IF($B9="","",1-H9*I9) | K9: =IF($B9="","",F9*J9) | L9: =IF($B9="","",I9*H9) | M9: =IF($B9="","",F9*L9) | N9: =IF($B9="","",MROUND(M9,1000)) | O9: 9 | P9: =IF($B9="","",MROUND(N9*O9,100)) | Q9: =IF(AND($B9<>"",$A9=""),COUNTIFS($A$5:$A9,"",$B$5:$B9,"<>"),"") | S9: 2.5 | T9: 0.0809 | V9: Anexos.Depósitos_1 | W9: Media
B10: Bodega auxiliar | C10: 30 | D10: 50 | E10: 3.5 | F10: 767900 | G10: =IF($B10="","",C10/D10) | H10: =IF($B10="","",1-0.5*(G10+G10^2)) | I10: =IF($B10="","",1-INDEX($T$6:$T$14,MATCH(E10,$S$6:$S$14,0))) | J10: =IF($B10="","",1-H10*I10) | K10: =IF($B10="","",F10*J10) | L10: =IF($B10="","",I10*H10) | M10: =IF($B10="","",F10*L10) | N10: =IF($B10="","",MROUND(M10,1000)) | O10: 8.32 | P10: =IF($B10="","",MROUND(N10*O10,100)) | Q10: =IF(AND($B10<>"",$A10=""),COUNTIFS($A$5:$A10,"",$B$5:$B10,"<>"),"") | S10: 3 | T10: 0.181 | V10: Anexos.Depósitos_1 | W10: Media
G11: =IF($B11="","",C11/D11) | H11: =IF($B11="","",1-0.5*(G11+G11^2)) | I11: =IF($B11="","",1-INDEX($T$6:$T$14,MATCH(E11,$S$6:$S$14,0))) | J11: =IF($B11="","",1-H11*I11) | K11: =IF($B11="","",F11*J11) | L11: =IF($B11="","",I11*H11) | M11: =IF($B11="","",F11*L11) | N11: =IF($B11="","",MROUND(M11,1000)) | P11: =IF($B11="","",MROUND(N11*O11,100)) | Q11: =IF(AND($B11<>"",$A11=""),COUNTIFS($A$5:$A11,"",$B$5:$B11,"<>"),"") | S11: 3.5 | T11: 0.332
G12: =IF($B12="","",C12/D12) | H12: =IF($B12="","",1-0.5*(G12+G12^2)) | I12: =IF($B12="","",1-INDEX($T$6:$T$14,MATCH(E12,$S$6:$S$14,0))) | J12: =IF($B12="","",1-H12*I12) | K12: =IF($B12="","",F12*J12) | L12: =IF($B12="","",I12*H12) | M12: =IF($B12="","",F12*L12) | N12: =IF($B12="","",MROUND(M12,1000)) | P12: =IF($B12="","",MROUND(N12*O12,100)) | Q12: =IF(AND($B12<>"",$A12=""),COUNTIFS($A$5:$A12,"",$B$5:$B12,"<>"),"") | S12: 4 | T12: 0.526
G13: =IF($B13="","",C13/D13) | H13: =IF($B13="","",1-0.5*(G13+G13^2)) | I13: =IF($B13="","",1-INDEX($T$6:$T$14,MATCH(E13,$S$6:$S$14,0))) | J13: =IF($B13="","",1-H13*I13) | K13: =IF($B13="","",F13*J13) | L13: =IF($B13="","",I13*H13) | M13: =IF($B13="","",F13*L13) | N13: =IF($B13="","",MROUND(M13,1000)) | P13: =IF($B13="","",MROUND(N13*O13,100)) | Q13: =IF(AND($B13<>"",$A13=""),COUNTIFS($A$5:$A13,"",$B$5:$B13,"<>"),"") | S13: 4.5 | T13: 0.752
G14: =IF($B14="","",C14/D14) | H14: =IF($B14="","",1-0.5*(G14+G14^2)) | I14: =IF($B14="","",1-INDEX($T$6:$T$14,MATCH(E14,$S$6:$S$14,0))) | J14: =IF($B14="","",1-H14*I14) | K14: =IF($B14="","",F14*J14) | L14: =IF($B14="","",I14*H14) | M14: =IF($B14="","",F14*L14) | N14: =IF($B14="","",MROUND(M14,1000)) | P14: =IF($B14="","",MROUND(N14*O14,100)) | Q14: =IF(AND($B14<>"",$A14=""),COUNTIFS($A$5:$A14,"",$B$5:$B14,"<>"),"") | S14: 5 | T14: 1
A15: TOTAL | F15: =SUM(F5:F14) | K15: =SUM(K5:K14) | M15: =SUM(M5:M14) | N15: =SUM(N5:N14) | P15: =SUM(P5:P14)
A17: VÍNCULO CON LA TABLA DE MERCADO – VALOR ESTIMADO DE CONSTRUCCIONES POR OFERTA (se actualiza con las ofertas de 'MERCADO RURAL', hasta 20)
A18: No. | B18: UBICACIÓN | F18: Nº CONSTRUC-CIONES | G18: VALOR REPOSICIÓN TOTAL (F × O) | J18: DEPRECIACIÓN (reposición − valor actual) | M18: VALOR ESTIMADO CONSTRUCCIONES
A19: =IF((ROWS($A$19:$A19)+8)>AUX_COMBINACIONES!$C$3,"",IF(INDEX('MERCADO RURAL'!$A:$A,(ROWS($A$19:$A19)+8))="","",INDEX('MERCADO RURAL'!$A:$A,(ROWS($A$19:$A19)+8)))) | B19: =IF($A19="","",INDEX('MERCADO RURAL'!$B:$B,(ROWS($A$19:$A19)+8))) | F19: =IF($A19="","",COUNTIFS($A$5:$A$14,$A19,$B$5:$B$14,"<>")) | G19: =IF($A19="","",SUMPRODUCT(($A$5:$A$14=$A19)*$F$5:$F$14*$O$5:$O$14)) | J19: =IF($A19="","",G19-M19) | M19: =IF($A19="","",SUMIFS($P$5:$P$14,$A$5:$A$14,$A19))
A20: =IF((ROWS($A$19:$A20)+8)>AUX_COMBINACIONES!$C$3,"",IF(INDEX('MERCADO RURAL'!$A:$A,(ROWS($A$19:$A20)+8))="","",INDEX('MERCADO RURAL'!$A:$A,(ROWS($A$19:$A20)+8)))) | B20: =IF($A20="","",INDEX('MERCADO RURAL'!$B:$B,(ROWS($A$19:$A20)+8))) | F20: =IF($A20="","",COUNTIFS($A$5:$A$14,$A20,$B$5:$B$14,"<>")) | G20: =IF($A20="","",SUMPRODUCT(($A$5:$A$14=$A20)*$F$5:$F$14*$O$5:$O$14)) | J20: =IF($A20="","",G20-M20) | M20: =IF($A20="","",SUMIFS($P$5:$P$14,$A$5:$A$14,$A20))
A21: =IF((ROWS($A$19:$A21)+8)>AUX_COMBINACIONES!$C$3,"",IF(INDEX('MERCADO RURAL'!$A:$A,(ROWS($A$19:$A21)+8))="","",INDEX('MERCADO RURAL'!$A:$A,(ROWS($A$19:$A21)+8)))) | B21: =IF($A21="","",INDEX('MERCADO RURAL'!$B:$B,(ROWS($A$19:$A21)+8))) | F21: =IF($A21="","",COUNTIFS($A$5:$A$14,$A21,$B$5:$B$14,"<>")) | G21: =IF($A21="","",SUMPRODUCT(($A$5:$A$14=$A21)*$F$5:$F$14*$O$5:$O$14)) | J21: =IF($A21="","",G21-M21) | M21: =IF($A21="","",SUMIFS($P$5:$P$14,$A$5:$A$14,$A21))
A22: =IF((ROWS($A$19:$A22)+8)>AUX_COMBINACIONES!$C$3,"",IF(INDEX('MERCADO RURAL'!$A:$A,(ROWS($A$19:$A22)+8))="","",INDEX('MERCADO RURAL'!$A:$A,(ROWS($A$19:$A22)+8)))) | B22: =IF($A22="","",INDEX('MERCADO RURAL'!$B:$B,(ROWS($A$19:$A22)+8))) | F22: =IF($A22="","",COUNTIFS($A$5:$A$14,$A22,$B$5:$B$14,"<>")) | G22: =IF($A22="","",SUMPRODUCT(($A$5:$A$14=$A22)*$F$5:$F$14*$O$5:$O$14)) | J22: =IF($A22="","",G22-M22) | M22: =IF($A22="","",SUMIFS($P$5:$P$14,$A$5:$A$14,$A22))
A23: =IF((ROWS($A$19:$A23)+8)>AUX_COMBINACIONES!$C$3,"",IF(INDEX('MERCADO RURAL'!$A:$A,(ROWS($A$19:$A23)+8))="","",INDEX('MERCADO RURAL'!$A:$A,(ROWS($A$19:$A23)+8)))) | B23: =IF($A23="","",INDEX('MERCADO RURAL'!$B:$B,(ROWS($A$19:$A23)+8))) | F23: =IF($A23="","",COUNTIFS($A$5:$A$14,$A23,$B$5:$B$14,"<>")) | G23: =IF($A23="","",SUMPRODUCT(($A$5:$A$14=$A23)*$F$5:$F$14*$O$5:$O$14)) | J23: =IF($A23="","",G23-M23) | M23: =IF($A23="","",SUMIFS($P$5:$P$14,$A$5:$A$14,$A23))
A24: =IF((ROWS($A$19:$A24)+8)>AUX_COMBINACIONES!$C$3,"",IF(INDEX('MERCADO RURAL'!$A:$A,(ROWS($A$19:$A24)+8))="","",INDEX('MERCADO RURAL'!$A:$A,(ROWS($A$19:$A24)+8)))) | B24: =IF($A24="","",INDEX('MERCADO RURAL'!$B:$B,(ROWS($A$19:$A24)+8))) | F24: =IF($A24="","",COUNTIFS($A$5:$A$14,$A24,$B$5:$B$14,"<>")) | G24: =IF($A24="","",SUMPRODUCT(($A$5:$A$14=$A24)*$F$5:$F$14*$O$5:$O$14)) | J24: =IF($A24="","",G24-M24) | M24: =IF($A24="","",SUMIFS($P$5:$P$14,$A$5:$A$14,$A24))
A25: =IF((ROWS($A$19:$A25)+8)>AUX_COMBINACIONES!$C$3,"",IF(INDEX('MERCADO RURAL'!$A:$A,(ROWS($A$19:$A25)+8))="","",INDEX('MERCADO RURAL'!$A:$A,(ROWS($A$19:$A25)+8)))) | B25: =IF($A25="","",INDEX('MERCADO RURAL'!$B:$B,(ROWS($A$19:$A25)+8))) | F25: =IF($A25="","",COUNTIFS($A$5:$A$14,$A25,$B$5:$B$14,"<>")) | G25: =IF($A25="","",SUMPRODUCT(($A$5:$A$14=$A25)*$F$5:$F$14*$O$5:$O$14)) | J25: =IF($A25="","",G25-M25) | M25: =IF($A25="","",SUMIFS($P$5:$P$14,$A$5:$A$14,$A25))
A26: =IF((ROWS($A$19:$A26)+8)>AUX_COMBINACIONES!$C$3,"",IF(INDEX('MERCADO RURAL'!$A:$A,(ROWS($A$19:$A26)+8))="","",INDEX('MERCADO RURAL'!$A:$A,(ROWS($A$19:$A26)+8)))) | B26: =IF($A26="","",INDEX('MERCADO RURAL'!$B:$B,(ROWS($A$19:$A26)+8))) | F26: =IF($A26="","",COUNTIFS($A$5:$A$14,$A26,$B$5:$B$14,"<>")) | G26: =IF($A26="","",SUMPRODUCT(($A$5:$A$14=$A26)*$F$5:$F$14*$O$5:$O$14)) | J26: =IF($A26="","",G26-M26) | M26: =IF($A26="","",SUMIFS($P$5:$P$14,$A$5:$A$14,$A26))
A27: =IF((ROWS($A$19:$A27)+8)>AUX_COMBINACIONES!$C$3,"",IF(INDEX('MERCADO RURAL'!$A:$A,(ROWS($A$19:$A27)+8))="","",INDEX('MERCADO RURAL'!$A:$A,(ROWS($A$19:$A27)+8)))) | B27: =IF($A27="","",INDEX('MERCADO RURAL'!$B:$B,(ROWS($A$19:$A27)+8))) | F27: =IF($A27="","",COUNTIFS($A$5:$A$14,$A27,$B$5:$B$14,"<>")) | G27: =IF($A27="","",SUMPRODUCT(($A$5:$A$14=$A27)*$F$5:$F$14*$O$5:$O$14)) | J27: =IF($A27="","",G27-M27) | M27: =IF($A27="","",SUMIFS($P$5:$P$14,$A$5:$A$14,$A27))
A28: =IF((ROWS($A$19:$A28)+8)>AUX_COMBINACIONES!$C$3,"",IF(INDEX('MERCADO RURAL'!$A:$A,(ROWS($A$19:$A28)+8))="","",INDEX('MERCADO RURAL'!$A:$A,(ROWS($A$19:$A28)+8)))) | B28: =IF($A28="","",INDEX('MERCADO RURAL'!$B:$B,(ROWS($A$19:$A28)+8))) | F28: =IF($A28="","",COUNTIFS($A$5:$A$14,$A28,$B$5:$B$14,"<>")) | G28: =IF($A28="","",SUMPRODUCT(($A$5:$A$14=$A28)*$F$5:$F$14*$O$5:$O$14)) | J28: =IF($A28="","",G28-M28) | M28: =IF($A28="","",SUMIFS($P$5:$P$14,$A$5:$A$14,$A28))
A29: =IF((ROWS($A$19:$A29)+8)>AUX_COMBINACIONES!$C$3,"",IF(INDEX('MERCADO RURAL'!$A:$A,(ROWS($A$19:$A29)+8))="","",INDEX('MERCADO RURAL'!$A:$A,(ROWS($A$19:$A29)+8)))) | B29: =IF($A29="","",INDEX('MERCADO RURAL'!$B:$B,(ROWS($A$19:$A29)+8))) | F29: =IF($A29="","",COUNTIFS($A$5:$A$14,$A29,$B$5:$B$14,"<>")) | G29: =IF($A29="","",SUMPRODUCT(($A$5:$A$14=$A29)*$F$5:$F$14*$O$5:$O$14)) | J29: =IF($A29="","",G29-M29) | M29: =IF($A29="","",SUMIFS($P$5:$P$14,$A$5:$A$14,$A29))
A30: =IF((ROWS($A$19:$A30)+8)>AUX_COMBINACIONES!$C$3,"",IF(INDEX('MERCADO RURAL'!$A:$A,(ROWS($A$19:$A30)+8))="","",INDEX('MERCADO RURAL'!$A:$A,(ROWS($A$19:$A30)+8)))) | B30: =IF($A30="","",INDEX('MERCADO RURAL'!$B:$B,(ROWS($A$19:$A30)+8))) | F30: =IF($A30="","",COUNTIFS($A$5:$A$14,$A30,$B$5:$B$14,"<>")) | G30: =IF($A30="","",SUMPRODUCT(($A$5:$A$14=$A30)*$F$5:$F$14*$O$5:$O$14)) | J30: =IF($A30="","",G30-M30) | M30: =IF($A30="","",SUMIFS($P$5:$P$14,$A$5:$A$14,$A30))
... A38: =IF((ROWS($A$19:$A38)+8)>AUX_COMBINACIONES!$C$3,"",IF(INDEX('MERCADO RURAL'!$A:$A,(ROWS($A$19:$A38)+8))="","",INDEX('MERCADO RURAL'!$A:$A,(ROWS($A$19:$A38)+8)))) | B38: =IF($A38="","",INDEX('MERCADO RURAL'!$B:$B,(ROWS($A$19:$A38)+8))) | F38: =IF($A38="","",COUNTIFS($A$5:$A$14,$A38,$B$5:$B$14,"<>")) | G38: =IF($A38="","",SUMPRODUCT(($A$5:$A$14=$A38)*$F$5:$F$14*$O$5:$O$14)) | J38: =IF($A38="","",G38-M38) | M38: =IF($A38="","",SUMIFS($P$5:$P$14,$A$5:$A$14,$A38))
A39: TOTAL ASIGNADO A OFERTAS | F39: =SUM(F19:F38) | G39: =SUM(G19:G38) | J39: =SUM(J19:J38) | M39: =SUM(M19:M38)
A40: Construcciones del predio objeto (sin oferta asignada) – pasan a la hoja LIQUIDACIÓN | M40: =SUMIFS($P$5:$P$14,$A$5:$A$14,"",$B$5:$B$14,"<>")
A41: Control: total tabla = asignado a ofertas + predio objeto (debe ser 0) | M41: =P15-M39-M40
A43: Instrucciones: (1) Digite en la columna A el No. de la oferta de 'MERCADO RURAL' a la que pertenece cada construcción; si la deja vacía, la construcción pertenece al predio objeto y se lista en 'LIQUIDACIÓN' en el orden de la columna Q. (2) Los datos en azul son editables: edad, vida útil, calificación (1 a 5, pasos de 0,5), valor de reposición por m² y área construida (m²). (3) El valor total de cada construcción (columna P = valor adoptado por m² × área) se suma por oferta y alimenta 'MERCADO RURAL' (columna Valor estimado construcciones). (4) Capacidad: 10 construcciones y 20 ofertas.

Sheet LIQ LÍBANO
B2: TABLA DE VALORES – PREDIO LÍBANO
B3: TERRENO | H3: CÁLCULO AUXILIAR – VALOR EN LETRAS
B4: DESCRIPCIÓN | C4: UNIDAD | D4: CANTIDAD | E4: VALOR UNITARIO | F4: VALOR TOTAL | H4: CONCEPTO | I4: VALOR | J4: TEXTO | K4: TEXTO (APOCOPADO) | N4: UNIDADES 1–29 | O4: DECENAS 30–90
B5: ='MERCADO RURAL'!E4 | C5: Ha | D5: 0 | E5: ='MERCADO RURAL'!H24 | F5: =MROUND(D5*E5,100) | H5: Valor total (entero) | I5: =ROUND(F22,0) | N5: UNO | O5: TREINTA
B6: CONSTRUCCIÓN PRINCIPAL | H6: Millones totales | I6: =INT(I5/10^6) | N6: DOS | O6: CUARENTA
B7: DESCRIPCIÓN | C7: UNIDAD | D7: CANTIDAD | E7: VALOR UNITARIO | F7: VALOR TOTAL | H7: Bloque miles de millones | I7: =INT(I6/1000) | J7: =IF(I7=0,"",IF(I7=100,"CIEN",TRIM(CHOOSE(INT(I7/100)+1,"","CIENTO ","DOSCIENTOS ","TRESCIENTOS ","CUATROCIENTOS ","QUINIENTOS ","SEISCIENTOS ","SETECIENTOS ","OCHOCIENTOS ","NOVECIENTOS ")&IF(MOD(I7,100)=0,"",IF(MOD(I7,100)<30,INDEX($N$5:$N$33,MOD(I7,100)),INDEX($O$5:$O$11,INT(MOD(I7,100)/10)-2)&IF(MOD(I7,10)=0,""," Y "&INDEX($N$5:$N$13,MOD(I7,10)))))))) | K7: =IF(RIGHT(J7,9)="VEINTIUNO",LEFT(J7,LEN(J7)-9)&"VEINTIÚN",IF(RIGHT(J7,3)="UNO",LEFT(J7,LEN(J7)-1),J7)) | N7: TRES | O7: CINCUENTA
B8: =IFERROR(UPPER(INDEX('DEP LÍBANO'!$B$5:$B$14,MATCH(1,'DEP LÍBANO'!$Q$5:$Q$14,0))),"") | C8: =IF(B8="","","m²") | D8: =IF(B8="","",INDEX('DEP LÍBANO'!$O$5:$O$14,MATCH(1,'DEP LÍBANO'!$Q$5:$Q$14,0))) | E8: =IF(B8="","",INDEX('DEP LÍBANO'!$N$5:$N$14,MATCH(1,'DEP LÍBANO'!$Q$5:$Q$14,0))) | F8: =IF(B8="","",MROUND(D8*E8,100)) | H8: Bloque millones | I8: =MOD(I6,1000) | J8: =IF(I8=0,"",IF(I8=100,"CIEN",TRIM(CHOOSE(INT(I8/100)+1,"","CIENTO ","DOSCIENTOS ","TRESCIENTOS ","CUATROCIENTOS ","QUINIENTOS ","SEISCIENTOS ","SETECIENTOS ","OCHOCIENTOS ","NOVECIENTOS ")&IF(MOD(I8,100)=0,"",IF(MOD(I8,100)<30,INDEX($N$5:$N$33,MOD(I8,100)),INDEX($O$5:$O$11,INT(MOD(I8,100)/10)-2)&IF(MOD(I8,10)=0,""," Y "&INDEX($N$5:$N$13,MOD(I8,10)))))))) | K8: =IF(RIGHT(J8,9)="VEINTIUNO",LEFT(J8,LEN(J8)-9)&"VEINTIÚN",IF(RIGHT(J8,3)="UNO",LEFT(J8,LEN(J8)-1),J8)) | N8: CUATRO | O8: SESENTA
B9: VALOR TOTAL DE LA CONSTRUCCIÓN PRINCIPAL | F9: =SUM(F8:F8) | H9: Bloque miles | I9: =INT(MOD(I5,10^6)/1000) | J9: =IF(I9=0,"",IF(I9=100,"CIEN",TRIM(CHOOSE(INT(I9/100)+1,"","CIENTO ","DOSCIENTOS ","TRESCIENTOS ","CUATROCIENTOS ","QUINIENTOS ","SEISCIENTOS ","SETECIENTOS ","OCHOCIENTOS ","NOVECIENTOS ")&IF(MOD(I9,100)=0,"",IF(MOD(I9,100)<30,INDEX($N$5:$N$33,MOD(I9,100)),INDEX($O$5:$O$11,INT(MOD(I9,100)/10)-2)&IF(MOD(I9,10)=0,""," Y "&INDEX($N$5:$N$13,MOD(I9,10)))))))) | K9: =IF(RIGHT(J9,9)="VEINTIUNO",LEFT(J9,LEN(J9)-9)&"VEINTIÚN",IF(RIGHT(J9,3)="UNO",LEFT(J9,LEN(J9)-1),J9)) | N9: CINCO | O9: SETENTA
B10: CONSTRUCCIONES ANEXAS | H10: Bloque unidades | I10: =MOD(I5,1000) | J10: =IF(I10=0,"",IF(I10=100,"CIEN",TRIM(CHOOSE(INT(I10/100)+1,"","CIENTO ","DOSCIENTOS ","TRESCIENTOS ","CUATROCIENTOS ","QUINIENTOS ","SEISCIENTOS ","SETECIENTOS ","OCHOCIENTOS ","NOVECIENTOS ")&IF(MOD(I10,100)=0,"",IF(MOD(I10,100)<30,INDEX($N$5:$N$33,MOD(I10,100)),INDEX($O$5:$O$11,INT(MOD(I10,100)/10)-2)&IF(MOD(I10,10)=0,""," Y "&INDEX($N$5:$N$13,MOD(I10,10)))))))) | N10: SEIS | O10: OCHENTA
B11: DESCRIPCIÓN | C11: UNIDAD | D11: CANTIDAD | E11: VALOR UNITARIO | F11: VALOR TOTAL | N11: SIETE | O11: NOVENTA
B12: =IFERROR(UPPER(INDEX('DEP LÍBANO'!$B$5:$B$14,MATCH((ROWS($B$12:$B12)+1),'DEP LÍBANO'!$Q$5:$Q$14,0))),"") | C12: =IF(B12="","","m²") | D12: =IF(B12="","",INDEX('DEP LÍBANO'!$O$5:$O$14,MATCH((ROWS($B$12:$B12)+1),'DEP LÍBANO'!$Q$5:$Q$14,0))) | E12: =IF(B12="","",INDEX('DEP LÍBANO'!$N$5:$N$14,MATCH((ROWS($B$12:$B12)+1),'DEP LÍBANO'!$Q$5:$Q$14,0))) | F12: =IF(B12="","",MROUND(D12*E12,100)) | N12: OCHO
B13: =IFERROR(UPPER(INDEX('DEP LÍBANO'!$B$5:$B$14,MATCH((ROWS($B$12:$B13)+1),'DEP LÍBANO'!$Q$5:$Q$14,0))),"") | C13: =IF(B13="","","m²") | D13: =IF(B13="","",INDEX('DEP LÍBANO'!$O$5:$O$14,MATCH((ROWS($B$12:$B13)+1),'DEP LÍBANO'!$Q$5:$Q$14,0))) | E13: =IF(B13="","",INDEX('DEP LÍBANO'!$N$5:$N$14,MATCH((ROWS($B$12:$B13)+1),'DEP LÍBANO'!$Q$5:$Q$14,0))) | F13: =IF(B13="","",MROUND(D13*E13,100)) | N13: NUEVE
B14: =IFERROR(UPPER(INDEX('DEP LÍBANO'!$B$5:$B$14,MATCH((ROWS($B$12:$B14)+1),'DEP LÍBANO'!$Q$5:$Q$14,0))),"") | C14: =IF(B14="","","m²") | D14: =IF(B14="","",INDEX('DEP LÍBANO'!$O$5:$O$14,MATCH((ROWS($B$12:$B14)+1),'DEP LÍBANO'!$Q$5:$Q$14,0))) | E14: =IF(B14="","",INDEX('DEP LÍBANO'!$N$5:$N$14,MATCH((ROWS($B$12:$B14)+1),'DEP LÍBANO'!$Q$5:$Q$14,0))) | F14: =IF(B14="","",MROUND(D14*E14,100)) | N14: DIEZ
B15: =IFERROR(UPPER(INDEX('DEP LÍBANO'!$B$5:$B$14,MATCH((ROWS($B$12:$B15)+1),'DEP LÍBANO'!$Q$5:$Q$14,0))),"") | C15: =IF(B15="","","m²") | D15: =IF(B15="","",INDEX('DEP LÍBANO'!$O$5:$O$14,MATCH((ROWS($B$12:$B15)+1),'DEP LÍBANO'!$Q$5:$Q$14,0))) | E15: =IF(B15="","",INDEX('DEP LÍBANO'!$N$5:$N$14,MATCH((ROWS($B$12:$B15)+1),'DEP LÍBANO'!$Q$5:$Q$14,0))) | F15: =IF(B15="","",MROUND(D15*E15,100)) | N15: ONCE
B16: =IFERROR(UPPER(INDEX('DEP LÍBANO'!$B$5:$B$14,MATCH((ROWS($B$12:$B16)+1),'DEP LÍBANO'!$Q$5:$Q$14,0))),"") | C16: =IF(B16="","","m²") | D16: =IF(B16="","",INDEX('DEP LÍBANO'!$O$5:$O$14,MATCH((ROWS($B$12:$B16)+1),'DEP LÍBANO'!$Q$5:$Q$14,0))) | E16: =IF(B16="","",INDEX('DEP LÍBANO'!$N$5:$N$14,MATCH((ROWS($B$12:$B16)+1),'DEP LÍBANO'!$Q$5:$Q$14,0))) | F16: =IF(B16="","",MROUND(D16*E16,100)) | N16: DOCE
B17: =IFERROR(UPPER(INDEX('DEP LÍBANO'!$B$5:$B$14,MATCH((ROWS($B$12:$B17)+1),'DEP LÍBANO'!$Q$5:$Q$14,0))),"") | C17: =IF(B17="","","m²") | D17: =IF(B17="","",INDEX('DEP LÍBANO'!$O$5:$O$14,MATCH((ROWS($B$12:$B17)+1),'DEP LÍBANO'!$Q$5:$Q$14,0))) | E17: =IF(B17="","",INDEX('DEP LÍBANO'!$N$5:$N$14,MATCH((ROWS($B$12:$B17)+1),'DEP LÍBANO'!$Q$5:$Q$14,0))) | F17: =IF(B17="","",MROUND(D17*E17,100)) | N17: TRECE
B18: =IFERROR(UPPER(INDEX('DEP LÍBANO'!$B$5:$B$14,MATCH((ROWS($B$12:$B18)+1),'DEP LÍBANO'!$Q$5:$Q$14,0))),"") | C18: =IF(B18="","","m²") | D18: =IF(B18="","",INDEX('DEP LÍBANO'!$O$5:$O$14,MATCH((ROWS($B$12:$B18)+1),'DEP LÍBANO'!$Q$5:$Q$14,0))) | E18: =IF(B18="","",INDEX('DEP LÍBANO'!$N$5:$N$14,MATCH((ROWS($B$12:$B18)+1),'DEP LÍBANO'!$Q$5:$Q$14,0))) | F18: =IF(B18="","",MROUND(D18*E18,100)) | N18: CATORCE
B19: =IFERROR(UPPER(INDEX('DEP LÍBANO'!$B$5:$B$14,MATCH((ROWS($B$12:$B19)+1),'DEP LÍBANO'!$Q$5:$Q$14,0))),"") | C19: =IF(B19="","","m²") | D19: =IF(B19="","",INDEX('DEP LÍBANO'!$O$5:$O$14,MATCH((ROWS($B$12:$B19)+1),'DEP LÍBANO'!$Q$5:$Q$14,0))) | E19: =IF(B19="","",INDEX('DEP LÍBANO'!$N$5:$N$14,MATCH((ROWS($B$12:$B19)+1),'DEP LÍBANO'!$Q$5:$Q$14,0))) | F19: =IF(B19="","",MROUND(D19*E19,100)) | N19: QUINCE
B20: =IFERROR(UPPER(INDEX('DEP LÍBANO'!$B$5:$B$14,MATCH((ROWS($B$12:$B20)+1),'DEP LÍBANO'!$Q$5:$Q$14,0))),"") | C20: =IF(B20="","","m²") | D20: =IF(B20="","",INDEX('DEP LÍBANO'!$O$5:$O$14,MATCH((ROWS($B$12:$B20)+1),'DEP LÍBANO'!$Q$5:$Q$14,0))) | E20: =IF(B20="","",INDEX('DEP LÍBANO'!$N$5:$N$14,MATCH((ROWS($B$12:$B20)+1),'DEP LÍBANO'!$Q$5:$Q$14,0))) | F20: =IF(B20="","",MROUND(D20*E20,100)) | N20: DIECISÉIS
B21: VALOR TOTAL DE LAS CONSTRUCCIONES ANEXAS | F21: =MROUND(SUM(F12:F20),100) | N21: DIECISIETE
B22: VALOR TOTAL DEL AVALÚO | F22: =MROUND(F5+F9+F21,100) | N22: DIECIOCHO
B23: VALOR TOTAL EN LETRAS | C23: =TRIM(IF(I6=0,"",IF(I7=0,"",IF(I7=1,"",K7&" ")&"MIL ")&IF(I8=0,"",K8&" ")&IF(I6=1,"MILLÓN ","MILLONES "))&IF(I9=0,"",IF(I9=1,"",K9&" ")&"MIL ")&J10)&IF(I5=0,"CERO","")&" PESOS MLV" | N23: DIECINUEVE
N24: VEINTE
N25: VEINTIUNO
N26: VEINTIDÓS
B27: Notas: (1) Terreno: el valor unitario por hectárea se vincula con el valor adoptado de 'MERCADO RURAL'; digite en la celda amarilla la superficie del predio (Ha). (2) Construcciones: se listan automáticamente las construcciones de 'DEPRECIACIÓN' que no tienen oferta asignada (predio objeto), con su área (m²) y valor adoptado por m²; capacidad 10. (3) Los totales se redondean a la centena. (4) El valor en letras se genera por fórmula con el cálculo auxiliar de las columnas H a K. | N27: VEINTITRÉS
N28: VEINTICUATRO
N29: VEINTICINCO
N30: VEINTISÉIS
N31: VEINTISIETE
N32: VEINTIOCHO
N33: VEINTINUEVE

Sheet DEP PORCIÓN 1-2-3
A1: DEPRECIACIÓN DE CONSTRUCCIONES MÉTODO ROSS – HEIDECKE
A2: PREDIO PORCION 1-2-3 · Valores de reposición: Catálogo IGAC de Tipologías Constructivas (vigencia oct-2025 a oct-2026), Región Norte
A3: CÁLCULO DEL VALOR POR ESTADO DE CONSERVACIÓN SEGÚN ROSS - HEIDECKE
A4: OFERTA No. | B4: ÍTEM | C4: EDAD (años) | D4: VIDA ÚTIL (años) | E4: CALIFICACIÓN ESTADO | F4: VALOR REPOSICIÓN | G4: % (DE VIDA) | H4: FACTOR DEPRECIACIÓN POR EDAD ROSS | I4: E = FACTOR DEPRECIACIÓN POR ESTADO HEIDECKE | J4: K = DEPRECIACIÓN (tabla Ross-Heidecke) | K4: VALOR DEPRECIADO | L4: FD = FACTOR DEPRECIACIÓN | M4: VALOR ACTUAL (VALOR DEPRECIADO) | N4: VALOR ADOPTADO | O4: ÁREA CONSTRUIDA (m²) | P4: VALOR TOTAL CONSTRUCCIÓN (N × O) | Q4: ORDEN EN LIQUIDACIÓN (A vacío = predio objeto) | S4: TABLA HEIDECKE | V4: TIPOLOGÍA CATÁLOGO IGAC (Región Norte) | W4: CONFIANZA
B5: Casa Principal | C5: 45 | D5: 70 | E5: 3.5 | F5: 1014000 | G5: =IF($B5="","",C5/D5) | H5: =IF($B5="","",1-0.5*(G5+G5^2)) | I5: =IF($B5="","",1-INDEX($T$6:$T$14,MATCH(E5,$S$6:$S$14,0))) | J5: =IF($B5="","",1-H5*I5) | K5: =IF($B5="","",F5*J5) | L5: =IF($B5="","",I5*H5) | M5: =IF($B5="","",F5*L5) | N5: =IF($B5="","",MROUND(M5,1000)) | O5: =12*21 | P5: =IF($B5="","",MROUND(N5*O5,100)) | Q5: =IF(AND($B5<>"",$A5=""),COUNTIFS($A$5:$A5,"",$B$5:$B5,"<>"),"") | S5: CALIFICACIÓN | T5: % DEPRECIACIÓN | V5: 1004113_Residencial.Tipo_3_Menos | W5: Media
B6: Caseta de Porteria | C6: 40 | D6: 70 | E6: 3.5 | F6: 1014000 | G6: =IF($B6="","",C6/D6) | H6: =IF($B6="","",1-0.5*(G6+G6^2)) | I6: =IF($B6="","",1-INDEX($T$6:$T$14,MATCH(E6,$S$6:$S$14,0))) | J6: =IF($B6="","",1-H6*I6) | K6: =IF($B6="","",F6*J6) | L6: =IF($B6="","",I6*H6) | M6: =IF($B6="","",F6*L6) | N6: =IF($B6="","",MROUND(M6,1000)) | O6: =2.6*2.7 | P6: =IF($B6="","",MROUND(N6*O6,100)) | Q6: =IF(AND($B6<>"",$A6=""),COUNTIFS($A$5:$A6,"",$B$5:$B6,"<>"),"") | S6: 1 | T6: 0 | V6: 1004113_Residencial.Tipo_3_Menos | W6: Media
B7: Caseta de Fertilizantes | C7: 40 | D7: 70 | E7: 3 | G7: =IF($B7="","",C7/D7) | H7: =IF($B7="","",1-0.5*(G7+G7^2)) | I7: =IF($B7="","",1-INDEX($T$6:$T$14,MATCH(E7,$S$6:$S$14,0))) | J7: =IF($B7="","",1-H7*I7) | K7: =IF($B7="","",F7*J7) | L7: =IF($B7="","",I7*H7) | M7: =IF($B7="","",F7*L7) | N7: =IF($B7="","",MROUND(M7,1000)) | O7: =4*4 | P7: =IF($B7="","",MROUND(N7*O7,100)) | Q7: =IF(AND($B7<>"",$A7=""),COUNTIFS($A$5:$A7,"",$B$5:$B7,"<>"),"") | S7: 1.5 | T7: 0.00032 | V7: SIN CLASIFICAR | W7: —
B8: Comedor | C8: 30 | D8: 70 | E8: 2 | F8: 912600 | G8: =IF($B8="","",C8/D8) | H8: =IF($B8="","",1-0.5*(G8+G8^2)) | I8: =IF($B8="","",1-INDEX($T$6:$T$14,MATCH(E8,$S$6:$S$14,0))) | J8: =IF($B8="","",1-H8*I8) | K8: =IF($B8="","",F8*J8) | L8: =IF($B8="","",I8*H8) | M8: =IF($B8="","",F8*L8) | N8: =IF($B8="","",MROUND(M8,1000)) | O8: 367 | P8: =IF($B8="","",MROUND(N8*O8,100)) | Q8: =IF(AND($B8<>"",$A8=""),COUNTIFS($A$5:$A8,"",$B$5:$B8,"<>"),"") | S8: 2 | T8: 0.0252 | V8: Anexos.Ramadas_Cobertizos_Caneyes_Plus_Tipo_80 | W8: Media
B9: Empacadora | C9: 45 | D9: 70 | E9: 2 | F9: 680600 | G9: =IF($B9="","",C9/D9) | H9: =IF($B9="","",1-0.5*(G9+G9^2)) | I9: =IF($B9="","",1-INDEX($T$6:$T$14,MATCH(E9,$S$6:$S$14,0))) | J9: =IF($B9="","",1-H9*I9) | K9: =IF($B9="","",F9*J9) | L9: =IF($B9="","",I9*H9) | M9: =IF($B9="","",F9*L9) | N9: =IF($B9="","",MROUND(M9,1000)) | O9: 297 | P9: =IF($B9="","",MROUND(N9*O9,100)) | Q9: =IF(AND($B9<>"",$A9=""),COUNTIFS($A$5:$A9,"",$B$5:$B9,"<>"),"") | S9: 2.5 | T9: 0.0809 | V9: Anexos.Beneficiaderos_Medio_Tipo_60 | W9: Media
B10: Planta agua potable | C10: 45 | D10: 70 | E10: 3 | G10: =IF($B10="","",C10/D10) | H10: =IF($B10="","",1-0.5*(G10+G10^2)) | I10: =IF($B10="","",1-INDEX($T$6:$T$14,MATCH(E10,$S$6:$S$14,0))) | J10: =IF($B10="","",1-H10*I10) | K10: =IF($B10="","",F10*J10) | L10: =IF($B10="","",I10*H10) | M10: =IF($B10="","",F10*L10) | N10: =IF($B10="","",MROUND(M10,1000)) | O10: =2.2*3 | P10: =IF($B10="","",MROUND(N10*O10,100)) | Q10: =IF(AND($B10<>"",$A10=""),COUNTIFS($A$5:$A10,"",$B$5:$B10,"<>"),"") | S10: 3 | T10: 0.181 | V10: SIN CLASIFICAR | W10: —
B11: Caseta Planta electrica | C11: 40 | D11: 70 | E11: 3 | G11: =IF($B11="","",C11/D11) | H11: =IF($B11="","",1-0.5*(G11+G11^2)) | I11: =IF($B11="","",1-INDEX($T$6:$T$14,MATCH(E11,$S$6:$S$14,0))) | J11: =IF($B11="","",1-H11*I11) | K11: =IF($B11="","",F11*J11) | L11: =IF($B11="","",I11*H11) | M11: =IF($B11="","",F11*L11) | N11: =IF($B11="","",MROUND(M11,1000)) | O11: =2.5*2.75 | P11: =IF($B11="","",MROUND(N11*O11,100)) | Q11: =IF(AND($B11<>"",$A11=""),COUNTIFS($A$5:$A11,"",$B$5:$B11,"<>"),"") | S11: 3.5 | T11: 0.332 | V11: SIN CLASIFICAR | W11: —
B12: Ramada Aceite | C12: 40 | D12: 70 | E12: 3 | G12: =IF($B12="","",C12/D12) | H12: =IF($B12="","",1-0.5*(G12+G12^2)) | I12: =IF($B12="","",1-INDEX($T$6:$T$14,MATCH(E12,$S$6:$S$14,0))) | J12: =IF($B12="","",1-H12*I12) | K12: =IF($B12="","",F12*J12) | L12: =IF($B12="","",I12*H12) | M12: =IF($B12="","",F12*L12) | N12: =IF($B12="","",MROUND(M12,1000)) | O12: 28.88 | P12: =IF($B12="","",MROUND(N12*O12,100)) | Q12: =IF(AND($B12<>"",$A12=""),COUNTIFS($A$5:$A12,"",$B$5:$B12,"<>"),"") | S12: 4 | T12: 0.526 | V12: SIN CLASIFICAR | W12: —
B13: Caseta de desinfección | C13: 40 | D13: 70 | E13: 3 | G13: =IF($B13="","",C13/D13) | H13: =IF($B13="","",1-0.5*(G13+G13^2)) | I13: =IF($B13="","",1-INDEX($T$6:$T$14,MATCH(E13,$S$6:$S$14,0))) | J13: =IF($B13="","",1-H13*I13) | K13: =IF($B13="","",F13*J13) | L13: =IF($B13="","",I13*H13) | M13: =IF($B13="","",F13*L13) | N13: =IF($B13="","",MROUND(M13,1000)) | O13: =8.1*2.5 | P13: =IF($B13="","",MROUND(N13*O13,100)) | Q13: =IF(AND($B13<>"",$A13=""),COUNTIFS($A$5:$A13,"",$B$5:$B13,"<>"),"") | S13: 4.5 | T13: 0.752 | V13: SIN CLASIFICAR | W13: —
G14: =IF($B14="","",C14/D14) | H14: =IF($B14="","",1-0.5*(G14+G14^2)) | I14: =IF($B14="","",1-INDEX($T$6:$T$14,MATCH(E14,$S$6:$S$14,0))) | J14: =IF($B14="","",1-H14*I14) | K14: =IF($B14="","",F14*J14) | L14: =IF($B14="","",I14*H14) | M14: =IF($B14="","",F14*L14) | N14: =IF($B14="","",MROUND(M14,1000)) | P14: =IF($B14="","",MROUND(N14*O14,100)) | Q14: =IF(AND($B14<>"",$A14=""),COUNTIFS($A$5:$A14,"",$B$5:$B14,"<>"),"") | S14: 5 | T14: 1
A15: TOTAL | F15: =SUM(F5:F14) | K15: =SUM(K5:K14) | M15: =SUM(M5:M14) | N15: =SUM(N5:N14) | P15: =SUM(P5:P14)
A17: VÍNCULO CON LA TABLA DE MERCADO – VALOR ESTIMADO DE CONSTRUCCIONES POR OFERTA (se actualiza con las ofertas de 'MERCADO RURAL', hasta 20)
A18: No. | B18: UBICACIÓN | F18: Nº CONSTRUC-CIONES | G18: VALOR REPOSICIÓN TOTAL (F × O) | J18: DEPRECIACIÓN (reposición − valor actual) | M18: VALOR ESTIMADO CONSTRUCCIONES
A19: =IF((ROWS($A$19:$A19)+8)>AUX_COMBINACIONES!$C$3,"",IF(INDEX('MERCADO RURAL'!$A:$A,(ROWS($A$19:$A19)+8))="","",INDEX('MERCADO RURAL'!$A:$A,(ROWS($A$19:$A19)+8)))) | B19: =IF($A19="","",INDEX('MERCADO RURAL'!$B:$B,(ROWS($A$19:$A19)+8))) | F19: =IF($A19="","",COUNTIFS($A$5:$A$14,$A19,$B$5:$B$14,"<>")) | G19: =IF($A19="","",SUMPRODUCT(($A$5:$A$14=$A19)*$F$5:$F$14*$O$5:$O$14)) | J19: =IF($A19="","",G19-M19) | M19: =IF($A19="","",SUMIFS($P$5:$P$14,$A$5:$A$14,$A19))
A20: =IF((ROWS($A$19:$A20)+8)>AUX_COMBINACIONES!$C$3,"",IF(INDEX('MERCADO RURAL'!$A:$A,(ROWS($A$19:$A20)+8))="","",INDEX('MERCADO RURAL'!$A:$A,(ROWS($A$19:$A20)+8)))) | B20: =IF($A20="","",INDEX('MERCADO RURAL'!$B:$B,(ROWS($A$19:$A20)+8))) | F20: =IF($A20="","",COUNTIFS($A$5:$A$14,$A20,$B$5:$B$14,"<>")) | G20: =IF($A20="","",SUMPRODUCT(($A$5:$A$14=$A20)*$F$5:$F$14*$O$5:$O$14)) | J20: =IF($A20="","",G20-M20) | M20: =IF($A20="","",SUMIFS($P$5:$P$14,$A$5:$A$14,$A20))
A21: =IF((ROWS($A$19:$A21)+8)>AUX_COMBINACIONES!$C$3,"",IF(INDEX('MERCADO RURAL'!$A:$A,(ROWS($A$19:$A21)+8))="","",INDEX('MERCADO RURAL'!$A:$A,(ROWS($A$19:$A21)+8)))) | B21: =IF($A21="","",INDEX('MERCADO RURAL'!$B:$B,(ROWS($A$19:$A21)+8))) | F21: =IF($A21="","",COUNTIFS($A$5:$A$14,$A21,$B$5:$B$14,"<>")) | G21: =IF($A21="","",SUMPRODUCT(($A$5:$A$14=$A21)*$F$5:$F$14*$O$5:$O$14)) | J21: =IF($A21="","",G21-M21) | M21: =IF($A21="","",SUMIFS($P$5:$P$14,$A$5:$A$14,$A21))
A22: =IF((ROWS($A$19:$A22)+8)>AUX_COMBINACIONES!$C$3,"",IF(INDEX('MERCADO RURAL'!$A:$A,(ROWS($A$19:$A22)+8))="","",INDEX('MERCADO RURAL'!$A:$A,(ROWS($A$19:$A22)+8)))) | B22: =IF($A22="","",INDEX('MERCADO RURAL'!$B:$B,(ROWS($A$19:$A22)+8))) | F22: =IF($A22="","",COUNTIFS($A$5:$A$14,$A22,$B$5:$B$14,"<>")) | G22: =IF($A22="","",SUMPRODUCT(($A$5:$A$14=$A22)*$F$5:$F$14*$O$5:$O$14)) | J22: =IF($A22="","",G22-M22) | M22: =IF($A22="","",SUMIFS($P$5:$P$14,$A$5:$A$14,$A22))
A23: =IF((ROWS($A$19:$A23)+8)>AUX_COMBINACIONES!$C$3,"",IF(INDEX('MERCADO RURAL'!$A:$A,(ROWS($A$19:$A23)+8))="","",INDEX('MERCADO RURAL'!$A:$A,(ROWS($A$19:$A23)+8)))) | B23: =IF($A23="","",INDEX('MERCADO RURAL'!$B:$B,(ROWS($A$19:$A23)+8))) | F23: =IF($A23="","",COUNTIFS($A$5:$A$14,$A23,$B$5:$B$14,"<>")) | G23: =IF($A23="","",SUMPRODUCT(($A$5:$A$14=$A23)*$F$5:$F$14*$O$5:$O$14)) | J23: =IF($A23="","",G23-M23) | M23: =IF($A23="","",SUMIFS($P$5:$P$14,$A$5:$A$14,$A23))
A24: =IF((ROWS($A$19:$A24)+8)>AUX_COMBINACIONES!$C$3,"",IF(INDEX('MERCADO RURAL'!$A:$A,(ROWS($A$19:$A24)+8))="","",INDEX('MERCADO RURAL'!$A:$A,(ROWS($A$19:$A24)+8)))) | B24: =IF($A24="","",INDEX('MERCADO RURAL'!$B:$B,(ROWS($A$19:$A24)+8))) | F24: =IF($A24="","",COUNTIFS($A$5:$A$14,$A24,$B$5:$B$14,"<>")) | G24: =IF($A24="","",SUMPRODUCT(($A$5:$A$14=$A24)*$F$5:$F$14*$O$5:$O$14)) | J24: =IF($A24="","",G24-M24) | M24: =IF($A24="","",SUMIFS($P$5:$P$14,$A$5:$A$14,$A24))
A25: =IF((ROWS($A$19:$A25)+8)>AUX_COMBINACIONES!$C$3,"",IF(INDEX('MERCADO RURAL'!$A:$A,(ROWS($A$19:$A25)+8))="","",INDEX('MERCADO RURAL'!$A:$A,(ROWS($A$19:$A25)+8)))) | B25: =IF($A25="","",INDEX('MERCADO RURAL'!$B:$B,(ROWS($A$19:$A25)+8))) | F25: =IF($A25="","",COUNTIFS($A$5:$A$14,$A25,$B$5:$B$14,"<>")) | G25: =IF($A25="","",SUMPRODUCT(($A$5:$A$14=$A25)*$F$5:$F$14*$O$5:$O$14)) | J25: =IF($A25="","",G25-M25) | M25: =IF($A25="","",SUMIFS($P$5:$P$14,$A$5:$A$14,$A25))
A26: =IF((ROWS($A$19:$A26)+8)>AUX_COMBINACIONES!$C$3,"",IF(INDEX('MERCADO RURAL'!$A:$A,(ROWS($A$19:$A26)+8))="","",INDEX('MERCADO RURAL'!$A:$A,(ROWS($A$19:$A26)+8)))) | B26: =IF($A26="","",INDEX('MERCADO RURAL'!$B:$B,(ROWS($A$19:$A26)+8))) | F26: =IF($A26="","",COUNTIFS($A$5:$A$14,$A26,$B$5:$B$14,"<>")) | G26: =IF($A26="","",SUMPRODUCT(($A$5:$A$14=$A26)*$F$5:$F$14*$O$5:$O$14)) | J26: =IF($A26="","",G26-M26) | M26: =IF($A26="","",SUMIFS($P$5:$P$14,$A$5:$A$14,$A26))
A27: =IF((ROWS($A$19:$A27)+8)>AUX_COMBINACIONES!$C$3,"",IF(INDEX('MERCADO RURAL'!$A:$A,(ROWS($A$19:$A27)+8))="","",INDEX('MERCADO RURAL'!$A:$A,(ROWS($A$19:$A27)+8)))) | B27: =IF($A27="","",INDEX('MERCADO RURAL'!$B:$B,(ROWS($A$19:$A27)+8))) | F27: =IF($A27="","",COUNTIFS($A$5:$A$14,$A27,$B$5:$B$14,"<>")) | G27: =IF($A27="","",SUMPRODUCT(($A$5:$A$14=$A27)*$F$5:$F$14*$O$5:$O$14)) | J27: =IF($A27="","",G27-M27) | M27: =IF($A27="","",SUMIFS($P$5:$P$14,$A$5:$A$14,$A27))
A28: =IF((ROWS($A$19:$A28)+8)>AUX_COMBINACIONES!$C$3,"",IF(INDEX('MERCADO RURAL'!$A:$A,(ROWS($A$19:$A28)+8))="","",INDEX('MERCADO RURAL'!$A:$A,(ROWS($A$19:$A28)+8)))) | B28: =IF($A28="","",INDEX('MERCADO RURAL'!$B:$B,(ROWS($A$19:$A28)+8))) | F28: =IF($A28="","",COUNTIFS($A$5:$A$14,$A28,$B$5:$B$14,"<>")) | G28: =IF($A28="","",SUMPRODUCT(($A$5:$A$14=$A28)*$F$5:$F$14*$O$5:$O$14)) | J28: =IF($A28="","",G28-M28) | M28: =IF($A28="","",SUMIFS($P$5:$P$14,$A$5:$A$14,$A28))
A29: =IF((ROWS($A$19:$A29)+8)>AUX_COMBINACIONES!$C$3,"",IF(INDEX('MERCADO RURAL'!$A:$A,(ROWS($A$19:$A29)+8))="","",INDEX('MERCADO RURAL'!$A:$A,(ROWS($A$19:$A29)+8)))) | B29: =IF($A29="","",INDEX('MERCADO RURAL'!$B:$B,(ROWS($A$19:$A29)+8))) | F29: =IF($A29="","",COUNTIFS($A$5:$A$14,$A29,$B$5:$B$14,"<>")) | G29: =IF($A29="","",SUMPRODUCT(($A$5:$A$14=$A29)*$F$5:$F$14*$O$5:$O$14)) | J29: =IF($A29="","",G29-M29) | M29: =IF($A29="","",SUMIFS($P$5:$P$14,$A$5:$A$14,$A29))
A30: =IF((ROWS($A$19:$A30)+8)>AUX_COMBINACIONES!$C$3,"",IF(INDEX('MERCADO RURAL'!$A:$A,(ROWS($A$19:$A30)+8))="","",INDEX('MERCADO RURAL'!$A:$A,(ROWS($A$19:$A30)+8)))) | B30: =IF($A30="","",INDEX('MERCADO RURAL'!$B:$B,(ROWS($A$19:$A30)+8))) | F30: =IF($A30="","",COUNTIFS($A$5:$A$14,$A30,$B$5:$B$14,"<>")) | G30: =IF($A30="","",SUMPRODUCT(($A$5:$A$14=$A30)*$F$5:$F$14*$O$5:$O$14)) | J30: =IF($A30="","",G30-M30) | M30: =IF($A30="","",SUMIFS($P$5:$P$14,$A$5:$A$14,$A30))
... A38: =IF((ROWS($A$19:$A38)+8)>AUX_COMBINACIONES!$C$3,"",IF(INDEX('MERCADO RURAL'!$A:$A,(ROWS($A$19:$A38)+8))="","",INDEX('MERCADO RURAL'!$A:$A,(ROWS($A$19:$A38)+8)))) | B38: =IF($A38="","",INDEX('MERCADO RURAL'!$B:$B,(ROWS($A$19:$A38)+8))) | F38: =IF($A38="","",COUNTIFS($A$5:$A$14,$A38,$B$5:$B$14,"<>")) | G38: =IF($A38="","",SUMPRODUCT(($A$5:$A$14=$A38)*$F$5:$F$14*$O$5:$O$14)) | J38: =IF($A38="","",G38-M38) | M38: =IF($A38="","",SUMIFS($P$5:$P$14,$A$5:$A$14,$A38))
A39: TOTAL ASIGNADO A OFERTAS | F39: =SUM(F19:F38) | G39: =SUM(G19:G38) | J39: =SUM(J19:J38) | M39: =SUM(M19:M38)
A40: Construcciones del predio objeto (sin oferta asignada) – pasan a la hoja LIQUIDACIÓN | M40: =SUMIFS($P$5:$P$14,$A$5:$A$14,"",$B$5:$B$14,"<>")
A41: Control: total tabla = asignado a ofertas + predio objeto (debe ser 0) | M41: =P15-M39-M40
A43: Instrucciones: (1) Digite en la columna A el No. de la oferta de 'MERCADO RURAL' a la que pertenece cada construcción; si la deja vacía, la construcción pertenece al predio objeto y se lista en 'LIQUIDACIÓN' en el orden de la columna Q. (2) Los datos en azul son editables: edad, vida útil, calificación (1 a 5, pasos de 0,5), valor de reposición por m² y área construida (m²). (3) El valor total de cada construcción (columna P = valor adoptado por m² × área) se suma por oferta y alimenta 'MERCADO RURAL' (columna Valor estimado construcciones). (4) Capacidad: 10 construcciones y 20 ofertas.

Sheet LIQ PORCIÓN 1-2-3
B2: TABLA DE VALORES – PREDIO PORCION 1-2-3
B3: TERRENO | H3: CÁLCULO AUXILIAR – VALOR EN LETRAS
B4: DESCRIPCIÓN | C4: UNIDAD | D4: CANTIDAD | E4: VALOR UNITARIO | F4: VALOR TOTAL | H4: CONCEPTO | I4: VALOR | J4: TEXTO | K4: TEXTO (APOCOPADO) | N4: UNIDADES 1–29 | O4: DECENAS 30–90
B5: ='MERCADO RURAL'!E4 | C5: Ha | D5: 0 | E5: ='MERCADO RURAL'!H24 | F5: =MROUND(D5*E5,100) | H5: Valor total (entero) | I5: =ROUND(F22,0) | N5: UNO | O5: TREINTA
B6: CONSTRUCCIÓN PRINCIPAL | H6: Millones totales | I6: =INT(I5/10^6) | N6: DOS | O6: CUARENTA
B7: DESCRIPCIÓN | C7: UNIDAD | D7: CANTIDAD | E7: VALOR UNITARIO | F7: VALOR TOTAL | H7: Bloque miles de millones | I7: =INT(I6/1000) | J7: =IF(I7=0,"",IF(I7=100,"CIEN",TRIM(CHOOSE(INT(I7/100)+1,"","CIENTO ","DOSCIENTOS ","TRESCIENTOS ","CUATROCIENTOS ","QUINIENTOS ","SEISCIENTOS ","SETECIENTOS ","OCHOCIENTOS ","NOVECIENTOS ")&IF(MOD(I7,100)=0,"",IF(MOD(I7,100)<30,INDEX($N$5:$N$33,MOD(I7,100)),INDEX($O$5:$O$11,INT(MOD(I7,100)/10)-2)&IF(MOD(I7,10)=0,""," Y "&INDEX($N$5:$N$13,MOD(I7,10)))))))) | K7: =IF(RIGHT(J7,9)="VEINTIUNO",LEFT(J7,LEN(J7)-9)&"VEINTIÚN",IF(RIGHT(J7,3)="UNO",LEFT(J7,LEN(J7)-1),J7)) | N7: TRES | O7: CINCUENTA
