Workbook
Name DEPARTAMENTO: [1]Hoja1!$A$3:$A$35
Name eee: '[1]MERCADO RURAL'!$C$6
Name Seleccion: '[1]MERCADO URBANO'!$C$6

Sheet GUÍA
B1: GUÍA PARA AGREGAR OFERTAS Y ACTUALIZAR EL AVALÚO
B3: Paso | C3: Qué hacer
B4: 1. Nueva oferta | C4: En 'MERCADO RURAL' inserte una fila ENTRE la última oferta y la fila en blanco que está antes de PROMEDIO (clic derecho > Insertar). Copie la última oferta (Ctrl+C) y péguela en la fila nueva. Las columnas con fórmula son: Valor depurado (F), Valor terreno Ha (H), Construcciones (I) y Archivo PDF (Q); NO las sobrescriba. Escriba encima los demás datos (todos son datos propios de la fila, sin vínculos a la sección de descartadas): No., ubicación, coordenadas, valor pedido, % negociación, área (Ha), descripción, fuente, teléfono, enlace, fecha y comparabilidad. La sección 'OFERTAS REVISADAS Y DESCARTADAS' (filas 27 en adelante) es solo respaldo: puede borrarla sin afectar ninguna fórmula.
B5: 2. Estadísticos | C5: PROMEDIO, desviación, CV, límites, asimetría y VALOR ADOPTADO se recalculan solos al insertar la fila dentro de la tabla (incluye la fila en blanco final como colchón).
B6: 3. Construcciones | C6: En 'DEPRECIACIÓN' agregue la construcción en una fila libre (hasta 10): edad, vida útil, calificación, valor de reposición por m² y área (m²). Escriba en la columna A el No. de la oferta a la que pertenece; si la deja vacía, es del predio objeto y aparece en 'LIQUIDACIÓN'.
B7: 4. Combinaciones | C7: La hoja COMBINACIONES toma todas las ofertas de 'MERCADO RURAL' (hasta 30), prueba grupos de 3 o más ofertas y muestra hasta 3 combinaciones. Elija la que usará en la celda amarilla B18. El CV máximo (10 %, Res. 941) y el filtro por límites se cambian en B5 y B6.
B8: 5. Liquidación | C8: La hoja LIQUIDACIÓN toma el valor por Ha del VALOR ADOPTADO de 'MERCADO RURAL' y las construcciones del predio objeto desde 'DEPRECIACIÓN'. Solo debe digitar la superficie del predio (Ha) en la celda amarilla.
B9: 6. Google Earth | C9: Escriba las coordenadas (lat, lon) en 'MERCADO RURAL' columna COORDENADAS. 'KML_OFERTAS' genera el código KML (A1:A35): cópielo a un editor de texto y guárdelo como .kml. Para el enlace a Google Earth use Ctrl+K con https://earth.google.com/web/search/ + coordenadas.
B10: Colores | C10: Azul = dato editable · Amarillo = celda de entrada · Verde (texto) = vínculo a otra hoja · Negro = fórmula · Verde claro = resultado clave.
B11: Hojas de apoyo | C11: Las hojas AUX_COMBINACIONES y KML_OFERTAS contienen cálculos auxiliares; no las modifique.
B12: 7. Proyección | C12: La hoja PROYECCIÓN muestra el CV máximo, las combinaciones evaluadas con su banda admisible (promedio ± CV máximo), las dos combinaciones de orientación (baja y alta) y el gráfico. Todo es fórmula. El gráfico cubre hasta 12 ofertas; con más, amplíe el rango de datos (PROYECCIÓN!N11:S23). Incluye tarjetas indicadoras, mapa de valores (ofertas dentro/fuera del rango de orientación) y comparación del CV por combinación.
B13: Guardado | C13: Guarde el libro (Ctrl+G) y consérvelo como plantilla: para un nuevo estudio, reemplace las ofertas y construcciones y las fórmulas se mantienen.
B14: Simulación de prueba | C14: Las hojas SIM_MERCADO, SIM_COMBINACIONES, SIM_DEPRECIACIÓN, SIM_LIQUIDACIÓN, SIM_PROYECCIÓN y SIM_AUX (pestañas naranja) son una copia aislada con 4 ofertas ficticias (CV ≈ 8 %) para comprobar que el libro funciona. Solo están conectadas entre sí: no afectan las hojas del estudio y pueden eliminarse todas juntas.
B15: PANEL DE CONTROL (se actualiza solo)
B16: Verificación | C16: Estado
B17: Ofertas en 'MERCADO RURAL' (capacidad 30) | C17: =IF(COMBINACIONES!B8>30,"ALERTA: "&COMBINACIONES!B8&" ofertas; excede la capacidad de 30","OK – "&COMBINACIONES!B8&" ofertas") -> OK – 8 ofertas
B18: Capacidad de 'DEPRECIACIÓN' (20 ofertas) y del gráfico (12) | C18: =IF(COMBINACIONES!B8>20,"ALERTA: excede el resumen de DEPRECIACIÓN (20)",IF(COMBINACIONES!B8>12,"AVISO: el gráfico de PROYECCIÓN cubre 12; amplíe su rango","OK")) -> OK
B19: Construcciones (control de 'DEPRECIACIÓN') | C19: =IF(ABS(DEPRECIACIÓN!M41)<1,"OK – cuadra","ALERTA: hay construcciones asignadas a una oferta inexistente") -> OK – cuadra
B20: Errores de fórmula en las hojas principales | C20: =IF(SUMPRODUCT(--ISERROR('MERCADO RURAL'!A9:Q28))+SUMPRODUCT(--ISERROR(COMBINACIONES!A3:O25))+SUMPRODUCT(--ISERROR(DEPRECIACIÓN!A5:Q41))+SUMPRODUCT(--ISERROR(LIQUIDACIÓN!B5:F25))+SUMPRODUCT(--ISERROR(PROYECCIÓN!A4:L21))=0,"OK – sin errores","ALERTA: hay celdas con error") -> OK – sin errores
B21: Ofertas con coordenadas (para el KML) | C21: =COUNTIF(KML_OFERTAS!D5:D34,"?*")&" de "&COMBINACIONES!B8&" ofertas con coordenadas" -> 8 de 8 ofertas con coordenadas
B22: Coeficiente de variación (Res. 941) | C22: =IF(PROYECCIÓN!B8>0,"OK – "&PROYECCIÓN!B8&" combinación(es) cumplen","PENDIENTE – ninguna combinación cumple el "&TEXT(COMBINACIONES!B5,"0%")&"; agregue ofertas") -> PENDIENTE – ninguna combinación cumple el 10%; agregue ofertas

Sheet MERCADO RURAL
D1: ESTUDIO DE MERCADO PREDIOS RURALES GESTIÓN VALUATORIA | K1: Fecha estudio de mercado
K2: 2026 | L2: 10 | M2: 1
B3: ENTIDAD O NOMBRE DEL SOLICITANTE | F3: (Por definir) | L3: NIT o C.C.
B4: DIRECCIÓN DEL INMUEBLE | E4: Predio rural, sector Puente Bomba – El Ebanal (corr. Tigreras). Coord. 11.251133, -73.127307
A6: DEPARTAMENTO: | D6: LA GUAJIRA | F6: MUNICIPIO: | H6: RIOHACHA (confirmar con número predial)
A8: No. | B8: UBICACIÓN | C8: COORDENADAS | D8: VALOR PEDIDO | E8: %. NEG. | F8: VALOR DEPURADO | G8: ÁREA DE TERRENO Ha | H8: VALOR TERRENO Ha | I8: VALOR ESTIMADO CONSTRUCCIONES | J8: DESCRIPCIÓN DEL INMUEBLE | K8: NOMBRE FUENTE | L8: TELÉFONO FUENTE | M8: FOTOGRAFIA | N8: ENLACE DE LA OFERTA | O8: FECHA PUBLICACIÓN | P8: COMPARABILIDAD | Q8: ARCHIVO PDF
A9: 1 | B9: Dibulla, sobre Troncal del Caribe, cerca a Ciénaga de Mamavita / La Punta de los Remedios | C9: 11.27254658626432, -73.30951554818634 | D9: 7826000000 | E9: 0.1 | F9: =D9*(1-E9) -> 7043400000 | G9: 301 | H9: =(F9-I9)/G9 -> 23400000 | I9: =SUMIFS(DEPRECIACIÓN!$P$5:$P$14,DEPRECIACIÓN!$A$5:$A$14,$A9) -> 0 | J9: Finca agroindustrial y ganadera con potencial turístico, 200 m de frente sobre vía nacional, recursos hídricos abundantes, topografía plana a ondulada, 5 km de la playa y 4 km del casco urbano. Construcciones no detalladas en el anuncio. | K9: Hilton López Inmobiliaria – Luis López Y.M. (cód. 193716709) | L9: Solicitar en portal | N9: https://www.fincaraiz.com.co/finca-en-venta-en-dibulla/193716709 | O9: 2026-05-06 | P9: ALTA en uso agropecuario y corredor. Diferencias: tamaño (301 ha) y frente sobre la Troncal. | Q9: ="OFERTA "&TEXT(A9,"00") -> OFERTA 01
A10: 2 | B10: Camarones II, sector Cachaca 1, Riohacha – frente a vía principal, ~800 m de la playa | C10: 11.518410410351851, -72.95441972660828 | D10: 750000000 | E10: 0.1 | F10: =D10*(1-E10) -> 675000000 | G10: 0.54 | H10: =(F10-I10)/G10 -> 1250000000 | I10: =SUMIFS(DEPRECIACIÓN!$P$5:$P$14,DEPRECIACIÓN!$A$5:$A$14,$A10) -> 0 | J10: Lote comercial / turístico – 5.400 m². | K10: Tu360Inmobiliario (cód. 194341871) | L10: Solicitar en portal | N10: https://www.fincaraiz.com.co/lote-en-venta-en-camarones-ii-riohacha/194341871 | O10: No registrada | P10: DESCARTADA – Lote pequeño con frente a vía y vocación comercial/turística; ~$1.389 M/ha, fuera del rango de suelo agropecuario interior. | Q10: ="OFERTA "&TEXT(A10,"00") -> OFERTA 02
A11: 3 | B11: La Guija, a 5 km de El Retiro, Riohacha (vía destapada) | C11: 11.518410410351851, -72.95441972660828 | D11: 3300000000 | E11: 0.1 | F11: =D11*(1-E11) -> 2970000000 | G11: 6 | H11: =(F11-I11)/G11 -> 495000000 | I11: =SUMIFS(DEPRECIACIÓN!$P$5:$P$14,DEPRECIACIÓN!$A$5:$A$14,$A11) -> 0 | J11: Lote campestre / parcelación – 60.000 m². | K11: Aliviopropiedades (Punto Propiedad) | L11: Solicitar en portal | N11: https://www.puntopropiedad.com/inmueble/c62e-81cf-19854ae-9f91d049056f-79dd | O11: No registrada | P11: DESCARTADA – Vocación campestre de parcelación (~3 viviendas/ha); ~$550 M/ha, no comparable con uso agropecuario. | Q11: ="OFERTA "&TEXT(A11,"00") -> OFERTA 03
A12: 4 | B12: Riohacha, frente al mar (~40 m de playa) | C12: 11.518410410351851, -72.95441972660828 | D12: 750000000 | E12: 0.1 | F12: =D12*(1-E12) -> 675000000 | G12: 1 | H12: =(F12-I12)/G12 -> 675000000 | I12: =SUMIFS(DEPRECIACIÓN!$P$5:$P$14,DEPRECIACIÓN!$A$5:$A$14,$A12) -> 0 | J12: Lote turístico de playa – 10.000 m². | K12: Liliana Jaramillo De Castro (ref. 6983159) | L12: Solicitar en portal | N12: https://www.puntopropiedad.com/inmueble/7887-b18f-197d696-2c0a8cf753bf-72a9 | O12: No registrada | P12: DESCARTADA – Frente de playa; mercado turístico costero distinto al del predio. | Q12: ="OFERTA "&TEXT(A12,"00") -> OFERTA 04
A13: 5 | B13: Chingale / Mingueo, Dibulla – 250 m de frente de playa | C13: 11.518410410351851, -72.95441972660828 | D13: 6750000000 | E13: 0.1 | F13: =D13*(1-E13) -> 6075000000 | G13: 15 | H13: =(F13-I13)/G13 -> 405000000 | I13: =SUMIFS(DEPRECIACIÓN!$P$5:$P$14,DEPRECIACIÓN!$A$5:$A$14,$A13) -> 0 | J13: Lote turístico de playa – 150.000 m². | K13: Punto Propiedad | L13: Solicitar en portal | N13: https://www.puntopropiedad.com/inmueble/5572-9ce2-1931929-cf4b5a9bd510-747c | O13: No registrada | P13: DESCARTADA – Frente de playa; ~$450 M/ha refleja valor turístico costero. | Q13: ="OFERTA "&TEXT(A13,"00") -> OFERTA 05
A14: 6 | B14: Palomino, Dibulla – 25 m de frente de playa × 400 m | C14: 11.518410410351851, -72.95441972660828 | D14: 800000000 | E14: 0.1 | F14: =D14*(1-E14) -> 720000000 | G14: 1 | H14: =(F14-I14)/G14 -> 720000000 | I14: =SUMIFS(DEPRECIACIÓN!$P$5:$P$14,DEPRECIACIÓN!$A$5:$A$14,$A14) -> 0 | J14: Lote turístico de playa – 10.000 m². | K14: FazWaz (u4478556) | L14: Solicitar en portal | N14: https://www.fazwaz.com.co/propiedad-e-Inmueble-venta/terreno-parcela-en-venta-en-riohacha-la-guajira-u4478556 | O14: No registrada | P14: DESCARTADA – Frente de playa en el polo turístico de Palomino. | Q14: ="OFERTA "&TEXT(A14,"00") -> OFERTA 06
A15: 7 | B15: Estribaciones Sierra Nevada, Riohacha – 10 min del mar, riego en 12 ha, 2 casas | C15: 11.518410410351851, -72.95441972660828 | D15: 1500000000 | E15: 0.1 | F15: =D15*(1-E15) -> 1350000000 | G15: 50 | H15: =(F15-I15)/G15 -> 27000000 | I15: =SUMIFS(DEPRECIACIÓN!$P$5:$P$14,DEPRECIACIÓN!$A$5:$A$14,$A15) -> 0 | J15: Finca agrícola – 50 ha. | K15: Oceano Vía Inmobiliaria (ref. 4554009) | L15: Solicitar en portal | N15: https://fincaraiz.com.co/inmueble/finca-en-venta/riohacha/riohacha/4554009 | O15: 2019 | P15: DESCARTADA – Comparable en uso (~$30 M/ha), pero el anuncio es de 2019 y figura como NO DISPONIBLE. Solo referencia histórica. | Q15: ="OFERTA "&TEXT(A15,"00") -> OFERTA 07
A16: 8 | B16: Riohacha – "lotes para proyectos turísticos", mínimo 50 ha | C16: 11.518410410351851, -72.95441972660828 | D16: 1750000000 | E16: 0.1 | F16: =D16*(1-E16) -> 1575000000 | G16: 1000 | H16: =(F16-I16)/G16 -> 1575000 | I16: =SUMIFS(DEPRECIACIÓN!$P$5:$P$14,DEPRECIACIÓN!$A$5:$A$14,$A16) -> 0 | J16: Turístico – 10.000.000 m² (dato del anuncio). | K16: FazWaz (u4260056) | L16: Solicitar en portal | N16: https://www.fazwaz.com.co/propiedad-e-Inmueble-venta/terreno-parcela-en-venta-en-riohacha-la-guajira-u4260056 | O16: No registrada | P16: DESCARTADA – Datos inconsistentes (implicaría $175/m²); anuncio no confiable. | Q16: ="OFERTA "&TEXT(A16,"00") -> OFERTA 08
F18: PROMEDIO | H18: =AVERAGE(H9:H17) -> 449621875
F19: DESVIACIÓN ESTÁNDAR | H19: =_xlfn.STDEV.S(H9:H17) -> 4.3582031e+08
F20: COEFICIENTE DE VARIACIÓN | H20: =H19/H18 -> 0.96930406
F21: LÍMITE INFERIOR (Promedio − Desv. Est.) | H21: =H18-H19 -> 13801565
F22: LÍMITE SUPERIOR (Promedio + Desv. Est.) | H22: =H18+H19 -> 8.8544218e+08
F23: COEFICIENTE DE ASIMETRÍA | H23: =SKEW(H9:H17) -> 0.69280495
F24: VALOR ADOPTADO | H24: =ROUND(H18,-2) -> 449621900
A27: OBSERVACIONES: 1) Búsqueda realizada el 01/10/2026 en Fincaraíz, Punto Propiedad y FazWaz. Mercado Libre exigió inicio de sesión y Mitula/Trovit bloquearon el acceso, por lo que no fueron revisados. 2) Solo se encontró UNA oferta vigente con uso agropecuario en el corredor (finca de 301 ha en Dibulla, ~$26 M/ha pedido). La oferta pública en línea de la zona está dominada por lotes turísticos de playa y lotes comerciales sobre la Troncal, que no son comparables con un predio agropecuario interior situado a 1,5–2 km de la vía. 3) La tabla de mercado incluye, además de la oferta agropecuaria vigente (No. 1), las 7 ofertas descartadas (No. 2 a 8), vinculadas por fórmula a la sección inferior. Como son lotes turísticos, de playa o campestres, el promedio, la desviación estándar y el coeficiente de variación no son representativos del suelo agropecuario interior; el valor adoptado no se calcula con ellos y debe soportarse con ofertas de campo (avisos en sitio, comisionistas locales, juntas de acción comunal de Tigreras, Puente Bomba, El Ebanal y Pelechúa) y/o transacciones registradas. 4) El % de negociación (col. D) queda en 10 % porque no se obtuvo valor depurado; debe ajustarse con la negociación que confirme la fuente. 5) La oferta de 301 ha tiene frente sobre la Troncal y un tamaño muy superior; dado que la Res. 941/2026 prohíbe la homogenización por factores, su uso debe sustentarse por similitud y no mediante ajustes.

Sheet KML_OFERTAS
A1: <?xml version="1.0" encoding="UTF-8"?> | C1: Nombre | D1: Coordenadas (lat, lon) | E1: Latitud | F1: Longitud | G1: Descripción | I1: Cómo usar
A2: <kml xmlns="http://www.opengis.net/kml/2.2"><Document> | I2: 1. Digite las coordenadas (lat, lon) en 'MERCADO RURAL'!C9:C16; esta hoja las lee de allí.
A3: <name>Estudio de mercado rural – Puente Bomba / El Ebanal</name> | I3: 2. Copie A1:A35 de esta hoja y péguelo en un editor de texto (Bloc de notas).
A4: =IF(D4="","","<Placemark><name>"&C4&"</name><description>"&G4&"</description><Point><coordinates>"&F4&","&E4&",0</coordinates></Point></Placemark>") -> <Placemark><name>PREDIO OBJETO</name><description>Predio objeto de avalúo</description><Point><coordinates>-73.127307,11.251133,0</coordinates></Point></Placemark> | C4: PREDIO OBJETO | D4: =IFERROR(MID('MERCADO RURAL'!E4,FIND("Coord. ",'MERCADO RURAL'!E4)+7,40),"") -> 11.251133, -73.127307 | E4: =IF(D4="","",TRIM(LEFT(D4,FIND(",",D4)-1))) -> 11.251133 | F4: =IF(D4="","",TRIM(MID(D4,FIND(",",D4)+1,30))) -> -73.127307 | G4: Predio objeto de avalúo | I4: 3. Guarde el archivo como OFERTAS.kml (codificación UTF-8).
A5: =IF(OR(C5="",D5=""),"","<Placemark><name>"&C5&"</name><description>"&G5&"</description><Point><coordinates>"&F5&","&E5&",0</coordinates></Point></Placemark>") -> <Placemark><name>OFERTA 01</name><description>Dibulla, sobre Troncal del Caribe, cerca a Ciénaga de Mamavita / La Punta de los Remedios</description><Point><coordinates>-73.30951554818634,11.27254658626432,0</coordinates></Point></Placemark> | C5: =IF(9>AUX_COMBINACIONES!$C$3,"",INDEX('MERCADO RURAL'!$Q:$Q,9)) -> OFERTA 01 | D5: =IF(9>AUX_COMBINACIONES!$C$3,"",IF(INDEX('MERCADO RURAL'!$C:$C,9)="","",TRIM(INDEX('MERCADO RURAL'!$C:$C,9)))) -> 11.27254658626432, -73.30951554818634 | E5: =IF(D5="","",TRIM(LEFT(D5,FIND(",",D5)-1))) -> 11.27254658626432 | F5: =IF(D5="","",TRIM(MID(D5,FIND(",",D5)+1,30))) -> -73.30951554818634 | G5: =IF(C5="","",SUBSTITUTE(SUBSTITUTE(INDEX('MERCADO RURAL'!$B:$B,9),"&","&amp;"),"<","&lt;")) -> Dibulla, sobre Troncal del Caribe, cerca a Ciénaga de Mamavita / La Punta de los Remedios | I5: 4. Ábralo en Google Earth: aparecerán el predio objeto y las ofertas con coordenadas.
A6: =IF(OR(C6="",D6=""),"","<Placemark><name>"&C6&"</name><description>"&G6&"</description><Point><coordinates>"&F6&","&E6&",0</coordinates></Point></Placemark>") -> <Placemark><name>OFERTA 02</name><description>Camarones II, sector Cachaca 1, Riohacha – frente a vía principal, ~800 m de la playa</description><Point><coordinates>-72.95441972660828,11.518410410351851,0</coordinates></Point></Placemark> | C6: =IF(10>AUX_COMBINACIONES!$C$3,"",INDEX('MERCADO RURAL'!$Q:$Q,10)) -> OFERTA 02 | D6: =IF(10>AUX_COMBINACIONES!$C$3,"",IF(INDEX('MERCADO RURAL'!$C:$C,10)="","",TRIM(INDEX('MERCADO RURAL'!$C:$C,10)))) -> 11.518410410351851, -72.95441972660828 | E6: =IF(D6="","",TRIM(LEFT(D6,FIND(",",D6)-1))) -> 11.518410410351851 | F6: =IF(D6="","",TRIM(MID(D6,FIND(",",D6)+1,30))) -> -72.95441972660828 | G6: =IF(C6="","",SUBSTITUTE(SUBSTITUTE(INDEX('MERCADO RURAL'!$B:$B,10),"&","&amp;"),"<","&lt;")) -> Camarones II, sector Cachaca 1, Riohacha – frente a vía principal, ~800 m de la playa
A7: =IF(OR(C7="",D7=""),"","<Placemark><name>"&C7&"</name><description>"&G7&"</description><Point><coordinates>"&F7&","&E7&",0</coordinates></Point></Placemark>") -> <Placemark><name>OFERTA 03</name><description>La Guija, a 5 km de El Retiro, Riohacha (vía destapada)</description><Point><coordinates>-72.95441972660828,11.518410410351851,0</coordinates></Point></Placemark> | C7: =IF(11>AUX_COMBINACIONES!$C$3,"",INDEX('MERCADO RURAL'!$Q:$Q,11)) -> OFERTA 03 | D7: =IF(11>AUX_COMBINACIONES!$C$3,"",IF(INDEX('MERCADO RURAL'!$C:$C,11)="","",TRIM(INDEX('MERCADO RURAL'!$C:$C,11)))) -> 11.518410410351851, -72.95441972660828 | E7: =IF(D7="","",TRIM(LEFT(D7,FIND(",",D7)-1))) -> 11.518410410351851 | F7: =IF(D7="","",TRIM(MID(D7,FIND(",",D7)+1,30))) -> -72.95441972660828 | G7: =IF(C7="","",SUBSTITUTE(SUBSTITUTE(INDEX('MERCADO RURAL'!$B:$B,11),"&","&amp;"),"<","&lt;")) -> La Guija, a 5 km de El Retiro, Riohacha (vía destapada)
A8: =IF(OR(C8="",D8=""),"","<Placemark><name>"&C8&"</name><description>"&G8&"</description><Point><coordinates>"&F8&","&E8&",0</coordinates></Point></Placemark>") -> <Placemark><name>OFERTA 04</name><description>Riohacha, frente al mar (~40 m de playa)</description><Point><coordinates>-72.95441972660828,11.518410410351851,0</coordinates></Point></Placemark> | C8: =IF(12>AUX_COMBINACIONES!$C$3,"",INDEX('MERCADO RURAL'!$Q:$Q,12)) -> OFERTA 04 | D8: =IF(12>AUX_COMBINACIONES!$C$3,"",IF(INDEX('MERCADO RURAL'!$C:$C,12)="","",TRIM(INDEX('MERCADO RURAL'!$C:$C,12)))) -> 11.518410410351851, -72.95441972660828 | E8: =IF(D8="","",TRIM(LEFT(D8,FIND(",",D8)-1))) -> 11.518410410351851 | F8: =IF(D8="","",TRIM(MID(D8,FIND(",",D8)+1,30))) -> -72.95441972660828 | G8: =IF(C8="","",SUBSTITUTE(SUBSTITUTE(INDEX('MERCADO RURAL'!$B:$B,12),"&","&amp;"),"<","&lt;")) -> Riohacha, frente al mar (~40 m de playa)
A9: =IF(OR(C9="",D9=""),"","<Placemark><name>"&C9&"</name><description>"&G9&"</description><Point><coordinates>"&F9&","&E9&",0</coordinates></Point></Placemark>") -> <Placemark><name>OFERTA 05</name><description>Chingale / Mingueo, Dibulla – 250 m de frente de playa</description><Point><coordinates>-72.95441972660828,11.518410410351851,0</coordinates></Point></Placemark> | C9: =IF(13>AUX_COMBINACIONES!$C$3,"",INDEX('MERCADO RURAL'!$Q:$Q,13)) -> OFERTA 05 | D9: =IF(13>AUX_COMBINACIONES!$C$3,"",IF(INDEX('MERCADO RURAL'!$C:$C,13)="","",TRIM(INDEX('MERCADO RURAL'!$C:$C,13)))) -> 11.518410410351851, -72.95441972660828 | E9: =IF(D9="","",TRIM(LEFT(D9,FIND(",",D9)-1))) -> 11.518410410351851 | F9: =IF(D9="","",TRIM(MID(D9,FIND(",",D9)+1,30))) -> -72.95441972660828 | G9: =IF(C9="","",SUBSTITUTE(SUBSTITUTE(INDEX('MERCADO RURAL'!$B:$B,13),"&","&amp;"),"<","&lt;")) -> Chingale / Mingueo, Dibulla – 250 m de frente de playa
A10: =IF(OR(C10="",D10=""),"","<Placemark><name>"&C10&"</name><description>"&G10&"</description><Point><coordinates>"&F10&","&E10&",0</coordinates></Point></Placemark>") -> <Placemark><name>OFERTA 06</name><description>Palomino, Dibulla – 25 m de frente de playa × 400 m</description><Point><coordinates>-72.95441972660828,11.518410410351851,0</coordinates></Point></Placemark> | C10: =IF(14>AUX_COMBINACIONES!$C$3,"",INDEX('MERCADO RURAL'!$Q:$Q,14)) -> OFERTA 06 | D10: =IF(14>AUX_COMBINACIONES!$C$3,"",IF(INDEX('MERCADO RURAL'!$C:$C,14)="","",TRIM(INDEX('MERCADO RURAL'!$C:$C,14)))) -> 11.518410410351851, -72.95441972660828 | E10: =IF(D10="","",TRIM(LEFT(D10,FIND(",",D10)-1))) -> 11.518410410351851 | F10: =IF(D10="","",TRIM(MID(D10,FIND(",",D10)+1,30))) -> -72.95441972660828 | G10: =IF(C10="","",SUBSTITUTE(SUBSTITUTE(INDEX('MERCADO RURAL'!$B:$B,14),"&","&amp;"),"<","&lt;")) -> Palomino, Dibulla – 25 m de frente de playa × 400 m
A11: =IF(OR(C11="",D11=""),"","<Placemark><name>"&C11&"</name><description>"&G11&"</description><Point><coordinates>"&F11&","&E11&",0</coordinates></Point></Placemark>") -> <Placemark><name>OFERTA 07</name><description>Estribaciones Sierra Nevada, Riohacha – 10 min del mar, riego en 12 ha, 2 casas</description><Point><coordinates>-72.95441972660828,11.518410410351851,0</coordinates></Point></Placemark> | C11: =IF(15>AUX_COMBINACIONES!$C$3,"",INDEX('MERCADO RURAL'!$Q:$Q,15)) -> OFERTA 07 | D11: =IF(15>AUX_COMBINACIONES!$C$3,"",IF(INDEX('MERCADO RURAL'!$C:$C,15)="","",TRIM(INDEX('MERCADO RURAL'!$C:$C,15)))) -> 11.518410410351851, -72.95441972660828 | E11: =IF(D11="","",TRIM(LEFT(D11,FIND(",",D11)-1))) -> 11.518410410351851 | F11: =IF(D11="","",TRIM(MID(D11,FIND(",",D11)+1,30))) -> -72.95441972660828 | G11: =IF(C11="","",SUBSTITUTE(SUBSTITUTE(INDEX('MERCADO RURAL'!$B:$B,15),"&","&amp;"),"<","&lt;")) -> Estribaciones Sierra Nevada, Riohacha – 10 min del mar, riego en 12 ha, 2 casas
A12: =IF(OR(C12="",D12=""),"","<Placemark><name>"&C12&"</name><description>"&G12&"</description><Point><coordinates>"&F12&","&E12&",0</coordinates></Point></Placemark>") -> <Placemark><name>OFERTA 08</name><description>Riohacha – "lotes para proyectos turísticos", mínimo 50 ha</description><Point><coordinates>-72.95441972660828,11.518410410351851,0</coordinates></Point></Placemark> | C12: =IF(16>AUX_COMBINACIONES!$C$3,"",INDEX('MERCADO RURAL'!$Q:$Q,16)) -> OFERTA 08 | D12: =IF(16>AUX_COMBINACIONES!$C$3,"",IF(INDEX('MERCADO RURAL'!$C:$C,16)="","",TRIM(INDEX('MERCADO RURAL'!$C:$C,16)))) -> 11.518410410351851, -72.95441972660828 | E12: =IF(D12="","",TRIM(LEFT(D12,FIND(",",D12)-1))) -> 11.518410410351851 | F12: =IF(D12="","",TRIM(MID(D12,FIND(",",D12)+1,30))) -> -72.95441972660828 | G12: =IF(C12="","",SUBSTITUTE(SUBSTITUTE(INDEX('MERCADO RURAL'!$B:$B,16),"&","&amp;"),"<","&lt;")) -> Riohacha – "lotes para proyectos turísticos", mínimo 50 ha
A13: =IF(OR(C13="",D13=""),"","<Placemark><name>"&C13&"</name><description>"&G13&"</description><Point><coordinates>"&F13&","&E13&",0</coordinates></Point></Placemark>") | C13: =IF(17>AUX_COMBINACIONES!$C$3,"",INDEX('MERCADO RURAL'!$Q:$Q,17)) -> 0 | D13: =IF(17>AUX_COMBINACIONES!$C$3,"",IF(INDEX('MERCADO RURAL'!$C:$C,17)="","",TRIM(INDEX('MERCADO RURAL'!$C:$C,17)))) | E13: =IF(D13="","",TRIM(LEFT(D13,FIND(",",D13)-1))) | F13: =IF(D13="","",TRIM(MID(D13,FIND(",",D13)+1,30))) | G13: =IF(C13="","",SUBSTITUTE(SUBSTITUTE(INDEX('MERCADO RURAL'!$B:$B,17),"&","&amp;"),"<","&lt;"))
A14: =IF(OR(C14="",D14=""),"","<Placemark><name>"&C14&"</name><description>"&G14&"</description><Point><coordinates>"&F14&","&E14&",0</coordinates></Point></Placemark>") | C14: =IF(18>AUX_COMBINACIONES!$C$3,"",INDEX('MERCADO RURAL'!$Q:$Q,18)) | D14: =IF(18>AUX_COMBINACIONES!$C$3,"",IF(INDEX('MERCADO RURAL'!$C:$C,18)="","",TRIM(INDEX('MERCADO RURAL'!$C:$C,18)))) | E14: =IF(D14="","",TRIM(LEFT(D14,FIND(",",D14)-1))) | F14: =IF(D14="","",TRIM(MID(D14,FIND(",",D14)+1,30))) | G14: =IF(C14="","",SUBSTITUTE(SUBSTITUTE(INDEX('MERCADO RURAL'!$B:$B,18),"&","&amp;"),"<","&lt;"))
A15: =IF(OR(C15="",D15=""),"","<Placemark><name>"&C15&"</name><description>"&G15&"</description><Point><coordinates>"&F15&","&E15&",0</coordinates></Point></Placemark>") | C15: =IF(19>AUX_COMBINACIONES!$C$3,"",INDEX('MERCADO RURAL'!$Q:$Q,19)) | D15: =IF(19>AUX_COMBINACIONES!$C$3,"",IF(INDEX('MERCADO RURAL'!$C:$C,19)="","",TRIM(INDEX('MERCADO RURAL'!$C:$C,19)))) | E15: =IF(D15="","",TRIM(LEFT(D15,FIND(",",D15)-1))) | F15: =IF(D15="","",TRIM(MID(D15,FIND(",",D15)+1,30))) | G15: =IF(C15="","",SUBSTITUTE(SUBSTITUTE(INDEX('MERCADO RURAL'!$B:$B,19),"&","&amp;"),"<","&lt;"))
A16: =IF(OR(C16="",D16=""),"","<Placemark><name>"&C16&"</name><description>"&G16&"</description><Point><coordinates>"&F16&","&E16&",0</coordinates></Point></Placemark>") | C16: =IF(20>AUX_COMBINACIONES!$C$3,"",INDEX('MERCADO RURAL'!$Q:$Q,20)) | D16: =IF(20>AUX_COMBINACIONES!$C$3,"",IF(INDEX('MERCADO RURAL'!$C:$C,20)="","",TRIM(INDEX('MERCADO RURAL'!$C:$C,20)))) | E16: =IF(D16="","",TRIM(LEFT(D16,FIND(",",D16)-1))) | F16: =IF(D16="","",TRIM(MID(D16,FIND(",",D16)+1,30))) | G16: =IF(C16="","",SUBSTITUTE(SUBSTITUTE(INDEX('MERCADO RURAL'!$B:$B,20),"&","&amp;"),"<","&lt;"))
A17: =IF(OR(C17="",D17=""),"","<Placemark><name>"&C17&"</name><description>"&G17&"</description><Point><coordinates>"&F17&","&E17&",0</coordinates></Point></Placemark>") | C17: =IF(21>AUX_COMBINACIONES!$C$3,"",INDEX('MERCADO RURAL'!$Q:$Q,21)) | D17: =IF(21>AUX_COMBINACIONES!$C$3,"",IF(INDEX('MERCADO RURAL'!$C:$C,21)="","",TRIM(INDEX('MERCADO RURAL'!$C:$C,21)))) | E17: =IF(D17="","",TRIM(LEFT(D17,FIND(",",D17)-1))) | F17: =IF(D17="","",TRIM(MID(D17,FIND(",",D17)+1,30))) | G17: =IF(C17="","",SUBSTITUTE(SUBSTITUTE(INDEX('MERCADO RURAL'!$B:$B,21),"&","&amp;"),"<","&lt;"))
A18: =IF(OR(C18="",D18=""),"","<Placemark><name>"&C18&"</name><description>"&G18&"</description><Point><coordinates>"&F18&","&E18&",0</coordinates></Point></Placemark>") | C18: =IF(22>AUX_COMBINACIONES!$C$3,"",INDEX('MERCADO RURAL'!$Q:$Q,22)) | D18: =IF(22>AUX_COMBINACIONES!$C$3,"",IF(INDEX('MERCADO RURAL'!$C:$C,22)="","",TRIM(INDEX('MERCADO RURAL'!$C:$C,22)))) | E18: =IF(D18="","",TRIM(LEFT(D18,FIND(",",D18)-1))) | F18: =IF(D18="","",TRIM(MID(D18,FIND(",",D18)+1,30))) | G18: =IF(C18="","",SUBSTITUTE(SUBSTITUTE(INDEX('MERCADO RURAL'!$B:$B,22),"&","&amp;"),"<","&lt;"))
A19: =IF(OR(C19="",D19=""),"","<Placemark><name>"&C19&"</name><description>"&G19&"</description><Point><coordinates>"&F19&","&E19&",0</coordinates></Point></Placemark>") | C19: =IF(23>AUX_COMBINACIONES!$C$3,"",INDEX('MERCADO RURAL'!$Q:$Q,23)) | D19: =IF(23>AUX_COMBINACIONES!$C$3,"",IF(INDEX('MERCADO RURAL'!$C:$C,23)="","",TRIM(INDEX('MERCADO RURAL'!$C:$C,23)))) | E19: =IF(D19="","",TRIM(LEFT(D19,FIND(",",D19)-1))) | F19: =IF(D19="","",TRIM(MID(D19,FIND(",",D19)+1,30))) | G19: =IF(C19="","",SUBSTITUTE(SUBSTITUTE(INDEX('MERCADO RURAL'!$B:$B,23),"&","&amp;"),"<","&lt;"))
A20: =IF(OR(C20="",D20=""),"","<Placemark><name>"&C20&"</name><description>"&G20&"</description><Point><coordinates>"&F20&","&E20&",0</coordinates></Point></Placemark>") | C20: =IF(24>AUX_COMBINACIONES!$C$3,"",INDEX('MERCADO RURAL'!$Q:$Q,24)) | D20: =IF(24>AUX_COMBINACIONES!$C$3,"",IF(INDEX('MERCADO RURAL'!$C:$C,24)="","",TRIM(INDEX('MERCADO RURAL'!$C:$C,24)))) | E20: =IF(D20="","",TRIM(LEFT(D20,FIND(",",D20)-1))) | F20: =IF(D20="","",TRIM(MID(D20,FIND(",",D20)+1,30))) | G20: =IF(C20="","",SUBSTITUTE(SUBSTITUTE(INDEX('MERCADO RURAL'!$B:$B,24),"&","&amp;"),"<","&lt;"))
A21: =IF(OR(C21="",D21=""),"","<Placemark><name>"&C21&"</name><description>"&G21&"</description><Point><coordinates>"&F21&","&E21&",0</coordinates></Point></Placemark>") | C21: =IF(25>AUX_COMBINACIONES!$C$3,"",INDEX('MERCADO RURAL'!$Q:$Q,25)) | D21: =IF(25>AUX_COMBINACIONES!$C$3,"",IF(INDEX('MERCADO RURAL'!$C:$C,25)="","",TRIM(INDEX('MERCADO RURAL'!$C:$C,25)))) | E21: =IF(D21="","",TRIM(LEFT(D21,FIND(",",D21)-1))) | F21: =IF(D21="","",TRIM(MID(D21,FIND(",",D21)+1,30))) | G21: =IF(C21="","",SUBSTITUTE(SUBSTITUTE(INDEX('MERCADO RURAL'!$B:$B,25),"&","&amp;"),"<","&lt;"))
A22: =IF(OR(C22="",D22=""),"","<Placemark><name>"&C22&"</name><description>"&G22&"</description><Point><coordinates>"&F22&","&E22&",0</coordinates></Point></Placemark>") | C22: =IF(26>AUX_COMBINACIONES!$C$3,"",INDEX('MERCADO RURAL'!$Q:$Q,26)) | D22: =IF(26>AUX_COMBINACIONES!$C$3,"",IF(INDEX('MERCADO RURAL'!$C:$C,26)="","",TRIM(INDEX('MERCADO RURAL'!$C:$C,26)))) | E22: =IF(D22="","",TRIM(LEFT(D22,FIND(",",D22)-1))) | F22: =IF(D22="","",TRIM(MID(D22,FIND(",",D22)+1,30))) | G22: =IF(C22="","",SUBSTITUTE(SUBSTITUTE(INDEX('MERCADO RURAL'!$B:$B,26),"&","&amp;"),"<","&lt;"))
A23: =IF(OR(C23="",D23=""),"","<Placemark><name>"&C23&"</name><description>"&G23&"</description><Point><coordinates>"&F23&","&E23&",0</coordinates></Point></Placemark>") | C23: =IF(27>AUX_COMBINACIONES!$C$3,"",INDEX('MERCADO RURAL'!$Q:$Q,27)) | D23: =IF(27>AUX_COMBINACIONES!$C$3,"",IF(INDEX('MERCADO RURAL'!$C:$C,27)="","",TRIM(INDEX('MERCADO RURAL'!$C:$C,27)))) | E23: =IF(D23="","",TRIM(LEFT(D23,FIND(",",D23)-1))) | F23: =IF(D23="","",TRIM(MID(D23,FIND(",",D23)+1,30))) | G23: =IF(C23="","",SUBSTITUTE(SUBSTITUTE(INDEX('MERCADO RURAL'!$B:$B,27),"&","&amp;"),"<","&lt;"))
A24: =IF(OR(C24="",D24=""),"","<Placemark><name>"&C24&"</name><description>"&G24&"</description><Point><coordinates>"&F24&","&E24&",0</coordinates></Point></Placemark>") | C24: =IF(28>AUX_COMBINACIONES!$C$3,"",INDEX('MERCADO RURAL'!$Q:$Q,28)) | D24: =IF(28>AUX_COMBINACIONES!$C$3,"",IF(INDEX('MERCADO RURAL'!$C:$C,28)="","",TRIM(INDEX('MERCADO RURAL'!$C:$C,28)))) | E24: =IF(D24="","",TRIM(LEFT(D24,FIND(",",D24)-1))) | F24: =IF(D24="","",TRIM(MID(D24,FIND(",",D24)+1,30))) | G24: =IF(C24="","",SUBSTITUTE(SUBSTITUTE(INDEX('MERCADO RURAL'!$B:$B,28),"&","&amp;"),"<","&lt;"))
A25: =IF(OR(C25="",D25=""),"","<Placemark><name>"&C25&"</name><description>"&G25&"</description><Point><coordinates>"&F25&","&E25&",0</coordinates></Point></Placemark>") | C25: =IF(29>AUX_COMBINACIONES!$C$3,"",INDEX('MERCADO RURAL'!$Q:$Q,29)) | D25: =IF(29>AUX_COMBINACIONES!$C$3,"",IF(INDEX('MERCADO RURAL'!$C:$C,29)="","",TRIM(INDEX('MERCADO RURAL'!$C:$C,29)))) | E25: =IF(D25="","",TRIM(LEFT(D25,FIND(",",D25)-1))) | F25: =IF(D25="","",TRIM(MID(D25,FIND(",",D25)+1,30))) | G25: =IF(C25="","",SUBSTITUTE(SUBSTITUTE(INDEX('MERCADO RURAL'!$B:$B,29),"&","&amp;"),"<","&lt;"))
A26: =IF(OR(C26="",D26=""),"","<Placemark><name>"&C26&"</name><description>"&G26&"</description><Point><coordinates>"&F26&","&E26&",0</coordinates></Point></Placemark>") | C26: =IF(30>AUX_COMBINACIONES!$C$3,"",INDEX('MERCADO RURAL'!$Q:$Q,30)) | D26: =IF(30>AUX_COMBINACIONES!$C$3,"",IF(INDEX('MERCADO RURAL'!$C:$C,30)="","",TRIM(INDEX('MERCADO RURAL'!$C:$C,30)))) | E26: =IF(D26="","",TRIM(LEFT(D26,FIND(",",D26)-1))) | F26: =IF(D26="","",TRIM(MID(D26,FIND(",",D26)+1,30))) | G26: =IF(C26="","",SUBSTITUTE(SUBSTITUTE(INDEX('MERCADO RURAL'!$B:$B,30),"&","&amp;"),"<","&lt;"))
A27: =IF(OR(C27="",D27=""),"","<Placemark><name>"&C27&"</name><description>"&G27&"</description><Point><coordinates>"&F27&","&E27&",0</coordinates></Point></Placemark>") | C27: =IF(31>AUX_COMBINACIONES!$C$3,"",INDEX('MERCADO RURAL'!$Q:$Q,31)) | D27: =IF(31>AUX_COMBINACIONES!$C$3,"",IF(INDEX('MERCADO RURAL'!$C:$C,31)="","",TRIM(INDEX('MERCADO RURAL'!$C:$C,31)))) | E27: =IF(D27="","",TRIM(LEFT(D27,FIND(",",D27)-1))) | F27: =IF(D27="","",TRIM(MID(D27,FIND(",",D27)+1,30))) | G27: =IF(C27="","",SUBSTITUTE(SUBSTITUTE(INDEX('MERCADO RURAL'!$B:$B,31),"&","&amp;"),"<","&lt;"))
A28: =IF(OR(C28="",D28=""),"","<Placemark><name>"&C28&"</name><description>"&G28&"</description><Point><coordinates>"&F28&","&E28&",0</coordinates></Point></Placemark>") | C28: =IF(32>AUX_COMBINACIONES!$C$3,"",INDEX('MERCADO RURAL'!$Q:$Q,32)) | D28: =IF(32>AUX_COMBINACIONES!$C$3,"",IF(INDEX('MERCADO RURAL'!$C:$C,32)="","",TRIM(INDEX('MERCADO RURAL'!$C:$C,32)))) | E28: =IF(D28="","",TRIM(LEFT(D28,FIND(",",D28)-1))) | F28: =IF(D28="","",TRIM(MID(D28,FIND(",",D28)+1,30))) | G28: =IF(C28="","",SUBSTITUTE(SUBSTITUTE(INDEX('MERCADO RURAL'!$B:$B,32),"&","&amp;"),"<","&lt;"))
A29: =IF(OR(C29="",D29=""),"","<Placemark><name>"&C29&"</name><description>"&G29&"</description><Point><coordinates>"&F29&","&E29&",0</coordinates></Point></Placemark>") | C29: =IF(33>AUX_COMBINACIONES!$C$3,"",INDEX('MERCADO RURAL'!$Q:$Q,33)) | D29: =IF(33>AUX_COMBINACIONES!$C$3,"",IF(INDEX('MERCADO RURAL'!$C:$C,33)="","",TRIM(INDEX('MERCADO RURAL'!$C:$C,33)))) | E29: =IF(D29="","",TRIM(LEFT(D29,FIND(",",D29)-1))) | F29: =IF(D29="","",TRIM(MID(D29,FIND(",",D29)+1,30))) | G29: =IF(C29="","",SUBSTITUTE(SUBSTITUTE(INDEX('MERCADO RURAL'!$B:$B,33),"&","&amp;"),"<","&lt;"))
A30: =IF(OR(C30="",D30=""),"","<Placemark><name>"&C30&"</name><description>"&G30&"</description><Point><coordinates>"&F30&","&E30&",0</coordinates></Point></Placemark>") | C30: =IF(34>AUX_COMBINACIONES!$C$3,"",INDEX('MERCADO RURAL'!$Q:$Q,34)) | D30: =IF(34>AUX_COMBINACIONES!$C$3,"",IF(INDEX('MERCADO RURAL'!$C:$C,34)="","",TRIM(INDEX('MERCADO RURAL'!$C:$C,34)))) | E30: =IF(D30="","",TRIM(LEFT(D30,FIND(",",D30)-1))) | F30: =IF(D30="","",TRIM(MID(D30,FIND(",",D30)+1,30))) | G30: =IF(C30="","",SUBSTITUTE(SUBSTITUTE(INDEX('MERCADO RURAL'!$B:$B,34),"&","&amp;"),"<","&lt;"))
A31: =IF(OR(C31="",D31=""),"","<Placemark><name>"&C31&"</name><description>"&G31&"</description><Point><coordinates>"&F31&","&E31&",0</coordinates></Point></Placemark>") | C31: =IF(35>AUX_COMBINACIONES!$C$3,"",INDEX('MERCADO RURAL'!$Q:$Q,35)) | D31: =IF(35>AUX_COMBINACIONES!$C$3,"",IF(INDEX('MERCADO RURAL'!$C:$C,35)="","",TRIM(INDEX('MERCADO RURAL'!$C:$C,35)))) | E31: =IF(D31="","",TRIM(LEFT(D31,FIND(",",D31)-1))) | F31: =IF(D31="","",TRIM(MID(D31,FIND(",",D31)+1,30))) | G31: =IF(C31="","",SUBSTITUTE(SUBSTITUTE(INDEX('MERCADO RURAL'!$B:$B,35),"&","&amp;"),"<","&lt;"))
A32: =IF(OR(C32="",D32=""),"","<Placemark><name>"&C32&"</name><description>"&G32&"</description><Point><coordinates>"&F32&","&E32&",0</coordinates></Point></Placemark>") | C32: =IF(36>AUX_COMBINACIONES!$C$3,"",INDEX('MERCADO RURAL'!$Q:$Q,36)) | D32: =IF(36>AUX_COMBINACIONES!$C$3,"",IF(INDEX('MERCADO RURAL'!$C:$C,36)="","",TRIM(INDEX('MERCADO RURAL'!$C:$C,36)))) | E32: =IF(D32="","",TRIM(LEFT(D32,FIND(",",D32)-1))) | F32: =IF(D32="","",TRIM(MID(D32,FIND(",",D32)+1,30))) | G32: =IF(C32="","",SUBSTITUTE(SUBSTITUTE(INDEX('MERCADO RURAL'!$B:$B,36),"&","&amp;"),"<","&lt;"))
A33: =IF(OR(C33="",D33=""),"","<Placemark><name>"&C33&"</name><description>"&G33&"</description><Point><coordinates>"&F33&","&E33&",0</coordinates></Point></Placemark>") | C33: =IF(37>AUX_COMBINACIONES!$C$3,"",INDEX('MERCADO RURAL'!$Q:$Q,37)) | D33: =IF(37>AUX_COMBINACIONES!$C$3,"",IF(INDEX('MERCADO RURAL'!$C:$C,37)="","",TRIM(INDEX('MERCADO RURAL'!$C:$C,37)))) | E33: =IF(D33="","",TRIM(LEFT(D33,FIND(",",D33)-1))) | F33: =IF(D33="","",TRIM(MID(D33,FIND(",",D33)+1,30))) | G33: =IF(C33="","",SUBSTITUTE(SUBSTITUTE(INDEX('MERCADO RURAL'!$B:$B,37),"&","&amp;"),"<","&lt;"))
A34: =IF(OR(C34="",D34=""),"","<Placemark><name>"&C34&"</name><description>"&G34&"</description><Point><coordinates>"&F34&","&E34&",0</coordinates></Point></Placemark>") | C34: =IF(38>AUX_COMBINACIONES!$C$3,"",INDEX('MERCADO RURAL'!$Q:$Q,38)) | D34: =IF(38>AUX_COMBINACIONES!$C$3,"",IF(INDEX('MERCADO RURAL'!$C:$C,38)="","",TRIM(INDEX('MERCADO RURAL'!$C:$C,38)))) | E34: =IF(D34="","",TRIM(LEFT(D34,FIND(",",D34)-1))) | F34: =IF(D34="","",TRIM(MID(D34,FIND(",",D34)+1,30))) | G34: =IF(C34="","",SUBSTITUTE(SUBSTITUTE(INDEX('MERCADO RURAL'!$B:$B,38),"&","&amp;"),"<","&lt;"))
A35: </Document></kml>

Sheet COMBINACIONES
A1: COMBINACIONES DE MERCADO – VALOR POR HECTÁREA Y POR METRO CUADRADO
A2: Se recalcula con todas las ofertas de 'MERCADO RURAL'. Muestra mínima de 3 ofertas; usa 4, 5 o más si así se logra el CV máximo. Se muestran hasta 3 combinaciones.
A3: Límite inferior muestra completa ($/ha) | B3: ='MERCADO RURAL'!H21 -> 13801565
A4: Límite superior muestra completa ($/ha) | B4: ='MERCADO RURAL'!H22 -> 8.8544218e+08
A5: Coeficiente de variación máximo admisible (Res. 941, rural) | B5: 0.1
A6: Filtrar ofertas por límites inferior/superior (SÍ/NO) – solo si el CV general supera el máximo | B6: SÍ
A7: Ofertas elegibles para combinar | B7: =AUX_COMBINACIONES!J2 -> 6
A8: Ofertas en la tabla de mercado | B8: =COUNT(AUX_COMBINACIONES!D5:D34) -> 8
A9: Mínimo de ofertas por combinación | B9: 3
A10: Combinaciones posibles (3 o más ofertas) | B10: =COUNTIF(AUX_COMBINACIONES!N5:N410,1) -> 10
A12: Combinación | B12: Nº de ofertas | C12: Ofertas utilizadas (No., de menor a mayor valor) | D12: Valor mínimo $/ha | E12: Valor máximo $/ha | F12: Promedio $/ha | G12: Desviación estándar | H12: Coef. de variación | I12: Límite inferior | J12: Límite superior | K12: Coef. de asimetría | L12: ¿CV ≤ máximo admisible? | M12: Valor adoptado $/ha (promedio redondeado a 100) | N12: Valor $/m² | O12: Posición en AUX
A13: =IF($O13="","—","Combinación 1") -> Combinación 1 | B13: =IF($O13="","",INDEX(AUX_COMBINACIONES!$M$5:$M$410,$O13)) -> 3 | C13: =IF($O13="","",_xlfn.TEXTJOIN(", ",TRUE,INDEX(AUX_COMBINACIONES!$I$5:$I$34,INDEX(AUX_COMBINACIONES!$L$5:$L$410,$O13)):INDEX(AUX_COMBINACIONES!$I$5:$I$34,INDEX(AUX_COMBINACIONES!$L$5:$L$410,$O13)+$B13-1))) -> 3, 4, 6 | D13: =IF($O13="","",MIN(INDEX(AUX_COMBINACIONES!$J$5:$J$34,INDEX(AUX_COMBINACIONES!$L$5:$L$410,$O13)):INDEX(AUX_COMBINACIONES!$J$5:$J$34,INDEX(AUX_COMBINACIONES!$L$5:$L$410,$O13)+$B13-1))) -> 495000000 | E13: =IF($O13="","",MAX(INDEX(AUX_COMBINACIONES!$J$5:$J$34,INDEX(AUX_COMBINACIONES!$L$5:$L$410,$O13)):INDEX(AUX_COMBINACIONES!$J$5:$J$34,INDEX(AUX_COMBINACIONES!$L$5:$L$410,$O13)+$B13-1))) -> 720000000 | F13: =IF($O13="","",AVERAGE(INDEX(AUX_COMBINACIONES!$J$5:$J$34,INDEX(AUX_COMBINACIONES!$L$5:$L$410,$O13)):INDEX(AUX_COMBINACIONES!$J$5:$J$34,INDEX(AUX_COMBINACIONES!$L$5:$L$410,$O13)+$B13-1))) -> 630000000 | G13: =IF($O13="","",_xlfn.STDEV.S(INDEX(AUX_COMBINACIONES!$J$5:$J$34,INDEX(AUX_COMBINACIONES!$L$5:$L$410,$O13)):INDEX(AUX_COMBINACIONES!$J$5:$J$34,INDEX(AUX_COMBINACIONES!$L$5:$L$410,$O13)+$B13-1))) -> 1.1905881e+08 | H13: =IF($O13="","",G13/F13) -> 0.18898224 | I13: =IF($O13="","",F13-G13) -> 5.1094119e+08 | J13: =IF($O13="","",F13+G13) -> 7.4905881e+08 | K13: =IF($O13="","",SKEW(INDEX(AUX_COMBINACIONES!$J$5:$J$34,INDEX(AUX_COMBINACIONES!$L$5:$L$410,$O13)):INDEX(AUX_COMBINACIONES!$J$5:$J$34,INDEX(AUX_COMBINACIONES!$L$5:$L$410,$O13)+$B13-1))) -> -1.457863 | L13: =IF($O13="","",IF(H13<=$B$5,"SÍ","NO")) -> NO | M13: =IF($O13="","",ROUND(F13,-2)) -> 630000000 | N13: =IF($O13="","",M13/10000) -> 63000 | O13: =IFERROR(MATCH(SMALL(AUX_COMBINACIONES!$Q$5:$Q$410,ROWS($A$13:$A13)),AUX_COMBINACIONES!$Q$5:$Q$410,0),"") -> 82
A14: =IF($O14="","—","Combinación 2") -> Combinación 2 | B14: =IF($O14="","",INDEX(AUX_COMBINACIONES!$M$5:$M$410,$O14)) -> 4 | C14: =IF($O14="","",_xlfn.TEXTJOIN(", ",TRUE,INDEX(AUX_COMBINACIONES!$I$5:$I$34,INDEX(AUX_COMBINACIONES!$L$5:$L$410,$O14)):INDEX(AUX_COMBINACIONES!$I$5:$I$34,INDEX(AUX_COMBINACIONES!$L$5:$L$410,$O14)+$B14-1))) -> 5, 3, 4, 6 | D14: =IF($O14="","",MIN(INDEX(AUX_COMBINACIONES!$J$5:$J$34,INDEX(AUX_COMBINACIONES!$L$5:$L$410,$O14)):INDEX(AUX_COMBINACIONES!$J$5:$J$34,INDEX(AUX_COMBINACIONES!$L$5:$L$410,$O14)+$B14-1))) -> 405000000 | E14: =IF($O14="","",MAX(INDEX(AUX_COMBINACIONES!$J$5:$J$34,INDEX(AUX_COMBINACIONES!$L$5:$L$410,$O14)):INDEX(AUX_COMBINACIONES!$J$5:$J$34,INDEX(AUX_COMBINACIONES!$L$5:$L$410,$O14)+$B14-1))) -> 720000000 | F14: =IF($O14="","",AVERAGE(INDEX(AUX_COMBINACIONES!$J$5:$J$34,INDEX(AUX_COMBINACIONES!$L$5:$L$410,$O14)):INDEX(AUX_COMBINACIONES!$J$5:$J$34,INDEX(AUX_COMBINACIONES!$L$5:$L$410,$O14)+$B14-1))) -> 573750000 | G14: =IF($O14="","",_xlfn.STDEV.S(INDEX(AUX_COMBINACIONES!$J$5:$J$34,INDEX(AUX_COMBINACIONES!$L$5:$L$410,$O14)):INDEX(AUX_COMBINACIONES!$J$5:$J$34,INDEX(AUX_COMBINACIONES!$L$5:$L$410,$O14)+$B14-1))) -> 1.4868171e+08 | H14: =IF($O14="","",G14/F14) -> 0.25914023 | I14: =IF($O14="","",F14-G14) -> 4.2506829e+08 | J14: =IF($O14="","",F14+G14) -> 7.2243171e+08 | K14: =IF($O14="","",SKEW(INDEX(AUX_COMBINACIONES!$J$5:$J$34,INDEX(AUX_COMBINACIONES!$L$5:$L$410,$O14)):INDEX(AUX_COMBINACIONES!$J$5:$J$34,INDEX(AUX_COMBINACIONES!$L$5:$L$410,$O14)+$B14-1))) -> -0.22872776 | L14: =IF($O14="","",IF(H14<=$B$5,"SÍ","NO")) -> NO | M14: =IF($O14="","",ROUND(F14,-2)) -> 573750000 | N14: =IF($O14="","",M14/10000) -> 57375 | O14: =IFERROR(MATCH(SMALL(AUX_COMBINACIONES!$Q$5:$Q$410,ROWS($A$13:$A14)),AUX_COMBINACIONES!$Q$5:$Q$410,0),"") -> 57
A15: =IF($O15="","—","Combinación 3") -> Combinación 3 | B15: =IF($O15="","",INDEX(AUX_COMBINACIONES!$M$5:$M$410,$O15)) -> 3 | C15: =IF($O15="","",_xlfn.TEXTJOIN(", ",TRUE,INDEX(AUX_COMBINACIONES!$I$5:$I$34,INDEX(AUX_COMBINACIONES!$L$5:$L$410,$O15)):INDEX(AUX_COMBINACIONES!$I$5:$I$34,INDEX(AUX_COMBINACIONES!$L$5:$L$410,$O15)+$B15-1))) -> 5, 3, 4 | D15: =IF($O15="","",MIN(INDEX(AUX_COMBINACIONES!$J$5:$J$34,INDEX(AUX_COMBINACIONES!$L$5:$L$410,$O15)):INDEX(AUX_COMBINACIONES!$J$5:$J$34,INDEX(AUX_COMBINACIONES!$L$5:$L$410,$O15)+$B15-1))) -> 405000000 | E15: =IF($O15="","",MAX(INDEX(AUX_COMBINACIONES!$J$5:$J$34,INDEX(AUX_COMBINACIONES!$L$5:$L$410,$O15)):INDEX(AUX_COMBINACIONES!$J$5:$J$34,INDEX(AUX_COMBINACIONES!$L$5:$L$410,$O15)+$B15-1))) -> 675000000 | F15: =IF($O15="","",AVERAGE(INDEX(AUX_COMBINACIONES!$J$5:$J$34,INDEX(AUX_COMBINACIONES!$L$5:$L$410,$O15)):INDEX(AUX_COMBINACIONES!$J$5:$J$34,INDEX(AUX_COMBINACIONES!$L$5:$L$410,$O15)+$B15-1))) -> 525000000 | G15: =IF($O15="","",_xlfn.STDEV.S(INDEX(AUX_COMBINACIONES!$J$5:$J$34,INDEX(AUX_COMBINACIONES!$L$5:$L$410,$O15)):INDEX(AUX_COMBINACIONES!$J$5:$J$34,INDEX(AUX_COMBINACIONES!$L$5:$L$410,$O15)+$B15-1))) -> 1.3747727e+08 | H15: =IF($O15="","",G15/F15) -> 0.26186147 | I15: =IF($O15="","",F15-G15) -> 3.8752273e+08 | J15: =IF($O15="","",F15+G15) -> 6.6247727e+08 | K15: =IF($O15="","",SKEW(INDEX(AUX_COMBINACIONES!$J$5:$J$34,INDEX(AUX_COMBINACIONES!$L$5:$L$410,$O15)):INDEX(AUX_COMBINACIONES!$J$5:$J$34,INDEX(AUX_COMBINACIONES!$L$5:$L$410,$O15)+$B15-1))) -> 0.93521953 | L15: =IF($O15="","",IF(H15<=$B$5,"SÍ","NO")) -> NO | M15: =IF($O15="","",ROUND(F15,-2)) -> 525000000 | N15: =IF($O15="","",M15/10000) -> 52500 | O15: =IFERROR(MATCH(SMALL(AUX_COMBINACIONES!$Q$5:$Q$410,ROWS($A$13:$A15)),AUX_COMBINACIONES!$Q$5:$Q$410,0),"") -> 56
A17: COMBINACIÓN SELECCIONADA (elija en B18) – BASE PARA EL VALOR POR HECTÁREA Y POR m²
A18: Combinación | B18: Combinación 3
A19: Ofertas utilizadas | B19: =IFERROR(IF(INDEX($O$13:$O$15,MATCH($B$18,$A$13:$A$15,0))="","Muestra insuficiente (mínimo 3 ofertas elegibles)",INDEX($C$13:$C$15,MATCH($B$18,$A$13:$A$15,0))&" ("&INDEX($B$13:$B$15,MATCH($B$18,$A$13:$A$15,0))&" ofertas)"),"Seleccione una combinación") -> 5, 3, 4 (3 ofertas)
A20: Coeficiente de variación | B20: =IFERROR(INDEX($H$13:$H$15,MATCH($B$18,$A$13:$A$15,0)),"") -> 0.26186147
A21: ¿Cumple el CV máximo admisible? | B21: =IFERROR(INDEX($L$13:$L$15,MATCH($B$18,$A$13:$A$15,0)),"") -> NO
A22: Valor por hectárea ($/ha) | B22: =IFERROR(INDEX($M$13:$M$15,MATCH($B$18,$A$13:$A$15,0)),"") -> 525000000
A23: Valor por metro cuadrado ($/m²) | B23: =IFERROR(INDEX($N$13:$N$15,MATCH($B$18,$A$13:$A$15,0)),"") -> 52500
A25: Notas: (1) La muestra mínima es de 3 ofertas; si con 3 no se logra el CV máximo, la hoja prueba con 4, 5 o más ofertas (grupos de ofertas consecutivas por valor/ha, hoja AUX_COMBINACIONES, capacidad 30 ofertas). (2) Se muestran hasta 3 combinaciones: primero las que cumplen el CV máximo (con más ofertas primero y menor CV) y, si ninguna cumple, las de menor CV. (3) Con el filtro en SÍ solo se combinan ofertas dentro de los límites inferior y superior de la muestra completa, y únicamente cuando el CV de la muestra general supera el máximo admisible (si ya lo cumple, se usan todas las ofertas). (4) Valor $/m² = valor $/ha ÷ 10.000. Se recalcula al agregar o quitar ofertas en 'MERCADO RURAL'.

Sheet DEPRECIACIÓN
A1: DEPRECIACIÓN DE CONSTRUCCIONES MÉTODO ROSS – HEIDECKE
A2: Estudio de mercado predios rurales – Puente Bomba / El Ebanal (corr. Tigreras) · Referencia de liquidación: MI 080-8167
A3: CÁLCULO DEL VALOR POR ESTADO DE CONSERVACIÓN SEGÚN ROSS - HEIDECKE
A4: OFERTA No. | B4: ÍTEM | C4: EDAD (años) | D4: VIDA ÚTIL (años) | E4: CALIFICACIÓN ESTADO | F4: VALOR REPOSICIÓN | G4: % (DE VIDA) | H4: FACTOR DEPRECIACIÓN POR EDAD ROSS | I4: E = FACTOR DEPRECIACIÓN POR ESTADO HEIDECKE | J4: K = DEPRECIACIÓN (tabla Ross-Heidecke) | K4: VALOR DEPRECIADO | L4: FD = FACTOR DEPRECIACIÓN | M4: VALOR ACTUAL (VALOR DEPRECIADO) | N4: VALOR ADOPTADO | O4: ÁREA CONSTRUIDA (m²) | P4: VALOR TOTAL CONSTRUCCIÓN (N × O) | Q4: ORDEN EN LIQUIDACIÓN (A vacío = predio objeto) | S4: TABLA HEIDECKE
B5: Casa Principal | C5: 30 | D5: 70 | E5: 2.5 | F5: 1131400 | G5: =IF($B5="","",C5/D5) -> 0.42857143 | H5: =IF($B5="","",1-0.5*(G5+G5^2)) -> 0.69387755 | I5: =IF($B5="","",1-INDEX($T$6:$T$14,MATCH(E5,$S$6:$S$14,0))) -> 0.9191 | J5: =IF($B5="","",1-H5*I5) -> 0.36225714 | K5: =IF($B5="","",F5*J5) -> 409857.73 | L5: =IF($B5="","",I5*H5) -> 0.63774286 | M5: =IF($B5="","",F5*L5) -> 721542.27 | N5: =IF($B5="","",MROUND(M5,1000)) -> 722000 | O5: 97 | P5: =IF($B5="","",MROUND(N5*O5,100)) -> 70034000 | Q5: =IF(AND($B5<>"",$A5=""),COUNTIFS($A$5:$A5,"",$B$5:$B5,"<>"),"") -> 1 | S5: CALIFICACIÓN | T5: % DEPRECIACIÓN
B6: Casa Mayordomo | C6: 30 | D6: 70 | E6: 3.5 | F6: 1131400 | G6: =IF($B6="","",C6/D6) -> 0.42857143 | H6: =IF($B6="","",1-0.5*(G6+G6^2)) -> 0.69387755 | I6: =IF($B6="","",1-INDEX($T$6:$T$14,MATCH(E6,$S$6:$S$14,0))) -> 0.668 | J6: =IF($B6="","",1-H6*I6) -> 0.5364898 | K6: =IF($B6="","",F6*J6) -> 606984.56 | L6: =IF($B6="","",I6*H6) -> 0.4635102 | M6: =IF($B6="","",F6*L6) -> 524415.44 | N6: =IF($B6="","",MROUND(M6,1000)) -> 524000 | O6: 70 | P6: =IF($B6="","",MROUND(N6*O6,100)) -> 36680000 | Q6: =IF(AND($B6<>"",$A6=""),COUNTIFS($A$5:$A6,"",$B$5:$B6,"<>"),"") -> 2 | S6: 1 | T6: 0
B7: Casa pequeña | C7: 25 | D7: 70 | E7: 3.5 | F7: 1131400 | G7: =IF($B7="","",C7/D7) -> 0.35714286 | H7: =IF($B7="","",1-0.5*(G7+G7^2)) -> 0.75765306 | I7: =IF($B7="","",1-INDEX($T$6:$T$14,MATCH(E7,$S$6:$S$14,0))) -> 0.668 | J7: =IF($B7="","",1-H7*I7) -> 0.49388776 | K7: =IF($B7="","",F7*J7) -> 558784.61 | L7: =IF($B7="","",I7*H7) -> 0.50611224 | M7: =IF($B7="","",F7*L7) -> 572615.39 | N7: =IF($B7="","",MROUND(M7,1000)) -> 573000 | O7: 53 | P7: =IF($B7="","",MROUND(N7*O7,100)) -> 30369000 | Q7: =IF(AND($B7<>"",$A7=""),COUNTIFS($A$5:$A7,"",$B$5:$B7,"<>"),"") -> 3 | S7: 1.5 | T7: 0.00032
B8: Bodega principal | C8: 30 | D8: 70 | E8: 4 | F8: 1286778 | G8: =IF($B8="","",C8/D8) -> 0.42857143 | H8: =IF($B8="","",1-0.5*(G8+G8^2)) -> 0.69387755 | I8: =IF($B8="","",1-INDEX($T$6:$T$14,MATCH(E8,$S$6:$S$14,0))) -> 0.474 | J8: =IF($B8="","",1-H8*I8) -> 0.67110204 | K8: =IF($B8="","",F8*J8) -> 863559.34 | L8: =IF($B8="","",I8*H8) -> 0.32889796 | M8: =IF($B8="","",F8*L8) -> 423218.66 | N8: =IF($B8="","",MROUND(M8,1000)) -> 423000 | O8: 35 | P8: =IF($B8="","",MROUND(N8*O8,100)) -> 14805000 | Q8: =IF(AND($B8<>"",$A8=""),COUNTIFS($A$5:$A8,"",$B$5:$B8,"<>"),"") -> 4 | S8: 2 | T8: 0.0252
B9: Bodega auxiliar | C9: 30 | D9: 50 | E9: 4 | F9: 1286778 | G9: =IF($B9="","",C9/D9) -> 0.6 | H9: =IF($B9="","",1-0.5*(G9+G9^2)) -> 0.52 | I9: =IF($B9="","",1-INDEX($T$6:$T$14,MATCH(E9,$S$6:$S$14,0))) -> 0.474 | J9: =IF($B9="","",1-H9*I9) -> 0.75352 | K9: =IF($B9="","",F9*J9) -> 969612.96 | L9: =IF($B9="","",I9*H9) -> 0.24648 | M9: =IF($B9="","",F9*L9) -> 317165.04 | N9: =IF($B9="","",MROUND(M9,1000)) -> 317000 | O9: 28 | P9: =IF($B9="","",MROUND(N9*O9,100)) -> 8876000 | Q9: =IF(AND($B9<>"",$A9=""),COUNTIFS($A$5:$A9,"",$B$5:$B9,"<>"),"") -> 5 | S9: 2.5 | T9: 0.0809
B10: Cuarto útil | C10: 30 | D10: 70 | E10: 3 | F10: 1231701 | G10: =IF($B10="","",C10/D10) -> 0.42857143 | H10: =IF($B10="","",1-0.5*(G10+G10^2)) -> 0.69387755 | I10: =IF($B10="","",1-INDEX($T$6:$T$14,MATCH(E10,$S$6:$S$14,0))) -> 0.819 | J10: =IF($B10="","",1-H10*I10) -> 0.43171429 | K10: =IF($B10="","",F10*J10) -> 531742.92 | L10: =IF($B10="","",I10*H10) -> 0.56828571 | M10: =IF($B10="","",F10*L10) -> 699958.08 | N10: =IF($B10="","",MROUND(M10,1000)) -> 700000 | O10: 17 | P10: =IF($B10="","",MROUND(N10*O10,100)) -> 11900000 | Q10: =IF(AND($B10<>"",$A10=""),COUNTIFS($A$5:$A10,"",$B$5:$B10,"<>"),"") -> 6 | S10: 3 | T10: 0.181
G11: =IF($B11="","",C11/D11) | H11: =IF($B11="","",1-0.5*(G11+G11^2)) | I11: =IF($B11="","",1-INDEX($T$6:$T$14,MATCH(E11,$S$6:$S$14,0))) | J11: =IF($B11="","",1-H11*I11) | K11: =IF($B11="","",F11*J11) | L11: =IF($B11="","",I11*H11) | M11: =IF($B11="","",F11*L11) | N11: =IF($B11="","",MROUND(M11,1000)) | P11: =IF($B11="","",MROUND(N11*O11,100)) | Q11: =IF(AND($B11<>"",$A11=""),COUNTIFS($A$5:$A11,"",$B$5:$B11,"<>"),"") | S11: 3.5 | T11: 0.332
G12: =IF($B12="","",C12/D12) | H12: =IF($B12="","",1-0.5*(G12+G12^2)) | I12: =IF($B12="","",1-INDEX($T$6:$T$14,MATCH(E12,$S$6:$S$14,0))) | J12: =IF($B12="","",1-H12*I12) | K12: =IF($B12="","",F12*J12) | L12: =IF($B12="","",I12*H12) | M12: =IF($B12="","",F12*L12) | N12: =IF($B12="","",MROUND(M12,1000)) | P12: =IF($B12="","",MROUND(N12*O12,100)) | Q12: =IF(AND($B12<>"",$A12=""),COUNTIFS($A$5:$A12,"",$B$5:$B12,"<>"),"") | S12: 4 | T12: 0.526
G13: =IF($B13="","",C13/D13) | H13: =IF($B13="","",1-0.5*(G13+G13^2)) | I13: =IF($B13="","",1-INDEX($T$6:$T$14,MATCH(E13,$S$6:$S$14,0))) | J13: =IF($B13="","",1-H13*I13) | K13: =IF($B13="","",F13*J13) | L13: =IF($B13="","",I13*H13) | M13: =IF($B13="","",F13*L13) | N13: =IF($B13="","",MROUND(M13,1000)) | P13: =IF($B13="","",MROUND(N13*O13,100)) | Q13: =IF(AND($B13<>"",$A13=""),COUNTIFS($A$5:$A13,"",$B$5:$B13,"<>"),"") | S13: 4.5 | T13: 0.752
G14: =IF($B14="","",C14/D14) | H14: =IF($B14="","",1-0.5*(G14+G14^2)) | I14: =IF($B14="","",1-INDEX($T$6:$T$14,MATCH(E14,$S$6:$S$14,0))) | J14: =IF($B14="","",1-H14*I14) | K14: =IF($B14="","",F14*J14) | L14: =IF($B14="","",I14*H14) | M14: =IF($B14="","",F14*L14) | N14: =IF($B14="","",MROUND(M14,1000)) | P14: =IF($B14="","",MROUND(N14*O14,100)) | Q14: =IF(AND($B14<>"",$A14=""),COUNTIFS($A$5:$A14,"",$B$5:$B14,"<>"),"") | S14: 5 | T14: 1
A15: TOTAL | F15: =SUM(F5:F14) -> 7199457 | K15: =SUM(K5:K14) -> 3940542.1 | M15: =SUM(M5:M14) -> 3258914.9 | N15: =SUM(N5:N14) -> 3259000 | P15: =SUM(P5:P14) -> 172664000
A17: VÍNCULO CON LA TABLA DE MERCADO – VALOR ESTIMADO DE CONSTRUCCIONES POR OFERTA (se actualiza con las ofertas de 'MERCADO RURAL', hasta 20)
A18: No. | B18: UBICACIÓN | F18: Nº CONSTRUC-CIONES | G18: VALOR REPOSICIÓN TOTAL (F × O) | J18: DEPRECIACIÓN (reposición − valor actual) | M18: VALOR ESTIMADO CONSTRUCCIONES
A19: =IF((ROWS($A$19:$A19)+8)>AUX_COMBINACIONES!$C$3,"",IF(INDEX('MERCADO RURAL'!$A:$A,(ROWS($A$19:$A19)+8))="","",INDEX('MERCADO RURAL'!$A:$A,(ROWS($A$19:$A19)+8)))) -> 1 | B19: =IF($A19="","",INDEX('MERCADO RURAL'!$B:$B,(ROWS($A$19:$A19)+8))) -> Dibulla, sobre Troncal del Caribe, cerca a Ciénaga de Mamavita / La Punta de los Remedios | F19: =IF($A19="","",COUNTIFS($A$5:$A$14,$A19,$B$5:$B$14,"<>")) -> 0 | G19: =IF($A19="","",SUMPRODUCT(($A$5:$A$14=$A19)*$F$5:$F$14*$O$5:$O$14)) -> 0 | J19: =IF($A19="","",G19-M19) -> 0 | M19: =IF($A19="","",SUMIFS($P$5:$P$14,$A$5:$A$14,$A19)) -> 0
A20: =IF((ROWS($A$19:$A20)+8)>AUX_COMBINACIONES!$C$3,"",IF(INDEX('MERCADO RURAL'!$A:$A,(ROWS($A$19:$A20)+8))="","",INDEX('MERCADO RURAL'!$A:$A,(ROWS($A$19:$A20)+8)))) -> 2 | B20: =IF($A20="","",INDEX('MERCADO RURAL'!$B:$B,(ROWS($A$19:$A20)+8))) -> Camarones II, sector Cachaca 1, Riohacha – frente a vía principal, ~800 m de la playa | F20: =IF($A20="","",COUNTIFS($A$5:$A$14,$A20,$B$5:$B$14,"<>")) -> 0 | G20: =IF($A20="","",SUMPRODUCT(($A$5:$A$14=$A20)*$F$5:$F$14*$O$5:$O$14)) -> 0 | J20: =IF($A20="","",G20-M20) -> 0 | M20: =IF($A20="","",SUMIFS($P$5:$P$14,$A$5:$A$14,$A20)) -> 0
A21: =IF((ROWS($A$19:$A21)+8)>AUX_COMBINACIONES!$C$3,"",IF(INDEX('MERCADO RURAL'!$A:$A,(ROWS($A$19:$A21)+8))="","",INDEX('MERCADO RURAL'!$A:$A,(ROWS($A$19:$A21)+8)))) -> 3 | B21: =IF($A21="","",INDEX('MERCADO RURAL'!$B:$B,(ROWS($A$19:$A21)+8))) -> La Guija, a 5 km de El Retiro, Riohacha (vía destapada) | F21: =IF($A21="","",COUNTIFS($A$5:$A$14,$A21,$B$5:$B$14,"<>")) -> 0 | G21: =IF($A21="","",SUMPRODUCT(($A$5:$A$14=$A21)*$F$5:$F$14*$O$5:$O$14)) -> 0 | J21: =IF($A21="","",G21-M21) -> 0 | M21: =IF($A21="","",SUMIFS($P$5:$P$14,$A$5:$A$14,$A21)) -> 0
A22: =IF((ROWS($A$19:$A22)+8)>AUX_COMBINACIONES!$C$3,"",IF(INDEX('MERCADO RURAL'!$A:$A,(ROWS($A$19:$A22)+8))="","",INDEX('MERCADO RURAL'!$A:$A,(ROWS($A$19:$A22)+8)))) -> 4 | B22: =IF($A22="","",INDEX('MERCADO RURAL'!$B:$B,(ROWS($A$19:$A22)+8))) -> Riohacha, frente al mar (~40 m de playa) | F22: =IF($A22="","",COUNTIFS($A$5:$A$14,$A22,$B$5:$B$14,"<>")) -> 0 | G22: =IF($A22="","",SUMPRODUCT(($A$5:$A$14=$A22)*$F$5:$F$14*$O$5:$O$14)) -> 0 | J22: =IF($A22="","",G22-M22) -> 0 | M22: =IF($A22="","",SUMIFS($P$5:$P$14,$A$5:$A$14,$A22)) -> 0
A23: =IF((ROWS($A$19:$A23)+8)>AUX_COMBINACIONES!$C$3,"",IF(INDEX('MERCADO RURAL'!$A:$A,(ROWS($A$19:$A23)+8))="","",INDEX('MERCADO RURAL'!$A:$A,(ROWS($A$19:$A23)+8)))) -> 5 | B23: =IF($A23="","",INDEX('MERCADO RURAL'!$B:$B,(ROWS($A$19:$A23)+8))) -> Chingale / Mingueo, Dibulla – 250 m de frente de playa | F23: =IF($A23="","",COUNTIFS($A$5:$A$14,$A23,$B$5:$B$14,"<>")) -> 0 | G23: =IF($A23="","",SUMPRODUCT(($A$5:$A$14=$A23)*$F$5:$F$14*$O$5:$O$14)) -> 0 | J23: =IF($A23="","",G23-M23) -> 0 | M23: =IF($A23="","",SUMIFS($P$5:$P$14,$A$5:$A$14,$A23)) -> 0
A24: =IF((ROWS($A$19:$A24)+8)>AUX_COMBINACIONES!$C$3,"",IF(INDEX('MERCADO RURAL'!$A:$A,(ROWS($A$19:$A24)+8))="","",INDEX('MERCADO RURAL'!$A:$A,(ROWS($A$19:$A24)+8)))) -> 6 | B24: =IF($A24="","",INDEX('MERCADO RURAL'!$B:$B,(ROWS($A$19:$A24)+8))) -> Palomino, Dibulla – 25 m de frente de playa × 400 m | F24: =IF($A24="","",COUNTIFS($A$5:$A$14,$A24,$B$5:$B$14,"<>")) -> 0 | G24: =IF($A24="","",SUMPRODUCT(($A$5:$A$14=$A24)*$F$5:$F$14*$O$5:$O$14)) -> 0 | J24: =IF($A24="","",G24-M24) -> 0 | M24: =IF($A24="","",SUMIFS($P$5:$P$14,$A$5:$A$14,$A24)) -> 0
A25: =IF((ROWS($A$19:$A25)+8)>AUX_COMBINACIONES!$C$3,"",IF(INDEX('MERCADO RURAL'!$A:$A,(ROWS($A$19:$A25)+8))="","",INDEX('MERCADO RURAL'!$A:$A,(ROWS($A$19:$A25)+8)))) -> 7 | B25: =IF($A25="","",INDEX('MERCADO RURAL'!$B:$B,(ROWS($A$19:$A25)+8))) -> Estribaciones Sierra Nevada, Riohacha – 10 min del mar, riego en 12 ha, 2 casas | F25: =IF($A25="","",COUNTIFS($A$5:$A$14,$A25,$B$5:$B$14,"<>")) -> 0 | G25: =IF($A25="","",SUMPRODUCT(($A$5:$A$14=$A25)*$F$5:$F$14*$O$5:$O$14)) -> 0 | J25: =IF($A25="","",G25-M25) -> 0 | M25: =IF($A25="","",SUMIFS($P$5:$P$14,$A$5:$A$14,$A25)) -> 0
A26: =IF((ROWS($A$19:$A26)+8)>AUX_COMBINACIONES!$C$3,"",IF(INDEX('MERCADO RURAL'!$A:$A,(ROWS($A$19:$A26)+8))="","",INDEX('MERCADO RURAL'!$A:$A,(ROWS($A$19:$A26)+8)))) -> 8 | B26: =IF($A26="","",INDEX('MERCADO RURAL'!$B:$B,(ROWS($A$19:$A26)+8))) -> Riohacha – "lotes para proyectos turísticos", mínimo 50 ha | F26: =IF($A26="","",COUNTIFS($A$5:$A$14,$A26,$B$5:$B$14,"<>")) -> 0 | G26: =IF($A26="","",SUMPRODUCT(($A$5:$A$14=$A26)*$F$5:$F$14*$O$5:$O$14)) -> 0 | J26: =IF($A26="","",G26-M26) -> 0 | M26: =IF($A26="","",SUMIFS($P$5:$P$14,$A$5:$A$14,$A26)) -> 0
A27: =IF((ROWS($A$19:$A27)+8)>AUX_COMBINACIONES!$C$3,"",IF(INDEX('MERCADO RURAL'!$A:$A,(ROWS($A$19:$A27)+8))="","",INDEX('MERCADO RURAL'!$A:$A,(ROWS($A$19:$A27)+8)))) | B27: =IF($A27="","",INDEX('MERCADO RURAL'!$B:$B,(ROWS($A$19:$A27)+8))) | F27: =IF($A27="","",COUNTIFS($A$5:$A$14,$A27,$B$5:$B$14,"<>")) | G27: =IF($A27="","",SUMPRODUCT(($A$5:$A$14=$A27)*$F$5:$F$14*$O$5:$O$14)) | J27: =IF($A27="","",G27-M27) | M27: =IF($A27="","",SUMIFS($P$5:$P$14,$A$5:$A$14,$A27))
A28: =IF((ROWS($A$19:$A28)+8)>AUX_COMBINACIONES!$C$3,"",IF(INDEX('MERCADO RURAL'!$A:$A,(ROWS($A$19:$A28)+8))="","",INDEX('MERCADO RURAL'!$A:$A,(ROWS($A$19:$A28)+8)))) | B28: =IF($A28="","",INDEX('MERCADO RURAL'!$B:$B,(ROWS($A$19:$A28)+8))) | F28: =IF($A28="","",COUNTIFS($A$5:$A$14,$A28,$B$5:$B$14,"<>")) | G28: =IF($A28="","",SUMPRODUCT(($A$5:$A$14=$A28)*$F$5:$F$14*$O$5:$O$14)) | J28: =IF($A28="","",G28-M28) | M28: =IF($A28="","",SUMIFS($P$5:$P$14,$A$5:$A$14,$A28))
A29: =IF((ROWS($A$19:$A29)+8)>AUX_COMBINACIONES!$C$3,"",IF(INDEX('MERCADO RURAL'!$A:$A,(ROWS($A$19:$A29)+8))="","",INDEX('MERCADO RURAL'!$A:$A,(ROWS($A$19:$A29)+8)))) | B29: =IF($A29="","",INDEX('MERCADO RURAL'!$B:$B,(ROWS($A$19:$A29)+8))) | F29: =IF($A29="","",COUNTIFS($A$5:$A$14,$A29,$B$5:$B$14,"<>")) | G29: =IF($A29="","",SUMPRODUCT(($A$5:$A$14=$A29)*$F$5:$F$14*$O$5:$O$14)) | J29: =IF($A29="","",G29-M29) | M29: =IF($A29="","",SUMIFS($P$5:$P$14,$A$5:$A$14,$A29))
A30: =IF((ROWS($A$19:$A30)+8)>AUX_COMBINACIONES!$C$3,"",IF(INDEX('MERCADO RURAL'!$A:$A,(ROWS($A$19:$A30)+8))="","",INDEX('MERCADO RURAL'!$A:$A,(ROWS($A$19:$A30)+8)))) | B30: =IF($A30="","",INDEX('MERCADO RURAL'!$B:$B,(ROWS($A$19:$A30)+8))) | F30: =IF($A30="","",COUNTIFS($A$5:$A$14,$A30,$B$5:$B$14,"<>")) | G30: =IF($A30="","",SUMPRODUCT(($A$5:$A$14=$A30)*$F$5:$F$14*$O$5:$O$14)) | J30: =IF($A30="","",G30-M30) | M30: =IF($A30="","",SUMIFS($P$5:$P$14,$A$5:$A$14,$A30))
... A38: =IF((ROWS($A$19:$A38)+8)>AUX_COMBINACIONES!$C$3,"",IF(INDEX('MERCADO RURAL'!$A:$A,(ROWS($A$19:$A38)+8))="","",INDEX('MERCADO RURAL'!$A:$A,(ROWS($A$19:$A38)+8)))) | B38: =IF($A38="","",INDEX('MERCADO RURAL'!$B:$B,(ROWS($A$19:$A38)+8))) | F38: =IF($A38="","",COUNTIFS($A$5:$A$14,$A38,$B$5:$B$14,"<>")) | G38: =IF($A38="","",SUMPRODUCT(($A$5:$A$14=$A38)*$F$5:$F$14*$O$5:$O$14)) | J38: =IF($A38="","",G38-M38) | M38: =IF($A38="","",SUMIFS($P$5:$P$14,$A$5:$A$14,$A38))
A39: TOTAL ASIGNADO A OFERTAS | F39: =SUM(F19:F38) -> 0 | G39: =SUM(G19:G38) -> 0 | J39: =SUM(J19:J38) -> 0 | M39: =SUM(M19:M38) -> 0
A40: Construcciones del predio objeto (sin oferta asignada) – pasan a la hoja LIQUIDACIÓN | M40: =SUMIFS($P$5:$P$14,$A$5:$A$14,"",$B$5:$B$14,"<>") -> 172664000
A41: Control: total tabla = asignado a ofertas + predio objeto (debe ser 0) | M41: =P15-M39-M40 -> 0
A43: Instrucciones: (1) Digite en la columna A el No. de la oferta de 'MERCADO RURAL' a la que pertenece cada construcción; si la deja vacía, la construcción pertenece al predio objeto y se lista en 'LIQUIDACIÓN' en el orden de la columna Q. (2) Los datos en azul son editables: edad, vida útil, calificación (1 a 5, pasos de 0,5), valor de reposición por m² y área construida (m²). (3) El valor total de cada construcción (columna P = valor adoptado por m² × área) se suma por oferta y alimenta 'MERCADO RURAL' (columna Valor estimado construcciones). (4) Capacidad: 10 construcciones y 20 ofertas.

Sheet LIQUIDACIÓN
B2: TABLA DE VALORES
B3: TERRENO | H3: CÁLCULO AUXILIAR – VALOR EN LETRAS
B4: DESCRIPCIÓN | C4: UNIDAD | D4: CANTIDAD | E4: VALOR UNITARIO | F4: VALOR TOTAL | H4: CONCEPTO | I4: VALOR | J4: TEXTO | K4: TEXTO (APOCOPADO) | N4: UNIDADES 1–29 | O4: DECENAS 30–90
B5: ='MERCADO RURAL'!E4 -> Predio rural, sector Puente Bomba – El Ebanal (corr. Tigreras). Coord. 11.251133, -73.127307 | C5: Ha | D5: 2 | E5: ='MERCADO RURAL'!H24 -> 449621900 | F5: =MROUND(D5*E5,100) -> 899243800 | H5: Valor total (entero) | I5: =ROUND(F22,0) -> 1071907800 | N5: UNO | O5: TREINTA
B6: CONSTRUCCIÓN PRINCIPAL | H6: Millones totales | I6: =INT(I5/10^6) -> 1071 | N6: DOS | O6: CUARENTA
B7: DESCRIPCIÓN | C7: UNIDAD | D7: CANTIDAD | E7: VALOR UNITARIO | F7: VALOR TOTAL | H7: Bloque miles de millones | I7: =INT(I6/1000) -> 1 | J7: =IF(I7=0,"",IF(I7=100,"CIEN",TRIM(CHOOSE(INT(I7/100)+1,"","CIENTO ","DOSCIENTOS ","TRESCIENTOS ","CUATROCIENTOS ","QUINIENTOS ","SEISCIENTOS ","SETECIENTOS ","OCHOCIENTOS ","NOVECIENTOS ")&IF(MOD(I7,100)=0,"",IF(MOD(I7,100)<30,INDEX($N$5:$N$33,MOD(I7,100)),INDEX($O$5:$O$11,INT(MOD(I7,100)/10)-2)&IF(MOD(I7,10)=0,""," Y "&INDEX($N$5:$N$13,MOD(I7,10)))))))) -> UNO | K7: =IF(RIGHT(J7,9)="VEINTIUNO",LEFT(J7,LEN(J7)-9)&"VEINTIÚN",IF(RIGHT(J7,3)="UNO",LEFT(J7,LEN(J7)-1),J7)) -> UN | N7: TRES | O7: CINCUENTA
B8: =IFERROR(UPPER(INDEX(DEPRECIACIÓN!$B$5:$B$14,MATCH(1,DEPRECIACIÓN!$Q$5:$Q$14,0))),"") -> CASA PRINCIPAL | C8: =IF(B8="","","m²") -> m² | D8: =IF(B8="","",INDEX(DEPRECIACIÓN!$O$5:$O$14,MATCH(1,DEPRECIACIÓN!$Q$5:$Q$14,0))) -> 97 | E8: =IF(B8="","",INDEX(DEPRECIACIÓN!$N$5:$N$14,MATCH(1,DEPRECIACIÓN!$Q$5:$Q$14,0))) -> 722000 | F8: =IF(B8="","",MROUND(D8*E8,100)) -> 70034000 | H8: Bloque millones | I8: =MOD(I6,1000) -> 71 | J8: =IF(I8=0,"",IF(I8=100,"CIEN",TRIM(CHOOSE(INT(I8/100)+1,"","CIENTO ","DOSCIENTOS ","TRESCIENTOS ","CUATROCIENTOS ","QUINIENTOS ","SEISCIENTOS ","SETECIENTOS ","OCHOCIENTOS ","NOVECIENTOS ")&IF(MOD(I8,100)=0,"",IF(MOD(I8,100)<30,INDEX($N$5:$N$33,MOD(I8,100)),INDEX($O$5:$O$11,INT(MOD(I8,100)/10)-2)&IF(MOD(I8,10)=0,""," Y "&INDEX($N$5:$N$13,MOD(I8,10)))))))) -> SETENTA Y UNO | K8: =IF(RIGHT(J8,9)="VEINTIUNO",LEFT(J8,LEN(J8)-9)&"VEINTIÚN",IF(RIGHT(J8,3)="UNO",LEFT(J8,LEN(J8)-1),J8)) -> SETENTA Y UN | N8: CUATRO | O8: SESENTA
