Workbook

Sheet GUÍA
B1: GUÍA – FORMATO COMPARACIÓN DE MERCADO URBANO (NPH y PH) · Res. IGAC 941 de 2026
B3: Paso | C3: Qué hacer
B4: 1. DATOS | C4: Diligencie los datos del inmueble objeto y revise los parámetros: CV máximo urbano 7,5 % (Art. 21), % de negociación por defecto (sustentado), vigencia de ofertas y mínimo de ofertas por combinación.
B5: 2. Mercado NPH | C5: Lotes, casas, casalotes, edificios, locales y bodegas no sometidos a PH. Una oferta por fila (capacidad 30). Escriba solo en columnas azules. El valor unitario de terreno = (valor negociado − construcciones depreciadas) / área de terreno.
B6: 3. Depreciación | C6: Para ofertas NPH con construcción, registre cada construcción en DEPRECIACIÓN con el No. de la oferta (edad, vida útil, calificación Heidecke, valor de reposición $/m² y área). Sin No. de oferta = construcción del inmueble objeto.
B7: 4. Mercado PH | C7: Apartamentos, oficinas, locales y demás unidades en PH. Registre área privada construida y libre, parqueaderos y depósitos (solo si son unidades privadas independientes). Valor integral = valor depurado / área privada construida.
B8: 5. Depuración | C8: Use la columna ¿INCLUIR? (SÍ/NO) para excluir ofertas no comparables sin borrarlas y sustente en COMPARABILIDAD. No se aplican factores de homogenización (Anexo, num. 2.1, Nota 2). Revise la columna ALERTAS.
B9: 6. Combinaciones | C9: COMBINACIONES_NPH y COMBINACIONES_PH ordenan las ofertas incluidas y evalúan grupos consecutivos; muestran las 3 mejores. Elija en la celda amarilla B18 la fuente del valor adoptado; el dictamen indica si cumple el Art. 21.
B10: 7. Liquidación | C10: Digite el área del objeto en la celda amarilla de LIQUIDACIÓN_NPH o LIQUIDACIÓN_PH según el régimen. El valor en letras se genera solo.
B11: 8. Google Earth | C11: Escriba coordenadas como «lat, lon». KML_OFERTAS genera el código: copie la columna A a un archivo .kml.
B12: 9. Chequeos | C12: La hoja CHEQUEOS recalcula promedio, desviación, CV, valores negociados, vínculo con DEPRECIACIÓN y totales de liquidación. Todo debe quedar en OK.
B13: Colores | C13: Azul = dato editable · Amarillo = celda de entrada · Verde (texto) = vínculo a otra hoja · Negro = fórmula · Verde claro = resultado clave · Pestañas grises = cálculo auxiliar (no editar).
B15: PANEL DE CONTROL | C15: Estado (se actualiza solo)
B16: Régimen del inmueble objeto | C16: =DATOS!C11&IF(DATOS!C11="PH"," – use MERCADO PH y LIQUIDACIÓN_PH"," – use MERCADO NPH y LIQUIDACIÓN_NPH")
B17: Ofertas NPH incluidas / registradas | C17: =COUNT('MERCADO NPH'!AA9:AA38)&" de "&COUNT('MERCADO NPH'!A9:A38)
B18: Dictamen NPH (Art. 21) | C18: =COMBINACIONES_NPH!B24
B19: Ofertas PH incluidas / registradas | C19: =COUNT('MERCADO PH'!AM9:AM38)&" de "&COUNT('MERCADO PH'!A9:A38)
B20: Dictamen PH (Art. 21) | C20: =COMBINACIONES_PH!B24
B21: Ofertas NPH con alertas | C21: =COUNTIFS('MERCADO NPH'!AB9:AB38,"<>OK",'MERCADO NPH'!A9:A38,"<>")&" oferta(s) – ver columna ALERTAS"
B22: Ofertas PH con alertas | C22: =COUNTIFS('MERCADO PH'!AN9:AN38,"<>OK",'MERCADO PH'!A9:A38,"<>")&" oferta(s) – ver columna ALERTAS"
B23: Chequeos | C23: =IF(CHEQUEOS!C4=0,"OK – "&CHEQUEOS!C3&" verificaciones coinciden","ALERTA: "&CHEQUEOS!C4&" verificación(es) con diferencia – ver CHEQUEOS")

Sheet DATOS
B1: DATOS GENERALES Y PARÁMETROS DEL ESTUDIO DE MERCADO URBANO
B2: Resolución IGAC 941 de 2026 y su Anexo técnico · Celdas amarillas = entrada
B4: Solicitante / entidad | C4: (Por definir)
B5: NIT o C.C.
B6: Dirección o identificación del inmueble objeto | C6: Lote urbano – Bello (referencia: farmacia en el nivel inferior)
B7: Municipio – Departamento | C7: Bello – Antioquia
B8: Comuna / barrio | C8: Sector Niquía / Bellavista (confirmar con número predial)
B9: Coordenadas del inmueble objeto (lat, lon) | C9: 6.348283, -75.552109 | D9: Formato: 6.2442, -75.5812
B10: Tipo de inmueble objeto | C10: Lote
B11: Régimen jurídico (NPH / PH) | C11: NPH | D11: Define qué hoja de liquidación aplica
B12: Fecha del estudio de mercado | C12: 46297 | D12: Base para calcular la antigüedad de las ofertas
B13: Clase de suelo | C13: Urbano | D13: Urbano o suburbano
B14: Avaluador – RAA | C14: Andrés Felipe Cuartas Montoya – RAA (N.º por diligenciar)
B15: PARÁMETROS TÉCNICOS | C15: Valor | D15: Sustento
B16: Coeficiente de variación máximo – inmuebles urbanos | C16: 0.075 | D16: Res. 941 de 2026, Art. 21: inmuebles urbanos hasta 7,5 % (rurales hasta 10 %).
B17: % de negociación por defecto (editable oferta por oferta) | C17: 0.05 | D17: Referencia: Lonja de Propiedad Raíz de Medellín (MLS), vivienda usada: descuento promedio 4,51 %; zona Norte 4,10 %; Centro 6,13 %. Ajustar con indagación directa.
B18: Vigencia máxima de una oferta (meses) – alerta | C18: 12 | D18: Criterio del avaluador para marcar ofertas desactualizadas (Art. 17, fecha de captura).
B19: Mínimo de ofertas por combinación | C19: 3 | D19: Muestra mínima para el análisis estadístico.
B20: Filtrar por límites (promedio ± desviación) si la muestra completa no cumple (SÍ/NO) | C20: SÍ | D20: Depuración de atípicos antes de combinar.
B21: Valor unitario de referencia – parqueadero privado (PH) | C21: 0 | D21: Solo si el parqueadero es unidad privada independiente (folio propio). Sustentar con mercado.
B22: Valor unitario de referencia – cuarto útil / depósito privado (PH) | C22: 0 | D22: Ídem.
B23: Coeficiente del área privada libre (balcón / terraza) respecto al $/m² del área privada construida | C23: 0.33333333 | D23: Práctica valuatoria («regla del tercio»): las áreas libres descubiertas se ponderan entre 25 % y 50 % del m² cubierto; 1/3 como valor central. No es parámetro normativo de la Res. 941: sustentar y ajustar (p. ej. 50 % si es cubierta/semicubierta y habitable).
B24: Divisor del valor integral PH | C24: ÁREA EQUIVALENTE | D24: ÁREA EQUIVALENTE = privada construida + coef. × privada libre (coherente con la liquidación del balcón). ÁREA PRIVADA CONSTRUIDA = lectura literal del Anexo; en ese modo el balcón del objeto no se liquida aparte.
B26: Nota metodológica: el Anexo de la Res. 941 de 2026 (num. 2.1, Nota 2) establece que la homogenización u homologación mediante factores NO es aplicable. Este libro no aplica factores: la muestra se depura, clasifica y analiza; las ofertas no comparables se excluyen con la columna «¿Incluir?».

Sheet MERCADO NPH
A1: LOGO | D1: ESTUDIO DE MERCADO – INMUEBLES URBANOS (CASA O APARTAMENTO) NO SOMETIDOS A PROPIEDAD HORIZONTAL (NPH) Res. IGAC 941 de 2026 – Art. 17, 19 y 21 · Anexo num. 2.1 · Área máxima por oferta: 100 m² | AB1: Fecha estudio | AC1: =DATOS!$C$12
AB2: CV máx. (Art. 21) | AC2: =DATOS!$C$16
A3: SOLICITANTE | D3: =DATOS!C4
A4: INMUEBLE OBJETO | D4: =DATOS!C6
A5: MUNICIPIO – BARRIO | D5: =DATOS!C7&" – "&DATOS!C8
A6: % NEGOCIACIÓN POR DEFECTO | D6: =DATOS!$C$17 | E6: Se aplica a cada oferta; puede sobrescribirse en la fila con el % sustentado de esa oferta.
A8: No. | B8: FECHA DE CAPTURA | C8: TIPO DE INMUEBLE (CASA / APARTAMENTO) | D8: TIPO DE DATO | E8: MUNICIPIO | F8: COMUNA / BARRIO / SECTOR | G8: DIRECCIÓN O REFERENCIA | H8: COORDENADAS (lat, lon) | I8: VALOR PEDIDO | J8: % NEG. | K8: VALOR NEGOCIADO | L8: ÁREA DE TERRENO (m²) – SI SE PUBLICA | M8: ÁREA CONSTRUIDA / PRIVADA (m²) – MÁX. 100 | N8: VALOR CONSTRUCCIONES (DEPRECIACIÓN) | O8: VALOR TERRENO (NEGOCIADO − CONSTRUCCIÓN) | P8: VALOR UNITARIO TERRENO ($/m²) – SOLO SI HAY LOTE | Q8: VALOR INTEGRAL $/m² DE TERRENO | R8: VALOR INTEGRAL $/m² CONSTRUIDO (CASA / APARTAMENTO) | S8: NORMA URBANÍSTICA (POT / tratamiento / uso) | T8: ESTRATO | U8: OBSERVACIONES / DESCRIPCIÓN | V8: FUENTE (nombre) | W8: TELÉFONO | X8: ENLACE (URL) | Y8: COMPARABILIDAD | Z8: ¿INCLUIR? (SÍ/NO) | AA8: VALOR PARA ESTADÍSTICA ($/m² CONSTRUIDO) | AB8: ALERTAS | AC8: ¿EN VALOR ADOPTADO? | AD8: SOPORTE (captura)
A9: 1 | B9: 46300 | C9: Casa-lote | D9: Oferta de venta | E9: Bello | F9: Niquía Camacol (parte baja) | G9: Niquía Camacol parte baja, Bello | H9: 6.342933, -75.551884 | I9: 380000000 | J9: =DATOS!$C$17 | K9: =IF(I9="","",I9*(1-J9)) | L9: 216 | N9: =IF(A9="","",SUMIFS(DEPRECIACIÓN!$P$5:$P$24,DEPRECIACIÓN!$A$5:$A$24,A9)) | O9: =IF(K9="","",K9-N(N9)) | P9: =IF(OR(O9="",N(L9)<=0),"",O9/L9) | Q9: =IF(OR(K9="",N(L9)<=0),"",K9/L9) | R9: =IF(OR(K9="",N(M9)<=0),"",K9/M9) | S9: Por verificar en POT de Bello (Acuerdo vigente) | U9: Lote con casa para remodelar (ladrillo, piso en cemento), 2 alcobas, 1 baño, cocina sencilla sin gas. Cód. 6662. Ficha Doomos: 30/08/2026 y "2 días en el mercado · actualizado hoy" (fecha inconsistente). No publica piso, régimen ni administración ni área construida. | V9: La Palma Inmobiliaria S.A.S. – Doomos | W9: Solicitar en portal | X9: https://www.doomos.com.co/propiedad/lote-casa-en-venta-en-bello-cod-6662 | Y9: Casa-lote 216 m² (fuera del rango 80–120 m²); incluida por decisión del perito. Falta área construida, nivel y régimen. | Z9: SÍ | AA9: =IF(AND(Z9="SÍ",ISNUMBER(R9)),R9,"") | AB9: =IF(A9="","",IF(LEN(IF(B9="","SIN FECHA; ",IF(DATOS!$C$12-B9>DATOS!$C$18*30.4,"VENCIDA; ",""))&IF(X9="","SIN ENLACE; ","")&IF(H9="","SIN COORDENADAS; ","")&IF(L9="","SIN ÁREA; ","")&IF(AND(ISNUMBER(AA9),ISNUMBER($P$45),ISNUMBER($P$46),N($P$44)>DATOS!$C$16),IF(OR(AA9<$P$45,AA9>$P$46),"FUERA DE LÍMITES; ",""),""))=0,"OK",IF(B9="","SIN FECHA; ",IF(DATOS!$C$12-B9>DATOS!$C$18*30.4,"VENCIDA; ",""))&IF(X9="","SIN ENLACE; ","")&IF(H9="","SIN COORDENADAS; ","")&IF(L9="","SIN ÁREA; ","")&IF(AND(ISNUMBER(AA9),ISNUMBER($P$45),ISNUMBER($P$46),N($P$44)>DATOS!$C$16),IF(OR(AA9<$P$45,AA9>$P$46),"FUERA DE LÍMITES; ",""),""))) | AC9: =IF(AA9="","",IF(COMBINACIONES_NPH!$B$18="MUESTRA COMPLETA","SÍ",IF(AUX_NPH!F5="","NO (filtrada)",IF(AND(AUX_NPH!F5>=COMBINACIONES_NPH!$B$22,AUX_NPH!F5<=COMBINACIONES_NPH!$B$22+COMBINACIONES_NPH!$B$23-1),"SÍ","NO")))) | AD9: =IF(A9="","","OFERTA NPH "&TEXT(A9,"00"))
A10: 2 | B10: 46300 | C10: Casa-lote | D10: Oferta de venta | E10: Bello | F10: Niquía | G10: Niquía, Bello, Antioquia | I10: 600000000 | J10: =DATOS!$C$17 | K10: =IF(I10="","",I10*(1-J10)) | L10: 129 | N10: =IF(A10="","",SUMIFS(DEPRECIACIÓN!$P$5:$P$24,DEPRECIACIÓN!$A$5:$A$24,A10)) | O10: =IF(K10="","",K10-N(N10)) | P10: =IF(OR(O10="",N(L10)<=0),"",O10/L10) | Q10: =IF(OR(K10="",N(L10)<=0),"",K10/L10) | R10: =IF(OR(K10="",N(M10)<=0),"",K10/M10) | S10: Por verificar en POT de Bello (Acuerdo vigente) | U10: Casa de primer piso para remodelar, 4 habitaciones, 1 baño, sala, comedor, cocina integral, cuarto útil; 129 m² totales (no separa lote de construcción). Cerca al colegio Consejo de Bello. No publica régimen, administración ni coordenadas. | V10: Myeinmobiliariasas – MercadoLibre | W10: Solicitar en portal | X10: https://casa.mercadolibre.com.co/MCO-2237453771-casa-lote-en-venta-niquia-bello-_JM | Y10: Casa-lote primer piso; 129 m² totales sin separar lote/construido. Falta confirmar régimen, administración y coordenadas. | Z10: SÍ | AA10: =IF(AND(Z10="SÍ",ISNUMBER(R10)),R10,"") | AB10: =IF(A10="","",IF(LEN(IF(B10="","SIN FECHA; ",IF(DATOS!$C$12-B10>DATOS!$C$18*30.4,"VENCIDA; ",""))&IF(X10="","SIN ENLACE; ","")&IF(H10="","SIN COORDENADAS; ","")&IF(L10="","SIN ÁREA; ","")&IF(AND(ISNUMBER(AA10),ISNUMBER($P$45),ISNUMBER($P$46),N($P$44)>DATOS!$C$16),IF(OR(AA10<$P$45,AA10>$P$46),"FUERA DE LÍMITES; ",""),""))=0,"OK",IF(B10="","SIN FECHA; ",IF(DATOS!$C$12-B10>DATOS!$C$18*30.4,"VENCIDA; ",""))&IF(X10="","SIN ENLACE; ","")&IF(H10="","SIN COORDENADAS; ","")&IF(L10="","SIN ÁREA; ","")&IF(AND(ISNUMBER(AA10),ISNUMBER($P$45),ISNUMBER($P$46),N($P$44)>DATOS!$C$16),IF(OR(AA10<$P$45,AA10>$P$46),"FUERA DE LÍMITES; ",""),""))) | AC10: =IF(AA10="","",IF(COMBINACIONES_NPH!$B$18="MUESTRA COMPLETA","SÍ",IF(AUX_NPH!F6="","NO (filtrada)",IF(AND(AUX_NPH!F6>=COMBINACIONES_NPH!$B$22,AUX_NPH!F6<=COMBINACIONES_NPH!$B$22+COMBINACIONES_NPH!$B$23-1),"SÍ","NO")))) | AD10: =IF(A10="","","OFERTA NPH "&TEXT(A10,"00"))
A11: 3 | B11: 46300 | C11: Casa-lote | D11: Oferta de venta | E11: Bello | F11: Barrio Nuevo | G11: Barrio Nuevo, Bello, Antioquia | I11: 495000000 | J11: =DATOS!$C$17 | K11: =IF(I11="","",I11*(1-J11)) | L11: 120 | N11: =IF(A11="","",SUMIFS(DEPRECIACIÓN!$P$5:$P$24,DEPRECIACIÓN!$A$5:$A$24,A11)) | O11: =IF(K11="","",K11-N(N11)) | P11: =IF(OR(O11="",N(L11)<=0),"",O11/L11) | Q11: =IF(OR(K11="",N(L11)<=0),"",K11/L11) | R11: =IF(OR(K11="",N(M11)<=0),"",K11/M11) | S11: Por verificar en POT de Bello (Acuerdo vigente) | U11: Casa unifamiliar con aire, 4 habitaciones, 2 baños, 2 patios, sala-comedor, cocina semiintegral; 120 m² totales (no separa lote/construido). Publicada hace 9 días (a 05/10/2026). No publica nivel, régimen, administración ni coordenadas. | V11: Myeinmobiliariasas – MercadoLibre | W11: Solicitar en portal | X11: https://casa.mercadolibre.com.co/MCO-2237592443-casa-lote-en-venta-en-barrio-nuevo-bello-_JM | Y11: Casa-lote 120 m² totales sin separar lote/construido. Falta nivel, régimen, administración y coordenadas; barrio por confirmar distancia al objeto. | Z11: SÍ | AA11: =IF(AND(Z11="SÍ",ISNUMBER(R11)),R11,"") | AB11: =IF(A11="","",IF(LEN(IF(B11="","SIN FECHA; ",IF(DATOS!$C$12-B11>DATOS!$C$18*30.4,"VENCIDA; ",""))&IF(X11="","SIN ENLACE; ","")&IF(H11="","SIN COORDENADAS; ","")&IF(L11="","SIN ÁREA; ","")&IF(AND(ISNUMBER(AA11),ISNUMBER($P$45),ISNUMBER($P$46),N($P$44)>DATOS!$C$16),IF(OR(AA11<$P$45,AA11>$P$46),"FUERA DE LÍMITES; ",""),""))=0,"OK",IF(B11="","SIN FECHA; ",IF(DATOS!$C$12-B11>DATOS!$C$18*30.4,"VENCIDA; ",""))&IF(X11="","SIN ENLACE; ","")&IF(H11="","SIN COORDENADAS; ","")&IF(L11="","SIN ÁREA; ","")&IF(AND(ISNUMBER(AA11),ISNUMBER($P$45),ISNUMBER($P$46),N($P$44)>DATOS!$C$16),IF(OR(AA11<$P$45,AA11>$P$46),"FUERA DE LÍMITES; ",""),""))) | AC11: =IF(AA11="","",IF(COMBINACIONES_NPH!$B$18="MUESTRA COMPLETA","SÍ",IF(AUX_NPH!F7="","NO (filtrada)",IF(AND(AUX_NPH!F7>=COMBINACIONES_NPH!$B$22,AUX_NPH!F7<=COMBINACIONES_NPH!$B$22+COMBINACIONES_NPH!$B$23-1),"SÍ","NO")))) | AD11: =IF(A11="","","OFERTA NPH "&TEXT(A11,"00"))
A12: 4 | B12: 46300 | C12: Casa-lote | D12: Oferta de venta | E12: Bello | F12: Mesa | G12: Barrio Mesa, a una cuadra de la Obra 2000, contiguo a fruver, Bello | I12: 390000000 | J12: =DATOS!$C$17 | K12: =IF(I12="","",I12*(1-J12)) | L12: 120 | N12: =IF(A12="","",SUMIFS(DEPRECIACIÓN!$P$5:$P$24,DEPRECIACIÓN!$A$5:$A$24,A12)) | O12: =IF(K12="","",K12-N(N12)) | P12: =IF(OR(O12="",N(L12)<=0),"",O12/L12) | Q12: =IF(OR(K12="",N(L12)<=0),"",K12/L12) | R12: =IF(OR(K12="",N(M12)<=0),"",K12/M12) | S12: Por verificar en POT de Bello (Acuerdo vigente) | U12: Casa-lote apta para construir apartamentos o locales. Escritura: 8 x 18 m; real aproximadamente 120 m². Ficha: 120 m² totales. Publicada hace 5 días (a 05/10/2026). No publica nivel, régimen, administración ni coordenadas. | V12: Aviarrendamientosvicasas – MercadoLibre | W12: Solicitar en portal | X12: https://casa.mercadolibre.com.co/MCO-4493777078-vendo-casa-lote-obra-2000-barrio-mesa-bello-_JM | Y12: Casa-lote ~120 m² reales (escritura 144 m²). Falta nivel, régimen, administración y coordenadas. | Z12: SÍ | AA12: =IF(AND(Z12="SÍ",ISNUMBER(R12)),R12,"") | AB12: =IF(A12="","",IF(LEN(IF(B12="","SIN FECHA; ",IF(DATOS!$C$12-B12>DATOS!$C$18*30.4,"VENCIDA; ",""))&IF(X12="","SIN ENLACE; ","")&IF(H12="","SIN COORDENADAS; ","")&IF(L12="","SIN ÁREA; ","")&IF(AND(ISNUMBER(AA12),ISNUMBER($P$45),ISNUMBER($P$46),N($P$44)>DATOS!$C$16),IF(OR(AA12<$P$45,AA12>$P$46),"FUERA DE LÍMITES; ",""),""))=0,"OK",IF(B12="","SIN FECHA; ",IF(DATOS!$C$12-B12>DATOS!$C$18*30.4,"VENCIDA; ",""))&IF(X12="","SIN ENLACE; ","")&IF(H12="","SIN COORDENADAS; ","")&IF(L12="","SIN ÁREA; ","")&IF(AND(ISNUMBER(AA12),ISNUMBER($P$45),ISNUMBER($P$46),N($P$44)>DATOS!$C$16),IF(OR(AA12<$P$45,AA12>$P$46),"FUERA DE LÍMITES; ",""),""))) | AC12: =IF(AA12="","",IF(COMBINACIONES_NPH!$B$18="MUESTRA COMPLETA","SÍ",IF(AUX_NPH!F8="","NO (filtrada)",IF(AND(AUX_NPH!F8>=COMBINACIONES_NPH!$B$22,AUX_NPH!F8<=COMBINACIONES_NPH!$B$22+COMBINACIONES_NPH!$B$23-1),"SÍ","NO")))) | AD12: =IF(A12="","","OFERTA NPH "&TEXT(A12,"00"))
A13: 5 | B13: 46300 | C13: Casa | D13: Oferta de venta | E13: Bello | F13: Santa Ana | G13: Santa Ana, cerca a La Salle Super Punto, Bello | I13: 390000000 | J13: =DATOS!$C$17 | K13: =IF(I13="","",I13*(1-J13)) | L13: 42 | M13: 168 | N13: =IF(A13="","",SUMIFS(DEPRECIACIÓN!$P$5:$P$24,DEPRECIACIÓN!$A$5:$A$24,A13)) | O13: =IF(K13="","",K13-N(N13)) | P13: =IF(OR(O13="",N(L13)<=0),"",O13/L13) | Q13: =IF(OR(K13="",N(L13)<=0),"",K13/L13) | R13: =IF(OR(K13="",N(M13)<=0),"",K13/M13) | S13: Por verificar en POT de Bello (Acuerdo vigente) | U13: Casa de 4 niveles, 4 alcobas, 3 baños (uno con bañera), sala-comedor grande, cuarto útil, balcón; 0 parqueaderos; antigüedad 8 años; cada nivel 42 m², área total 168 m² (construida no desglosada; lote no informado). Publicada hace 2 meses (a 05/10/2026). Cód. publicación 4221795790; cód. propiedad anunciante 7520838. No publica régimen, administración ni coordenadas. ÁREA DE TERRENO 42 m² = SUPUESTO (niveles apilados); confirmar con el anunciante. Construcción descontada en DEPRECIACIÓN. | V13: Aliadosinmobiliarios – MercadoLibre | W13: Solicitar en portal | X13: https://casa.mercadolibre.com.co/MCO-4221795790-se-vende-hermosa-casa-de-4-niveles-en-santa-ana-bello-de-168-mts-_JM | Y13: Casa de 4 niveles, 168 m² construidos; incluida por decisión del perito. Valor del suelo = negociado − construcción depreciada (DEPRECIACIÓN). Falta régimen, administración y coordenadas. | Z13: SÍ | AA13: =IF(AND(Z13="SÍ",ISNUMBER(R13)),R13,"") | AB13: =IF(A13="","",IF(LEN(IF(B13="","SIN FECHA; ",IF(DATOS!$C$12-B13>DATOS!$C$18*30.4,"VENCIDA; ",""))&IF(X13="","SIN ENLACE; ","")&IF(H13="","SIN COORDENADAS; ","")&IF(L13="","SIN ÁREA; ","")&IF(AND(ISNUMBER(AA13),ISNUMBER($P$45),ISNUMBER($P$46),N($P$44)>DATOS!$C$16),IF(OR(AA13<$P$45,AA13>$P$46),"FUERA DE LÍMITES; ",""),""))=0,"OK",IF(B13="","SIN FECHA; ",IF(DATOS!$C$12-B13>DATOS!$C$18*30.4,"VENCIDA; ",""))&IF(X13="","SIN ENLACE; ","")&IF(H13="","SIN COORDENADAS; ","")&IF(L13="","SIN ÁREA; ","")&IF(AND(ISNUMBER(AA13),ISNUMBER($P$45),ISNUMBER($P$46),N($P$44)>DATOS!$C$16),IF(OR(AA13<$P$45,AA13>$P$46),"FUERA DE LÍMITES; ",""),""))) | AC13: =IF(AA13="","",IF(COMBINACIONES_NPH!$B$18="MUESTRA COMPLETA","SÍ",IF(AUX_NPH!F9="","NO (filtrada)",IF(AND(AUX_NPH!F9>=COMBINACIONES_NPH!$B$22,AUX_NPH!F9<=COMBINACIONES_NPH!$B$22+COMBINACIONES_NPH!$B$23-1),"SÍ","NO")))) | AD13: =IF(A13="","","OFERTA NPH "&TEXT(A13,"00"))
J14: =DATOS!$C$17 | K14: =IF(I14="","",I14*(1-J14)) | N14: =IF(A14="","",SUMIFS(DEPRECIACIÓN!$P$5:$P$24,DEPRECIACIÓN!$A$5:$A$24,A14)) | O14: =IF(K14="","",K14-N(N14)) | P14: =IF(OR(O14="",N(L14)<=0),"",O14/L14) | Q14: =IF(OR(K14="",N(L14)<=0),"",K14/L14) | R14: =IF(OR(K14="",N(M14)<=0),"",K14/M14) | AA14: =IF(AND(Z14="SÍ",ISNUMBER(R14)),R14,"") | AB14: =IF(A14="","",IF(LEN(IF(B14="","SIN FECHA; ",IF(DATOS!$C$12-B14>DATOS!$C$18*30.4,"VENCIDA; ",""))&IF(X14="","SIN ENLACE; ","")&IF(H14="","SIN COORDENADAS; ","")&IF(L14="","SIN ÁREA; ","")&IF(AND(ISNUMBER(AA14),ISNUMBER($P$45),ISNUMBER($P$46),N($P$44)>DATOS!$C$16),IF(OR(AA14<$P$45,AA14>$P$46),"FUERA DE LÍMITES; ",""),""))=0,"OK",IF(B14="","SIN FECHA; ",IF(DATOS!$C$12-B14>DATOS!$C$18*30.4,"VENCIDA; ",""))&IF(X14="","SIN ENLACE; ","")&IF(H14="","SIN COORDENADAS; ","")&IF(L14="","SIN ÁREA; ","")&IF(AND(ISNUMBER(AA14),ISNUMBER($P$45),ISNUMBER($P$46),N($P$44)>DATOS!$C$16),IF(OR(AA14<$P$45,AA14>$P$46),"FUERA DE LÍMITES; ",""),""))) | AC14: =IF(AA14="","",IF(COMBINACIONES_NPH!$B$18="MUESTRA COMPLETA","SÍ",IF(AUX_NPH!F10="","NO (filtrada)",IF(AND(AUX_NPH!F10>=COMBINACIONES_NPH!$B$22,AUX_NPH!F10<=COMBINACIONES_NPH!$B$22+COMBINACIONES_NPH!$B$23-1),"SÍ","NO")))) | AD14: =IF(A14="","","OFERTA NPH "&TEXT(A14,"00"))
J15: =DATOS!$C$17 | K15: =IF(I15="","",I15*(1-J15)) | N15: =IF(A15="","",SUMIFS(DEPRECIACIÓN!$P$5:$P$24,DEPRECIACIÓN!$A$5:$A$24,A15)) | O15: =IF(K15="","",K15-N(N15)) | P15: =IF(OR(O15="",N(L15)<=0),"",O15/L15) | Q15: =IF(OR(K15="",N(L15)<=0),"",K15/L15) | R15: =IF(OR(K15="",N(M15)<=0),"",K15/M15) | AA15: =IF(AND(Z15="SÍ",ISNUMBER(R15)),R15,"") | AB15: =IF(A15="","",IF(LEN(IF(B15="","SIN FECHA; ",IF(DATOS!$C$12-B15>DATOS!$C$18*30.4,"VENCIDA; ",""))&IF(X15="","SIN ENLACE; ","")&IF(H15="","SIN COORDENADAS; ","")&IF(L15="","SIN ÁREA; ","")&IF(AND(ISNUMBER(AA15),ISNUMBER($P$45),ISNUMBER($P$46),N($P$44)>DATOS!$C$16),IF(OR(AA15<$P$45,AA15>$P$46),"FUERA DE LÍMITES; ",""),""))=0,"OK",IF(B15="","SIN FECHA; ",IF(DATOS!$C$12-B15>DATOS!$C$18*30.4,"VENCIDA; ",""))&IF(X15="","SIN ENLACE; ","")&IF(H15="","SIN COORDENADAS; ","")&IF(L15="","SIN ÁREA; ","")&IF(AND(ISNUMBER(AA15),ISNUMBER($P$45),ISNUMBER($P$46),N($P$44)>DATOS!$C$16),IF(OR(AA15<$P$45,AA15>$P$46),"FUERA DE LÍMITES; ",""),""))) | AC15: =IF(AA15="","",IF(COMBINACIONES_NPH!$B$18="MUESTRA COMPLETA","SÍ",IF(AUX_NPH!F11="","NO (filtrada)",IF(AND(AUX_NPH!F11>=COMBINACIONES_NPH!$B$22,AUX_NPH!F11<=COMBINACIONES_NPH!$B$22+COMBINACIONES_NPH!$B$23-1),"SÍ","NO")))) | AD15: =IF(A15="","","OFERTA NPH "&TEXT(A15,"00"))
J16: =DATOS!$C$17 | K16: =IF(I16="","",I16*(1-J16)) | N16: =IF(A16="","",SUMIFS(DEPRECIACIÓN!$P$5:$P$24,DEPRECIACIÓN!$A$5:$A$24,A16)) | O16: =IF(K16="","",K16-N(N16)) | P16: =IF(OR(O16="",N(L16)<=0),"",O16/L16) | Q16: =IF(OR(K16="",N(L16)<=0),"",K16/L16) | R16: =IF(OR(K16="",N(M16)<=0),"",K16/M16) | AA16: =IF(AND(Z16="SÍ",ISNUMBER(R16)),R16,"") | AB16: =IF(A16="","",IF(LEN(IF(B16="","SIN FECHA; ",IF(DATOS!$C$12-B16>DATOS!$C$18*30.4,"VENCIDA; ",""))&IF(X16="","SIN ENLACE; ","")&IF(H16="","SIN COORDENADAS; ","")&IF(L16="","SIN ÁREA; ","")&IF(AND(ISNUMBER(AA16),ISNUMBER($P$45),ISNUMBER($P$46),N($P$44)>DATOS!$C$16),IF(OR(AA16<$P$45,AA16>$P$46),"FUERA DE LÍMITES; ",""),""))=0,"OK",IF(B16="","SIN FECHA; ",IF(DATOS!$C$12-B16>DATOS!$C$18*30.4,"VENCIDA; ",""))&IF(X16="","SIN ENLACE; ","")&IF(H16="","SIN COORDENADAS; ","")&IF(L16="","SIN ÁREA; ","")&IF(AND(ISNUMBER(AA16),ISNUMBER($P$45),ISNUMBER($P$46),N($P$44)>DATOS!$C$16),IF(OR(AA16<$P$45,AA16>$P$46),"FUERA DE LÍMITES; ",""),""))) | AC16: =IF(AA16="","",IF(COMBINACIONES_NPH!$B$18="MUESTRA COMPLETA","SÍ",IF(AUX_NPH!F12="","NO (filtrada)",IF(AND(AUX_NPH!F12>=COMBINACIONES_NPH!$B$22,AUX_NPH!F12<=COMBINACIONES_NPH!$B$22+COMBINACIONES_NPH!$B$23-1),"SÍ","NO")))) | AD16: =IF(A16="","","OFERTA NPH "&TEXT(A16,"00"))
J17: =DATOS!$C$17 | K17: =IF(I17="","",I17*(1-J17)) | N17: =IF(A17="","",SUMIFS(DEPRECIACIÓN!$P$5:$P$24,DEPRECIACIÓN!$A$5:$A$24,A17)) | O17: =IF(K17="","",K17-N(N17)) | P17: =IF(OR(O17="",N(L17)<=0),"",O17/L17) | Q17: =IF(OR(K17="",N(L17)<=0),"",K17/L17) | R17: =IF(OR(K17="",N(M17)<=0),"",K17/M17) | AA17: =IF(AND(Z17="SÍ",ISNUMBER(R17)),R17,"") | AB17: =IF(A17="","",IF(LEN(IF(B17="","SIN FECHA; ",IF(DATOS!$C$12-B17>DATOS!$C$18*30.4,"VENCIDA; ",""))&IF(X17="","SIN ENLACE; ","")&IF(H17="","SIN COORDENADAS; ","")&IF(L17="","SIN ÁREA; ","")&IF(AND(ISNUMBER(AA17),ISNUMBER($P$45),ISNUMBER($P$46),N($P$44)>DATOS!$C$16),IF(OR(AA17<$P$45,AA17>$P$46),"FUERA DE LÍMITES; ",""),""))=0,"OK",IF(B17="","SIN FECHA; ",IF(DATOS!$C$12-B17>DATOS!$C$18*30.4,"VENCIDA; ",""))&IF(X17="","SIN ENLACE; ","")&IF(H17="","SIN COORDENADAS; ","")&IF(L17="","SIN ÁREA; ","")&IF(AND(ISNUMBER(AA17),ISNUMBER($P$45),ISNUMBER($P$46),N($P$44)>DATOS!$C$16),IF(OR(AA17<$P$45,AA17>$P$46),"FUERA DE LÍMITES; ",""),""))) | AC17: =IF(AA17="","",IF(COMBINACIONES_NPH!$B$18="MUESTRA COMPLETA","SÍ",IF(AUX_NPH!F13="","NO (filtrada)",IF(AND(AUX_NPH!F13>=COMBINACIONES_NPH!$B$22,AUX_NPH!F13<=COMBINACIONES_NPH!$B$22+COMBINACIONES_NPH!$B$23-1),"SÍ","NO")))) | AD17: =IF(A17="","","OFERTA NPH "&TEXT(A17,"00"))
J18: =DATOS!$C$17 | K18: =IF(I18="","",I18*(1-J18)) | N18: =IF(A18="","",SUMIFS(DEPRECIACIÓN!$P$5:$P$24,DEPRECIACIÓN!$A$5:$A$24,A18)) | O18: =IF(K18="","",K18-N(N18)) | P18: =IF(OR(O18="",N(L18)<=0),"",O18/L18) | Q18: =IF(OR(K18="",N(L18)<=0),"",K18/L18) | R18: =IF(OR(K18="",N(M18)<=0),"",K18/M18) | AA18: =IF(AND(Z18="SÍ",ISNUMBER(R18)),R18,"") | AB18: =IF(A18="","",IF(LEN(IF(B18="","SIN FECHA; ",IF(DATOS!$C$12-B18>DATOS!$C$18*30.4,"VENCIDA; ",""))&IF(X18="","SIN ENLACE; ","")&IF(H18="","SIN COORDENADAS; ","")&IF(L18="","SIN ÁREA; ","")&IF(AND(ISNUMBER(AA18),ISNUMBER($P$45),ISNUMBER($P$46),N($P$44)>DATOS!$C$16),IF(OR(AA18<$P$45,AA18>$P$46),"FUERA DE LÍMITES; ",""),""))=0,"OK",IF(B18="","SIN FECHA; ",IF(DATOS!$C$12-B18>DATOS!$C$18*30.4,"VENCIDA; ",""))&IF(X18="","SIN ENLACE; ","")&IF(H18="","SIN COORDENADAS; ","")&IF(L18="","SIN ÁREA; ","")&IF(AND(ISNUMBER(AA18),ISNUMBER($P$45),ISNUMBER($P$46),N($P$44)>DATOS!$C$16),IF(OR(AA18<$P$45,AA18>$P$46),"FUERA DE LÍMITES; ",""),""))) | AC18: =IF(AA18="","",IF(COMBINACIONES_NPH!$B$18="MUESTRA COMPLETA","SÍ",IF(AUX_NPH!F14="","NO (filtrada)",IF(AND(AUX_NPH!F14>=COMBINACIONES_NPH!$B$22,AUX_NPH!F14<=COMBINACIONES_NPH!$B$22+COMBINACIONES_NPH!$B$23-1),"SÍ","NO")))) | AD18: =IF(A18="","","OFERTA NPH "&TEXT(A18,"00"))
J19: =DATOS!$C$17 | K19: =IF(I19="","",I19*(1-J19)) | N19: =IF(A19="","",SUMIFS(DEPRECIACIÓN!$P$5:$P$24,DEPRECIACIÓN!$A$5:$A$24,A19)) | O19: =IF(K19="","",K19-N(N19)) | P19: =IF(OR(O19="",N(L19)<=0),"",O19/L19) | Q19: =IF(OR(K19="",N(L19)<=0),"",K19/L19) | R19: =IF(OR(K19="",N(M19)<=0),"",K19/M19) | AA19: =IF(AND(Z19="SÍ",ISNUMBER(R19)),R19,"") | AB19: =IF(A19="","",IF(LEN(IF(B19="","SIN FECHA; ",IF(DATOS!$C$12-B19>DATOS!$C$18*30.4,"VENCIDA; ",""))&IF(X19="","SIN ENLACE; ","")&IF(H19="","SIN COORDENADAS; ","")&IF(L19="","SIN ÁREA; ","")&IF(AND(ISNUMBER(AA19),ISNUMBER($P$45),ISNUMBER($P$46),N($P$44)>DATOS!$C$16),IF(OR(AA19<$P$45,AA19>$P$46),"FUERA DE LÍMITES; ",""),""))=0,"OK",IF(B19="","SIN FECHA; ",IF(DATOS!$C$12-B19>DATOS!$C$18*30.4,"VENCIDA; ",""))&IF(X19="","SIN ENLACE; ","")&IF(H19="","SIN COORDENADAS; ","")&IF(L19="","SIN ÁREA; ","")&IF(AND(ISNUMBER(AA19),ISNUMBER($P$45),ISNUMBER($P$46),N($P$44)>DATOS!$C$16),IF(OR(AA19<$P$45,AA19>$P$46),"FUERA DE LÍMITES; ",""),""))) | AC19: =IF(AA19="","",IF(COMBINACIONES_NPH!$B$18="MUESTRA COMPLETA","SÍ",IF(AUX_NPH!F15="","NO (filtrada)",IF(AND(AUX_NPH!F15>=COMBINACIONES_NPH!$B$22,AUX_NPH!F15<=COMBINACIONES_NPH!$B$22+COMBINACIONES_NPH!$B$23-1),"SÍ","NO")))) | AD19: =IF(A19="","","OFERTA NPH "&TEXT(A19,"00"))
J20: =DATOS!$C$17 | K20: =IF(I20="","",I20*(1-J20)) | N20: =IF(A20="","",SUMIFS(DEPRECIACIÓN!$P$5:$P$24,DEPRECIACIÓN!$A$5:$A$24,A20)) | O20: =IF(K20="","",K20-N(N20)) | P20: =IF(OR(O20="",N(L20)<=0),"",O20/L20) | Q20: =IF(OR(K20="",N(L20)<=0),"",K20/L20) | R20: =IF(OR(K20="",N(M20)<=0),"",K20/M20) | AA20: =IF(AND(Z20="SÍ",ISNUMBER(R20)),R20,"") | AB20: =IF(A20="","",IF(LEN(IF(B20="","SIN FECHA; ",IF(DATOS!$C$12-B20>DATOS!$C$18*30.4,"VENCIDA; ",""))&IF(X20="","SIN ENLACE; ","")&IF(H20="","SIN COORDENADAS; ","")&IF(L20="","SIN ÁREA; ","")&IF(AND(ISNUMBER(AA20),ISNUMBER($P$45),ISNUMBER($P$46),N($P$44)>DATOS!$C$16),IF(OR(AA20<$P$45,AA20>$P$46),"FUERA DE LÍMITES; ",""),""))=0,"OK",IF(B20="","SIN FECHA; ",IF(DATOS!$C$12-B20>DATOS!$C$18*30.4,"VENCIDA; ",""))&IF(X20="","SIN ENLACE; ","")&IF(H20="","SIN COORDENADAS; ","")&IF(L20="","SIN ÁREA; ","")&IF(AND(ISNUMBER(AA20),ISNUMBER($P$45),ISNUMBER($P$46),N($P$44)>DATOS!$C$16),IF(OR(AA20<$P$45,AA20>$P$46),"FUERA DE LÍMITES; ",""),""))) | AC20: =IF(AA20="","",IF(COMBINACIONES_NPH!$B$18="MUESTRA COMPLETA","SÍ",IF(AUX_NPH!F16="","NO (filtrada)",IF(AND(AUX_NPH!F16>=COMBINACIONES_NPH!$B$22,AUX_NPH!F16<=COMBINACIONES_NPH!$B$22+COMBINACIONES_NPH!$B$23-1),"SÍ","NO")))) | AD20: =IF(A20="","","OFERTA NPH "&TEXT(A20,"00"))
J21: =DATOS!$C$17 | K21: =IF(I21="","",I21*(1-J21)) | N21: =IF(A21="","",SUMIFS(DEPRECIACIÓN!$P$5:$P$24,DEPRECIACIÓN!$A$5:$A$24,A21)) | O21: =IF(K21="","",K21-N(N21)) | P21: =IF(OR(O21="",N(L21)<=0),"",O21/L21) | Q21: =IF(OR(K21="",N(L21)<=0),"",K21/L21) | R21: =IF(OR(K21="",N(M21)<=0),"",K21/M21) | AA21: =IF(AND(Z21="SÍ",ISNUMBER(R21)),R21,"") | AB21: =IF(A21="","",IF(LEN(IF(B21="","SIN FECHA; ",IF(DATOS!$C$12-B21>DATOS!$C$18*30.4,"VENCIDA; ",""))&IF(X21="","SIN ENLACE; ","")&IF(H21="","SIN COORDENADAS; ","")&IF(L21="","SIN ÁREA; ","")&IF(AND(ISNUMBER(AA21),ISNUMBER($P$45),ISNUMBER($P$46),N($P$44)>DATOS!$C$16),IF(OR(AA21<$P$45,AA21>$P$46),"FUERA DE LÍMITES; ",""),""))=0,"OK",IF(B21="","SIN FECHA; ",IF(DATOS!$C$12-B21>DATOS!$C$18*30.4,"VENCIDA; ",""))&IF(X21="","SIN ENLACE; ","")&IF(H21="","SIN COORDENADAS; ","")&IF(L21="","SIN ÁREA; ","")&IF(AND(ISNUMBER(AA21),ISNUMBER($P$45),ISNUMBER($P$46),N($P$44)>DATOS!$C$16),IF(OR(AA21<$P$45,AA21>$P$46),"FUERA DE LÍMITES; ",""),""))) | AC21: =IF(AA21="","",IF(COMBINACIONES_NPH!$B$18="MUESTRA COMPLETA","SÍ",IF(AUX_NPH!F17="","NO (filtrada)",IF(AND(AUX_NPH!F17>=COMBINACIONES_NPH!$B$22,AUX_NPH!F17<=COMBINACIONES_NPH!$B$22+COMBINACIONES_NPH!$B$23-1),"SÍ","NO")))) | AD21: =IF(A21="","","OFERTA NPH "&TEXT(A21,"00"))
J22: =DATOS!$C$17 | K22: =IF(I22="","",I22*(1-J22)) | N22: =IF(A22="","",SUMIFS(DEPRECIACIÓN!$P$5:$P$24,DEPRECIACIÓN!$A$5:$A$24,A22)) | O22: =IF(K22="","",K22-N(N22)) | P22: =IF(OR(O22="",N(L22)<=0),"",O22/L22) | Q22: =IF(OR(K22="",N(L22)<=0),"",K22/L22) | R22: =IF(OR(K22="",N(M22)<=0),"",K22/M22) | AA22: =IF(AND(Z22="SÍ",ISNUMBER(R22)),R22,"") | AB22: =IF(A22="","",IF(LEN(IF(B22="","SIN FECHA; ",IF(DATOS!$C$12-B22>DATOS!$C$18*30.4,"VENCIDA; ",""))&IF(X22="","SIN ENLACE; ","")&IF(H22="","SIN COORDENADAS; ","")&IF(L22="","SIN ÁREA; ","")&IF(AND(ISNUMBER(AA22),ISNUMBER($P$45),ISNUMBER($P$46),N($P$44)>DATOS!$C$16),IF(OR(AA22<$P$45,AA22>$P$46),"FUERA DE LÍMITES; ",""),""))=0,"OK",IF(B22="","SIN FECHA; ",IF(DATOS!$C$12-B22>DATOS!$C$18*30.4,"VENCIDA; ",""))&IF(X22="","SIN ENLACE; ","")&IF(H22="","SIN COORDENADAS; ","")&IF(L22="","SIN ÁREA; ","")&IF(AND(ISNUMBER(AA22),ISNUMBER($P$45),ISNUMBER($P$46),N($P$44)>DATOS!$C$16),IF(OR(AA22<$P$45,AA22>$P$46),"FUERA DE LÍMITES; ",""),""))) | AC22: =IF(AA22="","",IF(COMBINACIONES_NPH!$B$18="MUESTRA COMPLETA","SÍ",IF(AUX_NPH!F18="","NO (filtrada)",IF(AND(AUX_NPH!F18>=COMBINACIONES_NPH!$B$22,AUX_NPH!F18<=COMBINACIONES_NPH!$B$22+COMBINACIONES_NPH!$B$23-1),"SÍ","NO")))) | AD22: =IF(A22="","","OFERTA NPH "&TEXT(A22,"00"))
K23: =IF(I23="","",I23*(1-J23)) | N23: =IF(A23="","",SUMIFS(DEPRECIACIÓN!$P$5:$P$24,DEPRECIACIÓN!$A$5:$A$24,A23)) | O23: =IF(K23="","",K23-N(N23)) | P23: =IF(OR(O23="",N(L23)<=0),"",O23/L23) | Q23: =IF(OR(K23="",N(L23)<=0),"",K23/L23) | R23: =IF(OR(K23="",N(M23)<=0),"",K23/M23) | AA23: =IF(AND(Z23="SÍ",ISNUMBER(R23)),R23,"") | AB23: =IF(A23="","",IF(LEN(IF(B23="","SIN FECHA; ",IF(DATOS!$C$12-B23>DATOS!$C$18*30.4,"VENCIDA; ",""))&IF(X23="","SIN ENLACE; ","")&IF(H23="","SIN COORDENADAS; ","")&IF(L23="","SIN ÁREA; ","")&IF(AND(ISNUMBER(AA23),ISNUMBER($P$45),ISNUMBER($P$46),N($P$44)>DATOS!$C$16),IF(OR(AA23<$P$45,AA23>$P$46),"FUERA DE LÍMITES; ",""),""))=0,"OK",IF(B23="","SIN FECHA; ",IF(DATOS!$C$12-B23>DATOS!$C$18*30.4,"VENCIDA; ",""))&IF(X23="","SIN ENLACE; ","")&IF(H23="","SIN COORDENADAS; ","")&IF(L23="","SIN ÁREA; ","")&IF(AND(ISNUMBER(AA23),ISNUMBER($P$45),ISNUMBER($P$46),N($P$44)>DATOS!$C$16),IF(OR(AA23<$P$45,AA23>$P$46),"FUERA DE LÍMITES; ",""),""))) | AC23: =IF(AA23="","",IF(COMBINACIONES_NPH!$B$18="MUESTRA COMPLETA","SÍ",IF(AUX_NPH!F19="","NO (filtrada)",IF(AND(AUX_NPH!F19>=COMBINACIONES_NPH!$B$22,AUX_NPH!F19<=COMBINACIONES_NPH!$B$22+COMBINACIONES_NPH!$B$23-1),"SÍ","NO")))) | AD23: =IF(A23="","","OFERTA NPH "&TEXT(A23,"00"))
K24: =IF(I24="","",I24*(1-J24)) | N24: =IF(A24="","",SUMIFS(DEPRECIACIÓN!$P$5:$P$24,DEPRECIACIÓN!$A$5:$A$24,A24)) | O24: =IF(K24="","",K24-N(N24)) | P24: =IF(OR(O24="",N(L24)<=0),"",O24/L24) | Q24: =IF(OR(K24="",N(L24)<=0),"",K24/L24) | R24: =IF(OR(K24="",N(M24)<=0),"",K24/M24) | AA24: =IF(AND(Z24="SÍ",ISNUMBER(R24)),R24,"") | AB24: =IF(A24="","",IF(LEN(IF(B24="","SIN FECHA; ",IF(DATOS!$C$12-B24>DATOS!$C$18*30.4,"VENCIDA; ",""))&IF(X24="","SIN ENLACE; ","")&IF(H24="","SIN COORDENADAS; ","")&IF(L24="","SIN ÁREA; ","")&IF(AND(ISNUMBER(AA24),ISNUMBER($P$45),ISNUMBER($P$46),N($P$44)>DATOS!$C$16),IF(OR(AA24<$P$45,AA24>$P$46),"FUERA DE LÍMITES; ",""),""))=0,"OK",IF(B24="","SIN FECHA; ",IF(DATOS!$C$12-B24>DATOS!$C$18*30.4,"VENCIDA; ",""))&IF(X24="","SIN ENLACE; ","")&IF(H24="","SIN COORDENADAS; ","")&IF(L24="","SIN ÁREA; ","")&IF(AND(ISNUMBER(AA24),ISNUMBER($P$45),ISNUMBER($P$46),N($P$44)>DATOS!$C$16),IF(OR(AA24<$P$45,AA24>$P$46),"FUERA DE LÍMITES; ",""),""))) | AC24: =IF(AA24="","",IF(COMBINACIONES_NPH!$B$18="MUESTRA COMPLETA","SÍ",IF(AUX_NPH!F20="","NO (filtrada)",IF(AND(AUX_NPH!F20>=COMBINACIONES_NPH!$B$22,AUX_NPH!F20<=COMBINACIONES_NPH!$B$22+COMBINACIONES_NPH!$B$23-1),"SÍ","NO")))) | AD24: =IF(A24="","","OFERTA NPH "&TEXT(A24,"00"))
K25: =IF(I25="","",I25*(1-J25)) | N25: =IF(A25="","",SUMIFS(DEPRECIACIÓN!$P$5:$P$24,DEPRECIACIÓN!$A$5:$A$24,A25)) | O25: =IF(K25="","",K25-N(N25)) | P25: =IF(OR(O25="",N(L25)<=0),"",O25/L25) | Q25: =IF(OR(K25="",N(L25)<=0),"",K25/L25) | R25: =IF(OR(K25="",N(M25)<=0),"",K25/M25) | AA25: =IF(AND(Z25="SÍ",ISNUMBER(R25)),R25,"") | AB25: =IF(A25="","",IF(LEN(IF(B25="","SIN FECHA; ",IF(DATOS!$C$12-B25>DATOS!$C$18*30.4,"VENCIDA; ",""))&IF(X25="","SIN ENLACE; ","")&IF(H25="","SIN COORDENADAS; ","")&IF(L25="","SIN ÁREA; ","")&IF(AND(ISNUMBER(AA25),ISNUMBER($P$45),ISNUMBER($P$46),N($P$44)>DATOS!$C$16),IF(OR(AA25<$P$45,AA25>$P$46),"FUERA DE LÍMITES; ",""),""))=0,"OK",IF(B25="","SIN FECHA; ",IF(DATOS!$C$12-B25>DATOS!$C$18*30.4,"VENCIDA; ",""))&IF(X25="","SIN ENLACE; ","")&IF(H25="","SIN COORDENADAS; ","")&IF(L25="","SIN ÁREA; ","")&IF(AND(ISNUMBER(AA25),ISNUMBER($P$45),ISNUMBER($P$46),N($P$44)>DATOS!$C$16),IF(OR(AA25<$P$45,AA25>$P$46),"FUERA DE LÍMITES; ",""),""))) | AC25: =IF(AA25="","",IF(COMBINACIONES_NPH!$B$18="MUESTRA COMPLETA","SÍ",IF(AUX_NPH!F21="","NO (filtrada)",IF(AND(AUX_NPH!F21>=COMBINACIONES_NPH!$B$22,AUX_NPH!F21<=COMBINACIONES_NPH!$B$22+COMBINACIONES_NPH!$B$23-1),"SÍ","NO")))) | AD25: =IF(A25="","","OFERTA NPH "&TEXT(A25,"00"))
K26: =IF(I26="","",I26*(1-J26)) | N26: =IF(A26="","",SUMIFS(DEPRECIACIÓN!$P$5:$P$24,DEPRECIACIÓN!$A$5:$A$24,A26)) | O26: =IF(K26="","",K26-N(N26)) | P26: =IF(OR(O26="",N(L26)<=0),"",O26/L26) | Q26: =IF(OR(K26="",N(L26)<=0),"",K26/L26) | R26: =IF(OR(K26="",N(M26)<=0),"",K26/M26) | AA26: =IF(AND(Z26="SÍ",ISNUMBER(R26)),R26,"") | AB26: =IF(A26="","",IF(LEN(IF(B26="","SIN FECHA; ",IF(DATOS!$C$12-B26>DATOS!$C$18*30.4,"VENCIDA; ",""))&IF(X26="","SIN ENLACE; ","")&IF(H26="","SIN COORDENADAS; ","")&IF(L26="","SIN ÁREA; ","")&IF(AND(ISNUMBER(AA26),ISNUMBER($P$45),ISNUMBER($P$46),N($P$44)>DATOS!$C$16),IF(OR(AA26<$P$45,AA26>$P$46),"FUERA DE LÍMITES; ",""),""))=0,"OK",IF(B26="","SIN FECHA; ",IF(DATOS!$C$12-B26>DATOS!$C$18*30.4,"VENCIDA; ",""))&IF(X26="","SIN ENLACE; ","")&IF(H26="","SIN COORDENADAS; ","")&IF(L26="","SIN ÁREA; ","")&IF(AND(ISNUMBER(AA26),ISNUMBER($P$45),ISNUMBER($P$46),N($P$44)>DATOS!$C$16),IF(OR(AA26<$P$45,AA26>$P$46),"FUERA DE LÍMITES; ",""),""))) | AC26: =IF(AA26="","",IF(COMBINACIONES_NPH!$B$18="MUESTRA COMPLETA","SÍ",IF(AUX_NPH!F22="","NO (filtrada)",IF(AND(AUX_NPH!F22>=COMBINACIONES_NPH!$B$22,AUX_NPH!F22<=COMBINACIONES_NPH!$B$22+COMBINACIONES_NPH!$B$23-1),"SÍ","NO")))) | AD26: =IF(A26="","","OFERTA NPH "&TEXT(A26,"00"))
K27: =IF(I27="","",I27*(1-J27)) | N27: =IF(A27="","",SUMIFS(DEPRECIACIÓN!$P$5:$P$24,DEPRECIACIÓN!$A$5:$A$24,A27)) | O27: =IF(K27="","",K27-N(N27)) | P27: =IF(OR(O27="",N(L27)<=0),"",O27/L27) | Q27: =IF(OR(K27="",N(L27)<=0),"",K27/L27) | R27: =IF(OR(K27="",N(M27)<=0),"",K27/M27) | AA27: =IF(AND(Z27="SÍ",ISNUMBER(R27)),R27,"") | AB27: =IF(A27="","",IF(LEN(IF(B27="","SIN FECHA; ",IF(DATOS!$C$12-B27>DATOS!$C$18*30.4,"VENCIDA; ",""))&IF(X27="","SIN ENLACE; ","")&IF(H27="","SIN COORDENADAS; ","")&IF(L27="","SIN ÁREA; ","")&IF(AND(ISNUMBER(AA27),ISNUMBER($P$45),ISNUMBER($P$46),N($P$44)>DATOS!$C$16),IF(OR(AA27<$P$45,AA27>$P$46),"FUERA DE LÍMITES; ",""),""))=0,"OK",IF(B27="","SIN FECHA; ",IF(DATOS!$C$12-B27>DATOS!$C$18*30.4,"VENCIDA; ",""))&IF(X27="","SIN ENLACE; ","")&IF(H27="","SIN COORDENADAS; ","")&IF(L27="","SIN ÁREA; ","")&IF(AND(ISNUMBER(AA27),ISNUMBER($P$45),ISNUMBER($P$46),N($P$44)>DATOS!$C$16),IF(OR(AA27<$P$45,AA27>$P$46),"FUERA DE LÍMITES; ",""),""))) | AC27: =IF(AA27="","",IF(COMBINACIONES_NPH!$B$18="MUESTRA COMPLETA","SÍ",IF(AUX_NPH!F23="","NO (filtrada)",IF(AND(AUX_NPH!F23>=COMBINACIONES_NPH!$B$22,AUX_NPH!F23<=COMBINACIONES_NPH!$B$22+COMBINACIONES_NPH!$B$23-1),"SÍ","NO")))) | AD27: =IF(A27="","","OFERTA NPH "&TEXT(A27,"00"))
K28: =IF(I28="","",I28*(1-J28)) | N28: =IF(A28="","",SUMIFS(DEPRECIACIÓN!$P$5:$P$24,DEPRECIACIÓN!$A$5:$A$24,A28)) | O28: =IF(K28="","",K28-N(N28)) | P28: =IF(OR(O28="",N(L28)<=0),"",O28/L28) | Q28: =IF(OR(K28="",N(L28)<=0),"",K28/L28) | R28: =IF(OR(K28="",N(M28)<=0),"",K28/M28) | AA28: =IF(AND(Z28="SÍ",ISNUMBER(R28)),R28,"") | AB28: =IF(A28="","",IF(LEN(IF(B28="","SIN FECHA; ",IF(DATOS!$C$12-B28>DATOS!$C$18*30.4,"VENCIDA; ",""))&IF(X28="","SIN ENLACE; ","")&IF(H28="","SIN COORDENADAS; ","")&IF(L28="","SIN ÁREA; ","")&IF(AND(ISNUMBER(AA28),ISNUMBER($P$45),ISNUMBER($P$46),N($P$44)>DATOS!$C$16),IF(OR(AA28<$P$45,AA28>$P$46),"FUERA DE LÍMITES; ",""),""))=0,"OK",IF(B28="","SIN FECHA; ",IF(DATOS!$C$12-B28>DATOS!$C$18*30.4,"VENCIDA; ",""))&IF(X28="","SIN ENLACE; ","")&IF(H28="","SIN COORDENADAS; ","")&IF(L28="","SIN ÁREA; ","")&IF(AND(ISNUMBER(AA28),ISNUMBER($P$45),ISNUMBER($P$46),N($P$44)>DATOS!$C$16),IF(OR(AA28<$P$45,AA28>$P$46),"FUERA DE LÍMITES; ",""),""))) | AC28: =IF(AA28="","",IF(COMBINACIONES_NPH!$B$18="MUESTRA COMPLETA","SÍ",IF(AUX_NPH!F24="","NO (filtrada)",IF(AND(AUX_NPH!F24>=COMBINACIONES_NPH!$B$22,AUX_NPH!F24<=COMBINACIONES_NPH!$B$22+COMBINACIONES_NPH!$B$23-1),"SÍ","NO")))) | AD28: =IF(A28="","","OFERTA NPH "&TEXT(A28,"00"))
K29: =IF(I29="","",I29*(1-J29)) | N29: =IF(A29="","",SUMIFS(DEPRECIACIÓN!$P$5:$P$24,DEPRECIACIÓN!$A$5:$A$24,A29)) | O29: =IF(K29="","",K29-N(N29)) | P29: =IF(OR(O29="",N(L29)<=0),"",O29/L29) | Q29: =IF(OR(K29="",N(L29)<=0),"",K29/L29) | R29: =IF(OR(K29="",N(M29)<=0),"",K29/M29) | AA29: =IF(AND(Z29="SÍ",ISNUMBER(R29)),R29,"") | AB29: =IF(A29="","",IF(LEN(IF(B29="","SIN FECHA; ",IF(DATOS!$C$12-B29>DATOS!$C$18*30.4,"VENCIDA; ",""))&IF(X29="","SIN ENLACE; ","")&IF(H29="","SIN COORDENADAS; ","")&IF(L29="","SIN ÁREA; ","")&IF(AND(ISNUMBER(AA29),ISNUMBER($P$45),ISNUMBER($P$46),N($P$44)>DATOS!$C$16),IF(OR(AA29<$P$45,AA29>$P$46),"FUERA DE LÍMITES; ",""),""))=0,"OK",IF(B29="","SIN FECHA; ",IF(DATOS!$C$12-B29>DATOS!$C$18*30.4,"VENCIDA; ",""))&IF(X29="","SIN ENLACE; ","")&IF(H29="","SIN COORDENADAS; ","")&IF(L29="","SIN ÁREA; ","")&IF(AND(ISNUMBER(AA29),ISNUMBER($P$45),ISNUMBER($P$46),N($P$44)>DATOS!$C$16),IF(OR(AA29<$P$45,AA29>$P$46),"FUERA DE LÍMITES; ",""),""))) | AC29: =IF(AA29="","",IF(COMBINACIONES_NPH!$B$18="MUESTRA COMPLETA","SÍ",IF(AUX_NPH!F25="","NO (filtrada)",IF(AND(AUX_NPH!F25>=COMBINACIONES_NPH!$B$22,AUX_NPH!F25<=COMBINACIONES_NPH!$B$22+COMBINACIONES_NPH!$B$23-1),"SÍ","NO")))) | AD29: =IF(A29="","","OFERTA NPH "&TEXT(A29,"00"))
K30: =IF(I30="","",I30*(1-J30)) | N30: =IF(A30="","",SUMIFS(DEPRECIACIÓN!$P$5:$P$24,DEPRECIACIÓN!$A$5:$A$24,A30)) | O30: =IF(K30="","",K30-N(N30)) | P30: =IF(OR(O30="",N(L30)<=0),"",O30/L30) | Q30: =IF(OR(K30="",N(L30)<=0),"",K30/L30) | R30: =IF(OR(K30="",N(M30)<=0),"",K30/M30) | AA30: =IF(AND(Z30="SÍ",ISNUMBER(R30)),R30,"") | AB30: =IF(A30="","",IF(LEN(IF(B30="","SIN FECHA; ",IF(DATOS!$C$12-B30>DATOS!$C$18*30.4,"VENCIDA; ",""))&IF(X30="","SIN ENLACE; ","")&IF(H30="","SIN COORDENADAS; ","")&IF(L30="","SIN ÁREA; ","")&IF(AND(ISNUMBER(AA30),ISNUMBER($P$45),ISNUMBER($P$46),N($P$44)>DATOS!$C$16),IF(OR(AA30<$P$45,AA30>$P$46),"FUERA DE LÍMITES; ",""),""))=0,"OK",IF(B30="","SIN FECHA; ",IF(DATOS!$C$12-B30>DATOS!$C$18*30.4,"VENCIDA; ",""))&IF(X30="","SIN ENLACE; ","")&IF(H30="","SIN COORDENADAS; ","")&IF(L30="","SIN ÁREA; ","")&IF(AND(ISNUMBER(AA30),ISNUMBER($P$45),ISNUMBER($P$46),N($P$44)>DATOS!$C$16),IF(OR(AA30<$P$45,AA30>$P$46),"FUERA DE LÍMITES; ",""),""))) | AC30: =IF(AA30="","",IF(COMBINACIONES_NPH!$B$18="MUESTRA COMPLETA","SÍ",IF(AUX_NPH!F26="","NO (filtrada)",IF(AND(AUX_NPH!F26>=COMBINACIONES_NPH!$B$22,AUX_NPH!F26<=COMBINACIONES_NPH!$B$22+COMBINACIONES_NPH!$B$23-1),"SÍ","NO")))) | AD30: =IF(A30="","","OFERTA NPH "&TEXT(A30,"00"))
K31: =IF(I31="","",I31*(1-J31)) | N31: =IF(A31="","",SUMIFS(DEPRECIACIÓN!$P$5:$P$24,DEPRECIACIÓN!$A$5:$A$24,A31)) | O31: =IF(K31="","",K31-N(N31)) | P31: =IF(OR(O31="",N(L31)<=0),"",O31/L31) | Q31: =IF(OR(K31="",N(L31)<=0),"",K31/L31) | R31: =IF(OR(K31="",N(M31)<=0),"",K31/M31) | AA31: =IF(AND(Z31="SÍ",ISNUMBER(R31)),R31,"") | AB31: =IF(A31="","",IF(LEN(IF(B31="","SIN FECHA; ",IF(DATOS!$C$12-B31>DATOS!$C$18*30.4,"VENCIDA; ",""))&IF(X31="","SIN ENLACE; ","")&IF(H31="","SIN COORDENADAS; ","")&IF(L31="","SIN ÁREA; ","")&IF(AND(ISNUMBER(AA31),ISNUMBER($P$45),ISNUMBER($P$46),N($P$44)>DATOS!$C$16),IF(OR(AA31<$P$45,AA31>$P$46),"FUERA DE LÍMITES; ",""),""))=0,"OK",IF(B31="","SIN FECHA; ",IF(DATOS!$C$12-B31>DATOS!$C$18*30.4,"VENCIDA; ",""))&IF(X31="","SIN ENLACE; ","")&IF(H31="","SIN COORDENADAS; ","")&IF(L31="","SIN ÁREA; ","")&IF(AND(ISNUMBER(AA31),ISNUMBER($P$45),ISNUMBER($P$46),N($P$44)>DATOS!$C$16),IF(OR(AA31<$P$45,AA31>$P$46),"FUERA DE LÍMITES; ",""),""))) | AC31: =IF(AA31="","",IF(COMBINACIONES_NPH!$B$18="MUESTRA COMPLETA","SÍ",IF(AUX_NPH!F27="","NO (filtrada)",IF(AND(AUX_NPH!F27>=COMBINACIONES_NPH!$B$22,AUX_NPH!F27<=COMBINACIONES_NPH!$B$22+COMBINACIONES_NPH!$B$23-1),"SÍ","NO")))) | AD31: =IF(A31="","","OFERTA NPH "&TEXT(A31,"00"))
K32: =IF(I32="","",I32*(1-J32)) | N32: =IF(A32="","",SUMIFS(DEPRECIACIÓN!$P$5:$P$24,DEPRECIACIÓN!$A$5:$A$24,A32)) | O32: =IF(K32="","",K32-N(N32)) | P32: =IF(OR(O32="",N(L32)<=0),"",O32/L32) | Q32: =IF(OR(K32="",N(L32)<=0),"",K32/L32) | R32: =IF(OR(K32="",N(M32)<=0),"",K32/M32) | AA32: =IF(AND(Z32="SÍ",ISNUMBER(R32)),R32,"") | AB32: =IF(A32="","",IF(LEN(IF(B32="","SIN FECHA; ",IF(DATOS!$C$12-B32>DATOS!$C$18*30.4,"VENCIDA; ",""))&IF(X32="","SIN ENLACE; ","")&IF(H32="","SIN COORDENADAS; ","")&IF(L32="","SIN ÁREA; ","")&IF(AND(ISNUMBER(AA32),ISNUMBER($P$45),ISNUMBER($P$46),N($P$44)>DATOS!$C$16),IF(OR(AA32<$P$45,AA32>$P$46),"FUERA DE LÍMITES; ",""),""))=0,"OK",IF(B32="","SIN FECHA; ",IF(DATOS!$C$12-B32>DATOS!$C$18*30.4,"VENCIDA; ",""))&IF(X32="","SIN ENLACE; ","")&IF(H32="","SIN COORDENADAS; ","")&IF(L32="","SIN ÁREA; ","")&IF(AND(ISNUMBER(AA32),ISNUMBER($P$45),ISNUMBER($P$46),N($P$44)>DATOS!$C$16),IF(OR(AA32<$P$45,AA32>$P$46),"FUERA DE LÍMITES; ",""),""))) | AC32: =IF(AA32="","",IF(COMBINACIONES_NPH!$B$18="MUESTRA COMPLETA","SÍ",IF(AUX_NPH!F28="","NO (filtrada)",IF(AND(AUX_NPH!F28>=COMBINACIONES_NPH!$B$22,AUX_NPH!F28<=COMBINACIONES_NPH!$B$22+COMBINACIONES_NPH!$B$23-1),"SÍ","NO")))) | AD32: =IF(A32="","","OFERTA NPH "&TEXT(A32,"00"))
K33: =IF(I33="","",I33*(1-J33)) | N33: =IF(A33="","",SUMIFS(DEPRECIACIÓN!$P$5:$P$24,DEPRECIACIÓN!$A$5:$A$24,A33)) | O33: =IF(K33="","",K33-N(N33)) | P33: =IF(OR(O33="",N(L33)<=0),"",O33/L33) | Q33: =IF(OR(K33="",N(L33)<=0),"",K33/L33) | R33: =IF(OR(K33="",N(M33)<=0),"",K33/M33) | AA33: =IF(AND(Z33="SÍ",ISNUMBER(R33)),R33,"") | AB33: =IF(A33="","",IF(LEN(IF(B33="","SIN FECHA; ",IF(DATOS!$C$12-B33>DATOS!$C$18*30.4,"VENCIDA; ",""))&IF(X33="","SIN ENLACE; ","")&IF(H33="","SIN COORDENADAS; ","")&IF(L33="","SIN ÁREA; ","")&IF(AND(ISNUMBER(AA33),ISNUMBER($P$45),ISNUMBER($P$46),N($P$44)>DATOS!$C$16),IF(OR(AA33<$P$45,AA33>$P$46),"FUERA DE LÍMITES; ",""),""))=0,"OK",IF(B33="","SIN FECHA; ",IF(DATOS!$C$12-B33>DATOS!$C$18*30.4,"VENCIDA; ",""))&IF(X33="","SIN ENLACE; ","")&IF(H33="","SIN COORDENADAS; ","")&IF(L33="","SIN ÁREA; ","")&IF(AND(ISNUMBER(AA33),ISNUMBER($P$45),ISNUMBER($P$46),N($P$44)>DATOS!$C$16),IF(OR(AA33<$P$45,AA33>$P$46),"FUERA DE LÍMITES; ",""),""))) | AC33: =IF(AA33="","",IF(COMBINACIONES_NPH!$B$18="MUESTRA COMPLETA","SÍ",IF(AUX_NPH!F29="","NO (filtrada)",IF(AND(AUX_NPH!F29>=COMBINACIONES_NPH!$B$22,AUX_NPH!F29<=COMBINACIONES_NPH!$B$22+COMBINACIONES_NPH!$B$23-1),"SÍ","NO")))) | AD33: =IF(A33="","","OFERTA NPH "&TEXT(A33,"00"))
K34: =IF(I34="","",I34*(1-J34)) | N34: =IF(A34="","",SUMIFS(DEPRECIACIÓN!$P$5:$P$24,DEPRECIACIÓN!$A$5:$A$24,A34)) | O34: =IF(K34="","",K34-N(N34)) | P34: =IF(OR(O34="",N(L34)<=0),"",O34/L34) | Q34: =IF(OR(K34="",N(L34)<=0),"",K34/L34) | R34: =IF(OR(K34="",N(M34)<=0),"",K34/M34) | AA34: =IF(AND(Z34="SÍ",ISNUMBER(R34)),R34,"") | AB34: =IF(A34="","",IF(LEN(IF(B34="","SIN FECHA; ",IF(DATOS!$C$12-B34>DATOS!$C$18*30.4,"VENCIDA; ",""))&IF(X34="","SIN ENLACE; ","")&IF(H34="","SIN COORDENADAS; ","")&IF(L34="","SIN ÁREA; ","")&IF(AND(ISNUMBER(AA34),ISNUMBER($P$45),ISNUMBER($P$46),N($P$44)>DATOS!$C$16),IF(OR(AA34<$P$45,AA34>$P$46),"FUERA DE LÍMITES; ",""),""))=0,"OK",IF(B34="","SIN FECHA; ",IF(DATOS!$C$12-B34>DATOS!$C$18*30.4,"VENCIDA; ",""))&IF(X34="","SIN ENLACE; ","")&IF(H34="","SIN COORDENADAS; ","")&IF(L34="","SIN ÁREA; ","")&IF(AND(ISNUMBER(AA34),ISNUMBER($P$45),ISNUMBER($P$46),N($P$44)>DATOS!$C$16),IF(OR(AA34<$P$45,AA34>$P$46),"FUERA DE LÍMITES; ",""),""))) | AC34: =IF(AA34="","",IF(COMBINACIONES_NPH!$B$18="MUESTRA COMPLETA","SÍ",IF(AUX_NPH!F30="","NO (filtrada)",IF(AND(AUX_NPH!F30>=COMBINACIONES_NPH!$B$22,AUX_NPH!F30<=COMBINACIONES_NPH!$B$22+COMBINACIONES_NPH!$B$23-1),"SÍ","NO")))) | AD34: =IF(A34="","","OFERTA NPH "&TEXT(A34,"00"))
... K38: =IF(I38="","",I38*(1-J38)) | N38: =IF(A38="","",SUMIFS(DEPRECIACIÓN!$P$5:$P$24,DEPRECIACIÓN!$A$5:$A$24,A38)) | O38: =IF(K38="","",K38-N(N38)) | P38: =IF(OR(O38="",N(L38)<=0),"",O38/L38) | Q38: =IF(OR(K38="",N(L38)<=0),"",K38/L38) | R38: =IF(OR(K38="",N(M38)<=0),"",K38/M38) | AA38: =IF(AND(Z38="SÍ",ISNUMBER(R38)),R38,"") | AB38: =IF(A38="","",IF(LEN(IF(B38="","SIN FECHA; ",IF(DATOS!$C$12-B38>DATOS!$C$18*30.4,"VENCIDA; ",""))&IF(X38="","SIN ENLACE; ","")&IF(H38="","SIN COORDENADAS; ","")&IF(L38="","SIN ÁREA; ","")&IF(AND(ISNUMBER(AA38),ISNUMBER($P$45),ISNUMBER($P$46),N($P$44)>DATOS!$C$16),IF(OR(AA38<$P$45,AA38>$P$46),"FUERA DE LÍMITES; ",""),""))=0,"OK",IF(B38="","SIN FECHA; ",IF(DATOS!$C$12-B38>DATOS!$C$18*30.4,"VENCIDA; ",""))&IF(X38="","SIN ENLACE; ","")&IF(H38="","SIN COORDENADAS; ","")&IF(L38="","SIN ÁREA; ","")&IF(AND(ISNUMBER(AA38),ISNUMBER($P$45),ISNUMBER($P$46),N($P$44)>DATOS!$C$16),IF(OR(AA38<$P$45,AA38>$P$46),"FUERA DE LÍMITES; ",""),""))) | AC38: =IF(AA38="","",IF(COMBINACIONES_NPH!$B$18="MUESTRA COMPLETA","SÍ",IF(AUX_NPH!F34="","NO (filtrada)",IF(AND(AUX_NPH!F34>=COMBINACIONES_NPH!$B$22,AUX_NPH!F34<=COMBINACIONES_NPH!$B$22+COMBINACIONES_NPH!$B$23-1),"SÍ","NO")))) | AD38: =IF(A38="","","OFERTA NPH "&TEXT(A38,"00"))
L40: Nº DE OFERTAS INCLUIDAS | P40: =COUNT($AA$9:$AA$38)
L41: PROMEDIO (media aritmética) | P41: =IFERROR(AVERAGE($AA$9:$AA$38),"")
L42: MEDIANA | P42: =IFERROR(MEDIAN($AA$9:$AA$38),"")
L43: DESVIACIÓN ESTÁNDAR | P43: =IFERROR(_xlfn.STDEV.S($AA$9:$AA$38),"")
L44: COEFICIENTE DE VARIACIÓN | P44: =IFERROR(P43/P41,"")
L45: LÍMITE INFERIOR (promedio − desv.) | P45: =IFERROR(P41-P43,"")
...

Sheet MERCADO CASAS 1-2-3
A1: ESTUDIO DE MERCADO – CASAS URBANAS EN BELLO (NIQUÍA) – COMBINACIÓN DE LAS OFERTAS 1, 2 Y 3 (CV ≤ 7,5 %) Res. IGAC 941 de 2026 – Art. 17, 19 y 21 · Área máxima por oferta: 100 m² · Valor integral $/m² construido
A3: SOLICITANTE | D3: =DATOS!C4
A4: INMUEBLE OBJETO | D4: =DATOS!C6
A5: MUNICIPIO – BARRIO | D5: =DATOS!C7&" – "&DATOS!C8
A6: % NEGOCIACIÓN POR DEFECTO | D6: =DATOS!$C$17
A8: No. | B8: FECHA DE CAPTURA | C8: TIPO DE INMUEBLE (CASA) | D8: TIPO DE DATO | E8: MUNICIPIO | F8: COMUNA / BARRIO / SECTOR | G8: DIRECCIÓN O REFERENCIA | H8: COORDENADAS (lat, lon) | I8: VALOR PEDIDO | J8: % NEG. | K8: VALOR NEGOCIADO | L8: ÁREA DE TERRENO (m²) – SI SE PUBLICA | M8: ÁREA CONSTRUIDA (m²) – MÁX. 100 | N8: VALOR INTEGRAL $/m² CONSTRUIDO | O8: NORMA URBANÍSTICA (POT / tratamiento / uso) | P8: ESTRATO | Q8: OBSERVACIONES / DESCRIPCIÓN | R8: FUENTE (nombre) | S8: TELÉFONO | T8: ENLACE (URL) | U8: COMPARABILIDAD | V8: ¿INCLUIR? (SÍ/NO) | W8: VALOR PARA ESTADÍSTICA ($/m² CONSTRUIDO) | X8: DIFERENCIA FRENTE AL PROMEDIO | Y8: ¿DENTRO DE PROMEDIO ± DESV.? (informativo) | Z8: SOPORTE (captura)
A9: ='OFERTAS CASA-APTO BELLO'!A5 | B9: ='OFERTAS CASA-APTO BELLO'!B5 | C9: ='OFERTAS CASA-APTO BELLO'!C5 | D9: Oferta de venta | E9: ='OFERTAS CASA-APTO BELLO'!E5 | F9: ='OFERTAS CASA-APTO BELLO'!F5 | G9: ='OFERTAS CASA-APTO BELLO'!G5 | I9: ='OFERTAS CASA-APTO BELLO'!H5 | J9: ='OFERTAS CASA-APTO BELLO'!I5 | K9: =IF(I9="","",I9*(1-J9)) | L9: =IF('OFERTAS CASA-APTO BELLO'!L5="","",'OFERTAS CASA-APTO BELLO'!L5) | M9: ='OFERTAS CASA-APTO BELLO'!K5 | N9: =IF(OR(K9="",N(M9)<=0),"",K9/M9) | O9: Por verificar en POT de Bello (Acuerdo vigente) | P9: =IF('OFERTAS CASA-APTO BELLO'!N5="","",'OFERTAS CASA-APTO BELLO'!N5) | Q9: ='OFERTAS CASA-APTO BELLO'!O5 | R9: ='OFERTAS CASA-APTO BELLO'!P5 | S9: Solicitar en portal | T9: https://www.fincaraiz.com.co/venta/altos-de-niquia/bello | U9: ='OFERTAS CASA-APTO BELLO'!R5 | V9: SÍ | W9: =IF(AND(V9="SÍ",ISNUMBER(N9)),N9,"") | X9: =IF(W9="","",W9/$H$15-1) | Y9: =IF(W9="","",IF(AND(W9>=$H$25,W9<=$H$26),"SÍ","NO")) | Z9: ="OFERTA CASA "&TEXT(A9,"00")
A10: ='OFERTAS CASA-APTO BELLO'!A6 | B10: ='OFERTAS CASA-APTO BELLO'!B6 | C10: ='OFERTAS CASA-APTO BELLO'!C6 | D10: Oferta de venta | E10: ='OFERTAS CASA-APTO BELLO'!E6 | F10: ='OFERTAS CASA-APTO BELLO'!F6 | G10: ='OFERTAS CASA-APTO BELLO'!G6 | I10: ='OFERTAS CASA-APTO BELLO'!H6 | J10: ='OFERTAS CASA-APTO BELLO'!I6 | K10: =IF(I10="","",I10*(1-J10)) | L10: =IF('OFERTAS CASA-APTO BELLO'!L6="","",'OFERTAS CASA-APTO BELLO'!L6) | M10: ='OFERTAS CASA-APTO BELLO'!K6 | N10: =IF(OR(K10="",N(M10)<=0),"",K10/M10) | O10: Por verificar en POT de Bello (Acuerdo vigente) | P10: =IF('OFERTAS CASA-APTO BELLO'!N6="","",'OFERTAS CASA-APTO BELLO'!N6) | Q10: ='OFERTAS CASA-APTO BELLO'!O6 | R10: ='OFERTAS CASA-APTO BELLO'!P6 | S10: Solicitar en portal | T10: https://www.fincaraiz.com.co/venta/altos-de-niquia/bello | U10: ='OFERTAS CASA-APTO BELLO'!R6 | V10: SÍ | W10: =IF(AND(V10="SÍ",ISNUMBER(N10)),N10,"") | X10: =IF(W10="","",W10/$H$15-1) | Y10: =IF(W10="","",IF(AND(W10>=$H$25,W10<=$H$26),"SÍ","NO")) | Z10: ="OFERTA CASA "&TEXT(A10,"00")
A11: ='OFERTAS CASA-APTO BELLO'!A7 | B11: ='OFERTAS CASA-APTO BELLO'!B7 | C11: ='OFERTAS CASA-APTO BELLO'!C7 | D11: Oferta de venta | E11: ='OFERTAS CASA-APTO BELLO'!E7 | F11: ='OFERTAS CASA-APTO BELLO'!F7 | G11: ='OFERTAS CASA-APTO BELLO'!G7 | I11: ='OFERTAS CASA-APTO BELLO'!H7 | J11: ='OFERTAS CASA-APTO BELLO'!I7 | K11: =IF(I11="","",I11*(1-J11)) | L11: =IF('OFERTAS CASA-APTO BELLO'!L7="","",'OFERTAS CASA-APTO BELLO'!L7) | M11: ='OFERTAS CASA-APTO BELLO'!K7 | N11: =IF(OR(K11="",N(M11)<=0),"",K11/M11) | O11: Por verificar en POT de Bello (Acuerdo vigente) | P11: =IF('OFERTAS CASA-APTO BELLO'!N7="","",'OFERTAS CASA-APTO BELLO'!N7) | Q11: ='OFERTAS CASA-APTO BELLO'!O7 | R11: ='OFERTAS CASA-APTO BELLO'!P7 | S11: Solicitar en portal | T11: https://www.fincaraiz.com.co/venta/casas/niquia/bello | U11: ='OFERTAS CASA-APTO BELLO'!R7 | V11: SÍ | W11: =IF(AND(V11="SÍ",ISNUMBER(N11)),N11,"") | X11: =IF(W11="","",W11/$H$15-1) | Y11: =IF(W11="","",IF(AND(W11>=$H$25,W11<=$H$26),"SÍ","NO")) | Z11: ="OFERTA CASA "&TEXT(A11,"00")
A13: ESTADÍSTICOS DE LA MUESTRA – VALOR INTEGRAL $/m² CONSTRUIDO (Res. 941, Art. 21) | G13: ESTADÍSTICO | H13: VALOR
G14: Nº DE OFERTAS INCLUIDAS | H14: =COUNT($W$9:$W$11)
G15: PROMEDIO (media aritmética) | H15: =IFERROR(AVERAGE($W$9:$W$11),"")
G16: MEDIANA | H16: =IFERROR(MEDIAN($W$9:$W$11),"")
G17: DESVIACIÓN ESTÁNDAR (muestral) | H17: =IFERROR(_xlfn.STDEV.S($W$9:$W$11),"")
G18: VARIANZA (muestral) | H18: =IFERROR(_xlfn.VAR.S($W$9:$W$11),"")
G19: COEFICIENTE DE VARIACIÓN | H19: =IFERROR(H17/H15,"")
G20: VALOR MÍNIMO | H20: =IF(H14=0,"",MIN($W$9:$W$11))
G21: VALOR MÁXIMO | H21: =IF(H14=0,"",MAX($W$9:$W$11))
G22: RANGO (máximo − mínimo) | H22: =IFERROR(H21-H20,"")
G23: ERROR ESTÁNDAR DE LA MEDIA | H23: =IFERROR(H17/SQRT(H14),"")
G24: COEFICIENTE DE ASIMETRÍA | H24: =IFERROR(SKEW($W$9:$W$11),"")
G25: LÍMITE INFERIOR (promedio − desv.) | H25: =IFERROR(H15-H17,"")
G26: LÍMITE SUPERIOR (promedio + desv.) | H26: =IFERROR(H15+H17,"")
G27: CV MÁXIMO ADMISIBLE (DATOS, urbano) | H27: =DATOS!$C$16
G28: ¿CV ≤ MÁXIMO? | H28: =IF(ISNUMBER(H19),IF(H19<=H27,"SÍ","NO"),"")
G29: MÍNIMO DE OFERTAS (DATOS) | H29: =DATOS!$C$19
G30: ¿CUMPLE EL MÍNIMO DE OFERTAS? | H30: =IF(H14>=H29,"SÍ","NO")
G31: VALOR ADOPTADO $/m² (promedio redondeado a 100) | H31: =IF(AND(H30="SÍ",H28="SÍ"),ROUND(H15,-2),"NO CUMPLE")
G32: DICTAMEN | H32: =IF(H14<H29,"Sin datos suficientes: se requieren al menos "&H29&" ofertas.",IF(H19<=H27,"CUMPLE: el valor de $ "&FIXED(H31,0)&" /m² se soporta en "&H14&" ofertas con CV de "&ROUND(H19*100,2)&" % (máximo "&ROUND(H27*100,2)&" %, Res. 941 Art. 21).","NO CUMPLE: el CV de "&ROUND(H19*100,2)&" % supera el máximo de "&ROUND(H27*100,2)&" %."))

Sheet COMBINACIONES BELLO
A1: COMBINACIONES DE OFERTAS – CASA Y APARTAMENTO EN BELLO – VALOR INTEGRAL $/m² CONSTRUIDO
A2: Todas las combinaciones posibles de mínimo 3 ofertas (sin descartar ninguna oferta) cuyo coeficiente de variación queda dentro del máximo admisible. Cada fila marca con 1 las ofertas que la componen; los estadísticos son fórmulas sobre la hoja OFERTAS CASA-APTO BELLO.
G3: RESUMEN | H3: CASAS | I3: APARTAMENTOS | J3: TODAS
A4: CV máximo admisible (DATOS, urbano) | D4: =DATOS!$C$16 | G4: Nº de combinaciones | H4: =COUNTIF($A$9:$A$165,"Casas") | I4: =COUNTIF($A$9:$A$165,"Apartamentos") | J4: =COUNTIF($A$9:$A$165,"Todas")
A5: Mínimo de ofertas por combinación (DATOS) | D5: =DATOS!$C$19 | G5: Máx. de ofertas | H5: =_xlfn.MAXIFS($C$9:$C$165,$A$9:$A$165,"Casas") | I5: =_xlfn.MAXIFS($C$9:$C$165,$A$9:$A$165,"Apartamentos") | J5: =_xlfn.MAXIFS($C$9:$C$165,$A$9:$A$165,"Todas")
G6: Menor CV | H6: =_xlfn.MINIFS($K$9:$K$165,$A$9:$A$165,"Casas") | I6: =_xlfn.MINIFS($K$9:$K$165,$A$9:$A$165,"Apartamentos") | J6: =_xlfn.MINIFS($K$9:$K$165,$A$9:$A$165,"Todas") | N6: Nº de oferta → | O6: ='OFERTAS CASA-APTO BELLO'!A5 | P6: ='OFERTAS CASA-APTO BELLO'!A6 | Q6: ='OFERTAS CASA-APTO BELLO'!A7 | R6: ='OFERTAS CASA-APTO BELLO'!A8 | S6: ='OFERTAS CASA-APTO BELLO'!A9 | T6: ='OFERTAS CASA-APTO BELLO'!A10 | U6: ='OFERTAS CASA-APTO BELLO'!A11 | V6: ='OFERTAS CASA-APTO BELLO'!A12 | W6: ='OFERTAS CASA-APTO BELLO'!A13 | X6: ='OFERTAS CASA-APTO BELLO'!A14 | Y6: ='OFERTAS CASA-APTO BELLO'!A15 | Z6: ='OFERTAS CASA-APTO BELLO'!A16 | AA6: ='OFERTAS CASA-APTO BELLO'!A17 | AB6: ='OFERTAS CASA-APTO BELLO'!A18
N7: $/m² construido → | O7: ='OFERTAS CASA-APTO BELLO'!M5 | P7: ='OFERTAS CASA-APTO BELLO'!M6 | Q7: ='OFERTAS CASA-APTO BELLO'!M7 | R7: ='OFERTAS CASA-APTO BELLO'!M8 | S7: ='OFERTAS CASA-APTO BELLO'!M9 | T7: ='OFERTAS CASA-APTO BELLO'!M10 | U7: ='OFERTAS CASA-APTO BELLO'!M11 | V7: ='OFERTAS CASA-APTO BELLO'!M12 | W7: ='OFERTAS CASA-APTO BELLO'!M13 | X7: ='OFERTAS CASA-APTO BELLO'!M14 | Y7: ='OFERTAS CASA-APTO BELLO'!M15 | Z7: ='OFERTAS CASA-APTO BELLO'!M16 | AA7: ='OFERTAS CASA-APTO BELLO'!M17 | AB7: ='OFERTAS CASA-APTO BELLO'!M18
A8: GRUPO | B8: Nº COMBINACIÓN | C8: Nº DE OFERTAS | D8: OFERTAS UTILIZADAS (No.) | E8: COMPOSICIÓN | F8: VALOR MÍNIMO $/m² | G8: VALOR MÁXIMO $/m² | H8: PROMEDIO $/m² | I8: MEDIANA $/m² | J8: DESVIACIÓN ESTÁNDAR | K8: COEF. DE VARIACIÓN | L8: LÍMITE INFERIOR | M8: LÍMITE SUPERIOR | N8: ¿CV ≤ MÁXIMO? | O8: Of. 1 | P8: Of. 2 | Q8: Of. 3 | R8: Of. 4 | S8: Of. 5 | T8: Of. 6 | U8: Of. 7 | V8: Of. 8 | W8: Of. 9 | X8: Of. 10 | Y8: Of. 11 | Z8: Of. 12 | AA8: Of. 13 | AB8: Of. 14
A9: Casas | B9: 1 | C9: =SUM($O9:$AB9) | D9: =SUBSTITUTE(TRIM(IF(O9=1,O$6&" ","")&IF(P9=1,P$6&" ","")&IF(Q9=1,Q$6&" ","")&IF(R9=1,R$6&" ","")&IF(S9=1,S$6&" ","")&IF(T9=1,T$6&" ","")&IF(U9=1,U$6&" ","")&IF(V9=1,V$6&" ","")&IF(W9=1,W$6&" ","")&IF(X9=1,X$6&" ","")&IF(Y9=1,Y$6&" ","")&IF(Z9=1,Z$6&" ","")&IF(AA9=1,AA$6&" ","")&IF(AB9=1,AB$6&" ",""))," ",", ") | E9: =IF(SUMPRODUCT($O9:$AB9*($O$6:$AB$6<=6))=$C9,"Solo casas",IF(SUMPRODUCT($O9:$AB9*($O$6:$AB$6>6))=$C9,"Solo apartamentos","Mixta ("&SUMPRODUCT($O9:$AB9*($O$6:$AB$6<=6))&" casas + "&SUMPRODUCT($O9:$AB9*($O$6:$AB$6>6))&" aptos)")) | F9: =_xlfn.MINIFS($O$7:$AB$7,$O9:$AB9,1) | G9: =_xlfn.MAXIFS($O$7:$AB$7,$O9:$AB9,1) | H9: =SUMPRODUCT($O9:$AB9,$O$7:$AB$7)/C9 | I9: =_xlfn.AGGREGATE(16,6,$O$7:$AB$7/($O9:$AB9=1),0.5) | J9: =SQRT((SUMPRODUCT($O9:$AB9,$O$7:$AB$7^2)-C9*H9^2)/(C9-1)) | K9: =J9/H9 | L9: =H9-J9 | M9: =H9+J9 | N9: =IF(K9<=$D$4,"SÍ","NO") | O9: 1 | P9: 1 | Q9: 1 | R9: 0 | S9: 0 | T9: 0 | U9: 0 | V9: 0 | W9: 0 | X9: 0 | Y9: 0 | Z9: 0 | AA9: 0 | AB9: 0
A10: Apartamentos | B10: 1 | C10: =SUM($O10:$AB10) | D10: =SUBSTITUTE(TRIM(IF(O10=1,O$6&" ","")&IF(P10=1,P$6&" ","")&IF(Q10=1,Q$6&" ","")&IF(R10=1,R$6&" ","")&IF(S10=1,S$6&" ","")&IF(T10=1,T$6&" ","")&IF(U10=1,U$6&" ","")&IF(V10=1,V$6&" ","")&IF(W10=1,W$6&" ","")&IF(X10=1,X$6&" ","")&IF(Y10=1,Y$6&" ","")&IF(Z10=1,Z$6&" ","")&IF(AA10=1,AA$6&" ","")&IF(AB10=1,AB$6&" ",""))," ",", ") | E10: =IF(SUMPRODUCT($O10:$AB10*($O$6:$AB$6<=6))=$C10,"Solo casas",IF(SUMPRODUCT($O10:$AB10*($O$6:$AB$6>6))=$C10,"Solo apartamentos","Mixta ("&SUMPRODUCT($O10:$AB10*($O$6:$AB$6<=6))&" casas + "&SUMPRODUCT($O10:$AB10*($O$6:$AB$6>6))&" aptos)")) | F10: =_xlfn.MINIFS($O$7:$AB$7,$O10:$AB10,1) | G10: =_xlfn.MAXIFS($O$7:$AB$7,$O10:$AB10,1) | H10: =SUMPRODUCT($O10:$AB10,$O$7:$AB$7)/C10 | I10: =_xlfn.AGGREGATE(16,6,$O$7:$AB$7/($O10:$AB10=1),0.5) | J10: =SQRT((SUMPRODUCT($O10:$AB10,$O$7:$AB$7^2)-C10*H10^2)/(C10-1)) | K10: =J10/H10 | L10: =H10-J10 | M10: =H10+J10 | N10: =IF(K10<=$D$4,"SÍ","NO") | O10: 0 | P10: 0 | Q10: 0 | R10: 0 | S10: 0 | T10: 0 | U10: 1 | V10: 1 | W10: 1 | X10: 0 | Y10: 1 | Z10: 1 | AA10: 0 | AB10: 0
A11: Apartamentos | B11: 2 | C11: =SUM($O11:$AB11) | D11: =SUBSTITUTE(TRIM(IF(O11=1,O$6&" ","")&IF(P11=1,P$6&" ","")&IF(Q11=1,Q$6&" ","")&IF(R11=1,R$6&" ","")&IF(S11=1,S$6&" ","")&IF(T11=1,T$6&" ","")&IF(U11=1,U$6&" ","")&IF(V11=1,V$6&" ","")&IF(W11=1,W$6&" ","")&IF(X11=1,X$6&" ","")&IF(Y11=1,Y$6&" ","")&IF(Z11=1,Z$6&" ","")&IF(AA11=1,AA$6&" ","")&IF(AB11=1,AB$6&" ",""))," ",", ") | E11: =IF(SUMPRODUCT($O11:$AB11*($O$6:$AB$6<=6))=$C11,"Solo casas",IF(SUMPRODUCT($O11:$AB11*($O$6:$AB$6>6))=$C11,"Solo apartamentos","Mixta ("&SUMPRODUCT($O11:$AB11*($O$6:$AB$6<=6))&" casas + "&SUMPRODUCT($O11:$AB11*($O$6:$AB$6>6))&" aptos)")) | F11: =_xlfn.MINIFS($O$7:$AB$7,$O11:$AB11,1) | G11: =_xlfn.MAXIFS($O$7:$AB$7,$O11:$AB11,1) | H11: =SUMPRODUCT($O11:$AB11,$O$7:$AB$7)/C11 | I11: =_xlfn.AGGREGATE(16,6,$O$7:$AB$7/($O11:$AB11=1),0.5) | J11: =SQRT((SUMPRODUCT($O11:$AB11,$O$7:$AB$7^2)-C11*H11^2)/(C11-1)) | K11: =J11/H11 | L11: =H11-J11 | M11: =H11+J11 | N11: =IF(K11<=$D$4,"SÍ","NO") | O11: 0 | P11: 0 | Q11: 0 | R11: 0 | S11: 0 | T11: 0 | U11: 1 | V11: 1 | W11: 1 | X11: 0 | Y11: 1 | Z11: 0 | AA11: 0 | AB11: 1
A12: Apartamentos | B12: 3 | C12: =SUM($O12:$AB12) | D12: =SUBSTITUTE(TRIM(IF(O12=1,O$6&" ","")&IF(P12=1,P$6&" ","")&IF(Q12=1,Q$6&" ","")&IF(R12=1,R$6&" ","")&IF(S12=1,S$6&" ","")&IF(T12=1,T$6&" ","")&IF(U12=1,U$6&" ","")&IF(V12=1,V$6&" ","")&IF(W12=1,W$6&" ","")&IF(X12=1,X$6&" ","")&IF(Y12=1,Y$6&" ","")&IF(Z12=1,Z$6&" ","")&IF(AA12=1,AA$6&" ","")&IF(AB12=1,AB$6&" ",""))," ",", ") | E12: =IF(SUMPRODUCT($O12:$AB12*($O$6:$AB$6<=6))=$C12,"Solo casas",IF(SUMPRODUCT($O12:$AB12*($O$6:$AB$6>6))=$C12,"Solo apartamentos","Mixta ("&SUMPRODUCT($O12:$AB12*($O$6:$AB$6<=6))&" casas + "&SUMPRODUCT($O12:$AB12*($O$6:$AB$6>6))&" aptos)")) | F12: =_xlfn.MINIFS($O$7:$AB$7,$O12:$AB12,1) | G12: =_xlfn.MAXIFS($O$7:$AB$7,$O12:$AB12,1) | H12: =SUMPRODUCT($O12:$AB12,$O$7:$AB$7)/C12 | I12: =_xlfn.AGGREGATE(16,6,$O$7:$AB$7/($O12:$AB12=1),0.5) | J12: =SQRT((SUMPRODUCT($O12:$AB12,$O$7:$AB$7^2)-C12*H12^2)/(C12-1)) | K12: =J12/H12 | L12: =H12-J12 | M12: =H12+J12 | N12: =IF(K12<=$D$4,"SÍ","NO") | O12: 0 | P12: 0 | Q12: 0 | R12: 0 | S12: 0 | T12: 0 | U12: 1 | V12: 1 | W12: 0 | X12: 0 | Y12: 1 | Z12: 1 | AA12: 0 | AB12: 0
